[2024-04-24T23:44:51.204+0000] {taskinstance.py:1956} INFO - Dependencies all met for dep_context=non-requeueable deps ti=<TaskInstance: process_etl_mnist_784_data.train_model manual__2024-04-24T23:43:32.113831+00:00 [queued]>
[2024-04-24T23:44:51.209+0000] {taskinstance.py:1956} INFO - Dependencies all met for dep_context=requeueable deps ti=<TaskInstance: process_etl_mnist_784_data.train_model manual__2024-04-24T23:43:32.113831+00:00 [queued]>
[2024-04-24T23:44:51.210+0000] {taskinstance.py:2170} INFO - Starting attempt 1 of 2
[2024-04-24T23:44:51.219+0000] {taskinstance.py:2191} INFO - Executing <Task(_PythonVirtualenvDecoratedOperator): train_model> on 2024-04-24 23:43:32.113831+00:00
[2024-04-24T23:44:51.224+0000] {standard_task_runner.py:60} INFO - Started process 14074 to run task
[2024-04-24T23:44:51.229+0000] {standard_task_runner.py:87} INFO - Running: ['***', 'tasks', 'run', 'process_etl_mnist_784_data', 'train_model', 'manual__2024-04-24T23:43:32.113831+00:00', '--job-id', '40', '--raw', '--subdir', 'DAGS_FOLDER/etl_process.py', '--cfg-path', '/tmp/tmpq8cwqlub']
[2024-04-24T23:44:51.230+0000] {standard_task_runner.py:88} INFO - Job 40: Subtask train_model
[2024-04-24T23:44:51.258+0000] {task_command.py:423} INFO - Running <TaskInstance: process_etl_mnist_784_data.train_model manual__2024-04-24T23:43:32.113831+00:00 [running]> on host 6bdddfadcc67
[2024-04-24T23:44:51.302+0000] {taskinstance.py:2480} INFO - Exporting env vars: AIRFLOW_CTX_DAG_OWNER='Carlos Rodriguez' AIRFLOW_CTX_DAG_ID='process_etl_mnist_784_data' AIRFLOW_CTX_TASK_ID='train_model' AIRFLOW_CTX_EXECUTION_DATE='2024-04-24T23:43:32.113831+00:00' AIRFLOW_CTX_TRY_NUMBER='1' AIRFLOW_CTX_DAG_RUN_ID='manual__2024-04-24T23:43:32.113831+00:00'
[2024-04-24T23:44:51.304+0000] {process_utils.py:182} INFO - Executing cmd: /usr/local/bin/python -m virtualenv /tmp/venv8kfvp_oi --system-site-packages --python=python
[2024-04-24T23:44:51.310+0000] {process_utils.py:186} INFO - Output:
[2024-04-24T23:44:51.748+0000] {process_utils.py:190} INFO - created virtual environment CPython3.8.18.final.0-64 in 159ms
[2024-04-24T23:44:51.748+0000] {process_utils.py:190} INFO -   creator CPython3Posix(dest=/tmp/venv8kfvp_oi, clear=False, no_vcs_ignore=False, global=True)
[2024-04-24T23:44:51.749+0000] {process_utils.py:190} INFO -   seeder FromAppData(download=False, pip=bundle, setuptools=bundle, wheel=bundle, via=copy, app_data_dir=/home/***/.local/share/virtualenv)
[2024-04-24T23:44:51.749+0000] {process_utils.py:190} INFO -     added seed packages: pip==23.3.1, setuptools==69.0.2, wheel==0.42.0
[2024-04-24T23:44:51.750+0000] {process_utils.py:190} INFO -   activators BashActivator,CShellActivator,FishActivator,NushellActivator,PowerShellActivator,PythonActivator
[2024-04-24T23:44:51.776+0000] {process_utils.py:182} INFO - Executing cmd: /tmp/venv8kfvp_oi/bin/pip install -r /tmp/venv8kfvp_oi/requirements.txt
[2024-04-24T23:44:51.782+0000] {process_utils.py:186} INFO - Output:
[2024-04-24T23:44:52.661+0000] {process_utils.py:190} INFO - Collecting awswrangler==3.6.0 (from -r /tmp/venv8kfvp_oi/requirements.txt (line 1))
[2024-04-24T23:44:52.662+0000] {process_utils.py:190} INFO -   Using cached awswrangler-3.6.0-py3-none-any.whl.metadata (23 kB)
[2024-04-24T23:44:52.692+0000] {process_utils.py:190} INFO - Requirement already satisfied: boto3<2.0.0,>=1.20.32 in /home/***/.local/lib/python3.8/site-packages (from awswrangler==3.6.0->-r /tmp/venv8kfvp_oi/requirements.txt (line 1)) (1.34.88)
[2024-04-24T23:44:52.692+0000] {process_utils.py:190} INFO - Requirement already satisfied: botocore<2.0.0,>=1.23.32 in /home/***/.local/lib/python3.8/site-packages (from awswrangler==3.6.0->-r /tmp/venv8kfvp_oi/requirements.txt (line 1)) (1.34.88)
[2024-04-24T23:44:52.694+0000] {process_utils.py:190} INFO - Requirement already satisfied: numpy<2.0,>=1.18 in /home/***/.local/lib/python3.8/site-packages (from awswrangler==3.6.0->-r /tmp/venv8kfvp_oi/requirements.txt (line 1)) (1.24.4)
[2024-04-24T23:44:52.694+0000] {process_utils.py:190} INFO - Requirement already satisfied: packaging<24.0,>=21.1 in /home/***/.local/lib/python3.8/site-packages (from awswrangler==3.6.0->-r /tmp/venv8kfvp_oi/requirements.txt (line 1)) (23.2)
[2024-04-24T23:44:52.695+0000] {process_utils.py:190} INFO - Requirement already satisfied: pandas<2.1.0,>=1.2.0 in /home/***/.local/lib/python3.8/site-packages (from awswrangler==3.6.0->-r /tmp/venv8kfvp_oi/requirements.txt (line 1)) (2.0.3)
[2024-04-24T23:44:52.695+0000] {process_utils.py:190} INFO - Requirement already satisfied: pyarrow>=7.0.0 in /home/***/.local/lib/python3.8/site-packages (from awswrangler==3.6.0->-r /tmp/venv8kfvp_oi/requirements.txt (line 1)) (14.0.2)
[2024-04-24T23:44:52.696+0000] {process_utils.py:190} INFO - Requirement already satisfied: typing-extensions<5.0.0,>=4.4.0 in /home/***/.local/lib/python3.8/site-packages (from awswrangler==3.6.0->-r /tmp/venv8kfvp_oi/requirements.txt (line 1)) (4.9.0)
[2024-04-24T23:44:52.700+0000] {process_utils.py:190} INFO - Requirement already satisfied: jmespath<2.0.0,>=0.7.1 in /home/***/.local/lib/python3.8/site-packages (from boto3<2.0.0,>=1.20.32->awswrangler==3.6.0->-r /tmp/venv8kfvp_oi/requirements.txt (line 1)) (0.10.0)
[2024-04-24T23:44:52.700+0000] {process_utils.py:190} INFO - Requirement already satisfied: s3transfer<0.11.0,>=0.10.0 in /home/***/.local/lib/python3.8/site-packages (from boto3<2.0.0,>=1.20.32->awswrangler==3.6.0->-r /tmp/venv8kfvp_oi/requirements.txt (line 1)) (0.10.1)
[2024-04-24T23:44:52.704+0000] {process_utils.py:190} INFO - Requirement already satisfied: python-dateutil<3.0.0,>=2.1 in /home/***/.local/lib/python3.8/site-packages (from botocore<2.0.0,>=1.23.32->awswrangler==3.6.0->-r /tmp/venv8kfvp_oi/requirements.txt (line 1)) (2.8.2)
[2024-04-24T23:44:52.706+0000] {process_utils.py:190} INFO - Requirement already satisfied: urllib3<1.27,>=1.25.4 in /home/***/.local/lib/python3.8/site-packages (from botocore<2.0.0,>=1.23.32->awswrangler==3.6.0->-r /tmp/venv8kfvp_oi/requirements.txt (line 1)) (1.26.18)
[2024-04-24T23:44:52.765+0000] {process_utils.py:190} INFO - Requirement already satisfied: pytz>=2020.1 in /home/***/.local/lib/python3.8/site-packages (from pandas<2.1.0,>=1.2.0->awswrangler==3.6.0->-r /tmp/venv8kfvp_oi/requirements.txt (line 1)) (2023.3.post1)
[2024-04-24T23:44:52.766+0000] {process_utils.py:190} INFO - Requirement already satisfied: tzdata>=2022.1 in /home/***/.local/lib/python3.8/site-packages (from pandas<2.1.0,>=1.2.0->awswrangler==3.6.0->-r /tmp/venv8kfvp_oi/requirements.txt (line 1)) (2023.4)
[2024-04-24T23:44:52.771+0000] {process_utils.py:190} INFO - Requirement already satisfied: six>=1.5 in /home/***/.local/lib/python3.8/site-packages (from python-dateutil<3.0.0,>=2.1->botocore<2.0.0,>=1.23.32->awswrangler==3.6.0->-r /tmp/venv8kfvp_oi/requirements.txt (line 1)) (1.16.0)
[2024-04-24T23:44:52.792+0000] {process_utils.py:190} INFO - Using cached awswrangler-3.6.0-py3-none-any.whl (403 kB)
[2024-04-24T23:44:54.861+0000] {process_utils.py:190} INFO - Installing collected packages: awswrangler
[2024-04-24T23:44:55.023+0000] {process_utils.py:190} INFO - Successfully installed awswrangler-3.6.0
[2024-04-24T23:44:55.154+0000] {process_utils.py:190} INFO - 
[2024-04-24T23:44:55.154+0000] {process_utils.py:190} INFO - [notice] A new release of pip is available: 23.3.1 -> 24.0
[2024-04-24T23:44:55.154+0000] {process_utils.py:190} INFO - [notice] To update, run: python -m pip install --upgrade pip
[2024-04-24T23:44:55.282+0000] {process_utils.py:182} INFO - Executing cmd: /tmp/venv8kfvp_oi/bin/python /tmp/venv-calllp4du0wo/script.py /tmp/venv-calllp4du0wo/script.in /tmp/venv-calllp4du0wo/script.out /tmp/venv-calllp4du0wo/string_args.txt /tmp/venv-calllp4du0wo/termination.log
[2024-04-24T23:44:55.288+0000] {process_utils.py:186} INFO - Output:
[2024-04-24T23:44:57.420+0000] {process_utils.py:190} INFO - [[34m2024-04-24T23:44:57.419+0000[0m] {[34mcredentials.py:[0m1147} INFO[0m - Found credentials in environment variables.[0m
[2024-04-24T23:44:57.459+0000] {process_utils.py:190} INFO - [[34m2024-04-24T23:44:57.459+0000[0m] {[34mconfigprovider.py:[0m957} INFO[0m - Found endpoint for s3 via: environment_service.[0m
[2024-04-24T23:47:13.808+0000] {job.py:213} ERROR - Job heartbeat got an exception
Traceback (most recent call last):
  File "/home/airflow/.local/lib/python3.8/site-packages/sqlalchemy/engine/base.py", line 3371, in _wrap_pool_connect
    return fn()
  File "/home/airflow/.local/lib/python3.8/site-packages/sqlalchemy/pool/base.py", line 327, in connect
    return _ConnectionFairy._checkout(self)
  File "/home/airflow/.local/lib/python3.8/site-packages/sqlalchemy/pool/base.py", line 894, in _checkout
    fairy = _ConnectionRecord.checkout(pool)
  File "/home/airflow/.local/lib/python3.8/site-packages/sqlalchemy/pool/base.py", line 493, in checkout
    rec = pool._do_get()
  File "/home/airflow/.local/lib/python3.8/site-packages/sqlalchemy/pool/impl.py", line 256, in _do_get
    return self._create_connection()
  File "/home/airflow/.local/lib/python3.8/site-packages/sqlalchemy/pool/base.py", line 273, in _create_connection
    return _ConnectionRecord(self)
  File "/home/airflow/.local/lib/python3.8/site-packages/sqlalchemy/pool/base.py", line 388, in __init__
    self.__connect()
  File "/home/airflow/.local/lib/python3.8/site-packages/sqlalchemy/pool/base.py", line 691, in __connect
    pool.logger.debug("Error on connect(): %s", e)
  File "/home/airflow/.local/lib/python3.8/site-packages/sqlalchemy/util/langhelpers.py", line 70, in __exit__
    compat.raise_(
  File "/home/airflow/.local/lib/python3.8/site-packages/sqlalchemy/util/compat.py", line 211, in raise_
    raise exception
  File "/home/airflow/.local/lib/python3.8/site-packages/sqlalchemy/pool/base.py", line 686, in __connect
    self.dbapi_connection = connection = pool._invoke_creator(self)
  File "/home/airflow/.local/lib/python3.8/site-packages/sqlalchemy/engine/create.py", line 574, in connect
    return dialect.connect(*cargs, **cparams)
  File "/home/airflow/.local/lib/python3.8/site-packages/sqlalchemy/engine/default.py", line 598, in connect
    return self.dbapi.connect(*cargs, **cparams)
  File "/home/airflow/.local/lib/python3.8/site-packages/psycopg2/__init__.py", line 122, in connect
    conn = _connect(dsn, connection_factory=connection_factory, **kwasync)
psycopg2.OperationalError: could not translate host name "postgres" to address: Temporary failure in name resolution


The above exception was the direct cause of the following exception:

Traceback (most recent call last):
  File "/home/airflow/.local/lib/python3.8/site-packages/airflow/jobs/job.py", line 208, in heartbeat
    heartbeat_callback(session)
  File "/home/airflow/.local/lib/python3.8/site-packages/airflow/utils/session.py", line 76, in wrapper
    return func(*args, **kwargs)
  File "/home/airflow/.local/lib/python3.8/site-packages/airflow/jobs/local_task_job_runner.py", line 252, in heartbeat_callback
    self.task_instance.refresh_from_db()
  File "/home/airflow/.local/lib/python3.8/site-packages/airflow/utils/session.py", line 79, in wrapper
    return func(*args, session=session, **kwargs)
  File "/home/airflow/.local/lib/python3.8/site-packages/airflow/models/taskinstance.py", line 1725, in refresh_from_db
    _refresh_from_db(task_instance=self, session=session, lock_for_update=lock_for_update)
  File "/home/airflow/.local/lib/python3.8/site-packages/airflow/models/taskinstance.py", line 464, in _refresh_from_db
    ti = TaskInstance.get_task_instance(
  File "/home/airflow/.local/lib/python3.8/site-packages/airflow/api_internal/internal_api_call.py", line 114, in wrapper
    return func(*args, **kwargs)
  File "/home/airflow/.local/lib/python3.8/site-packages/airflow/utils/session.py", line 76, in wrapper
    return func(*args, **kwargs)
  File "/home/airflow/.local/lib/python3.8/site-packages/airflow/models/taskinstance.py", line 1711, in get_task_instance
    return query.one_or_none()
  File "/home/airflow/.local/lib/python3.8/site-packages/sqlalchemy/orm/query.py", line 2850, in one_or_none
    return self._iter().one_or_none()
  File "/home/airflow/.local/lib/python3.8/site-packages/sqlalchemy/orm/query.py", line 2916, in _iter
    result = self.session.execute(
  File "/home/airflow/.local/lib/python3.8/site-packages/sqlalchemy/orm/session.py", line 1716, in execute
    conn = self._connection_for_bind(bind)
  File "/home/airflow/.local/lib/python3.8/site-packages/sqlalchemy/orm/session.py", line 1555, in _connection_for_bind
    return self._transaction._connection_for_bind(
  File "/home/airflow/.local/lib/python3.8/site-packages/sqlalchemy/orm/session.py", line 750, in _connection_for_bind
    conn = bind.connect()
  File "/home/airflow/.local/lib/python3.8/site-packages/sqlalchemy/future/engine.py", line 412, in connect
    return super(Engine, self).connect()
  File "/home/airflow/.local/lib/python3.8/site-packages/sqlalchemy/engine/base.py", line 3325, in connect
    return self._connection_cls(self, close_with_result=close_with_result)
  File "/home/airflow/.local/lib/python3.8/site-packages/sqlalchemy/engine/base.py", line 96, in __init__
    else engine.raw_connection()
  File "/home/airflow/.local/lib/python3.8/site-packages/sqlalchemy/engine/base.py", line 3404, in raw_connection
    return self._wrap_pool_connect(self.pool.connect, _connection)
  File "/home/airflow/.local/lib/python3.8/site-packages/sqlalchemy/engine/base.py", line 3374, in _wrap_pool_connect
    Connection._handle_dbapi_exception_noconnection(
  File "/home/airflow/.local/lib/python3.8/site-packages/sqlalchemy/engine/base.py", line 2208, in _handle_dbapi_exception_noconnection
    util.raise_(
  File "/home/airflow/.local/lib/python3.8/site-packages/sqlalchemy/util/compat.py", line 211, in raise_
    raise exception
  File "/home/airflow/.local/lib/python3.8/site-packages/sqlalchemy/engine/base.py", line 3371, in _wrap_pool_connect
    return fn()
  File "/home/airflow/.local/lib/python3.8/site-packages/sqlalchemy/pool/base.py", line 327, in connect
    return _ConnectionFairy._checkout(self)
  File "/home/airflow/.local/lib/python3.8/site-packages/sqlalchemy/pool/base.py", line 894, in _checkout
    fairy = _ConnectionRecord.checkout(pool)
  File "/home/airflow/.local/lib/python3.8/site-packages/sqlalchemy/pool/base.py", line 493, in checkout
    rec = pool._do_get()
  File "/home/airflow/.local/lib/python3.8/site-packages/sqlalchemy/pool/impl.py", line 256, in _do_get
    return self._create_connection()
  File "/home/airflow/.local/lib/python3.8/site-packages/sqlalchemy/pool/base.py", line 273, in _create_connection
    return _ConnectionRecord(self)
  File "/home/airflow/.local/lib/python3.8/site-packages/sqlalchemy/pool/base.py", line 388, in __init__
    self.__connect()
  File "/home/airflow/.local/lib/python3.8/site-packages/sqlalchemy/pool/base.py", line 691, in __connect
    pool.logger.debug("Error on connect(): %s", e)
  File "/home/airflow/.local/lib/python3.8/site-packages/sqlalchemy/util/langhelpers.py", line 70, in __exit__
    compat.raise_(
  File "/home/airflow/.local/lib/python3.8/site-packages/sqlalchemy/util/compat.py", line 211, in raise_
    raise exception
  File "/home/airflow/.local/lib/python3.8/site-packages/sqlalchemy/pool/base.py", line 686, in __connect
    self.dbapi_connection = connection = pool._invoke_creator(self)
  File "/home/airflow/.local/lib/python3.8/site-packages/sqlalchemy/engine/create.py", line 574, in connect
    return dialect.connect(*cargs, **cparams)
  File "/home/airflow/.local/lib/python3.8/site-packages/sqlalchemy/engine/default.py", line 598, in connect
    return self.dbapi.connect(*cargs, **cparams)
  File "/home/airflow/.local/lib/python3.8/site-packages/psycopg2/__init__.py", line 122, in connect
    conn = _connect(dsn, connection_factory=connection_factory, **kwasync)
sqlalchemy.exc.OperationalError: (psycopg2.OperationalError) could not translate host name "postgres" to address: Temporary failure in name resolution

(Background on this error at: https://sqlalche.me/e/14/e3q8)
[2024-04-24T23:47:17.160+0000] {job.py:221} ERROR - Job heartbeat failed with error. Scheduler is in unhealthy state
[2024-04-24T23:47:33.148+0000] {job.py:221} ERROR - Job heartbeat failed with error. Scheduler is in unhealthy state
[2024-04-24T23:48:38.705+0000] {job.py:221} ERROR - Job heartbeat failed with error. Scheduler is in unhealthy state
[2024-04-24T23:49:46.402+0000] {job.py:221} ERROR - Job heartbeat failed with error. Scheduler is in unhealthy state
[2024-04-24T23:51:31.135+0000] {taskinstance.py:2698} ERROR - Task failed with exception
Traceback (most recent call last):
  File "/home/airflow/.local/lib/python3.8/site-packages/airflow/models/taskinstance.py", line 433, in _execute_task
    result = execute_callable(context=context, **execute_callable_kwargs)
  File "/home/airflow/.local/lib/python3.8/site-packages/airflow/decorators/base.py", line 241, in execute
    return_value = super().execute(context)
  File "/home/airflow/.local/lib/python3.8/site-packages/airflow/operators/python.py", line 400, in execute
    return super().execute(context=serializable_context)
  File "/home/airflow/.local/lib/python3.8/site-packages/airflow/operators/python.py", line 199, in execute
    return_value = self.execute_callable()
  File "/home/airflow/.local/lib/python3.8/site-packages/airflow/operators/python.py", line 716, in execute_callable
    result = self._execute_python_callable_in_subprocess(python_path)
  File "/home/airflow/.local/lib/python3.8/site-packages/airflow/operators/python.py", line 454, in _execute_python_callable_in_subprocess
    execute_in_subprocess(
  File "/home/airflow/.local/lib/python3.8/site-packages/airflow/utils/process_utils.py", line 171, in execute_in_subprocess
    execute_in_subprocess_with_kwargs(cmd, cwd=cwd)
  File "/home/airflow/.local/lib/python3.8/site-packages/airflow/utils/process_utils.py", line 194, in execute_in_subprocess_with_kwargs
    raise subprocess.CalledProcessError(exit_code, cmd)
subprocess.CalledProcessError: Command '['/tmp/venv8kfvp_oi/bin/python', '/tmp/venv-calllp4du0wo/script.py', '/tmp/venv-calllp4du0wo/script.in', '/tmp/venv-calllp4du0wo/script.out', '/tmp/venv-calllp4du0wo/string_args.txt', '/tmp/venv-calllp4du0wo/termination.log']' died with <Signals.SIGKILL: 9>.
[2024-04-24T23:51:34.345+0000] {taskinstance.py:1138} INFO - Marking task as UP_FOR_RETRY. dag_id=process_etl_mnist_784_data, task_id=train_model, execution_date=20240424T234332, start_date=20240424T234451, end_date=20240424T235133
[2024-04-24T23:51:34.682+0000] {standard_task_runner.py:107} ERROR - Failed to execute job 40 for task train_model (Command '['/tmp/venv8kfvp_oi/bin/python', '/tmp/venv-calllp4du0wo/script.py', '/tmp/venv-calllp4du0wo/script.in', '/tmp/venv-calllp4du0wo/script.out', '/tmp/venv-calllp4du0wo/string_args.txt', '/tmp/venv-calllp4du0wo/termination.log']' died with <Signals.SIGKILL: 9>.; 14074)
[2024-04-24T23:51:38.509+0000] {local_task_job_runner.py:234} INFO - Task exited with return code 1
[2024-04-24T23:51:38.710+0000] {taskinstance.py:3280} INFO - 0 downstream tasks scheduled from follow-on schedule check
