[2024-04-24T23:43:46.275+0000] {taskinstance.py:1956} INFO - Dependencies all met for dep_context=non-requeueable deps ti=<TaskInstance: retrain_the_model_mnist_784.train_the_challenger_model manual__2024-04-24T23:43:44.048605+00:00 [queued]>
[2024-04-24T23:43:46.280+0000] {taskinstance.py:1956} INFO - Dependencies all met for dep_context=requeueable deps ti=<TaskInstance: retrain_the_model_mnist_784.train_the_challenger_model manual__2024-04-24T23:43:44.048605+00:00 [queued]>
[2024-04-24T23:43:46.280+0000] {taskinstance.py:2170} INFO - Starting attempt 1 of 2
[2024-04-24T23:43:46.289+0000] {taskinstance.py:2191} INFO - Executing <Task(_PythonVirtualenvDecoratedOperator): train_the_challenger_model> on 2024-04-24 23:43:44.048605+00:00
[2024-04-24T23:43:46.293+0000] {standard_task_runner.py:60} INFO - Started process 13411 to run task
[2024-04-24T23:43:46.296+0000] {standard_task_runner.py:87} INFO - Running: ['***', 'tasks', 'run', 'retrain_the_model_mnist_784', 'train_the_challenger_model', 'manual__2024-04-24T23:43:44.048605+00:00', '--job-id', '38', '--raw', '--subdir', 'DAGS_FOLDER/retrain_the_model.py', '--cfg-path', '/tmp/tmpe0ppjgnp']
[2024-04-24T23:43:46.297+0000] {standard_task_runner.py:88} INFO - Job 38: Subtask train_the_challenger_model
[2024-04-24T23:43:46.326+0000] {task_command.py:423} INFO - Running <TaskInstance: retrain_the_model_mnist_784.train_the_challenger_model manual__2024-04-24T23:43:44.048605+00:00 [running]> on host 6bdddfadcc67
[2024-04-24T23:43:46.379+0000] {taskinstance.py:2480} INFO - Exporting env vars: AIRFLOW_CTX_DAG_OWNER='Carlos Rodriguez' AIRFLOW_CTX_DAG_ID='retrain_the_model_mnist_784' AIRFLOW_CTX_TASK_ID='train_the_challenger_model' AIRFLOW_CTX_EXECUTION_DATE='2024-04-24T23:43:44.048605+00:00' AIRFLOW_CTX_TRY_NUMBER='1' AIRFLOW_CTX_DAG_RUN_ID='manual__2024-04-24T23:43:44.048605+00:00'
[2024-04-24T23:43:46.381+0000] {process_utils.py:182} INFO - Executing cmd: /usr/local/bin/python -m virtualenv /tmp/venv8qgl3nx0 --system-site-packages --python=python
[2024-04-24T23:43:46.389+0000] {process_utils.py:186} INFO - Output:
[2024-04-24T23:43:46.900+0000] {process_utils.py:190} INFO - created virtual environment CPython3.8.18.final.0-64 in 182ms
[2024-04-24T23:43:46.900+0000] {process_utils.py:190} INFO -   creator CPython3Posix(dest=/tmp/venv8qgl3nx0, clear=False, no_vcs_ignore=False, global=True)
[2024-04-24T23:43:46.901+0000] {process_utils.py:190} INFO -   seeder FromAppData(download=False, pip=bundle, setuptools=bundle, wheel=bundle, via=copy, app_data_dir=/home/***/.local/share/virtualenv)
[2024-04-24T23:43:46.901+0000] {process_utils.py:190} INFO -     added seed packages: pip==23.3.1, setuptools==69.0.2, wheel==0.42.0
[2024-04-24T23:43:46.901+0000] {process_utils.py:190} INFO -   activators BashActivator,CShellActivator,FishActivator,NushellActivator,PowerShellActivator,PythonActivator
[2024-04-24T23:43:47.003+0000] {process_utils.py:182} INFO - Executing cmd: /tmp/venv8qgl3nx0/bin/pip install -r /tmp/venv8qgl3nx0/requirements.txt
[2024-04-24T23:43:47.011+0000] {process_utils.py:186} INFO - Output:
[2024-04-24T23:43:47.976+0000] {process_utils.py:190} INFO - Collecting awswrangler==3.6.0 (from -r /tmp/venv8qgl3nx0/requirements.txt (line 1))
[2024-04-24T23:43:47.978+0000] {process_utils.py:190} INFO -   Using cached awswrangler-3.6.0-py3-none-any.whl.metadata (23 kB)
[2024-04-24T23:43:48.068+0000] {process_utils.py:190} INFO - Collecting mlflow==2.10.2 (from -r /tmp/venv8qgl3nx0/requirements.txt (line 2))
[2024-04-24T23:43:48.193+0000] {process_utils.py:190} INFO -   Downloading mlflow-2.10.2-py3-none-any.whl.metadata (13 kB)
[2024-04-24T23:43:48.202+0000] {process_utils.py:190} INFO - Requirement already satisfied: scikit-learn==1.3.2 in /home/***/.local/lib/python3.8/site-packages (from -r /tmp/venv8qgl3nx0/requirements.txt (line 3)) (1.3.2)
[2024-04-24T23:43:48.233+0000] {process_utils.py:190} INFO - Requirement already satisfied: boto3<2.0.0,>=1.20.32 in /home/***/.local/lib/python3.8/site-packages (from awswrangler==3.6.0->-r /tmp/venv8qgl3nx0/requirements.txt (line 1)) (1.34.88)
[2024-04-24T23:43:48.233+0000] {process_utils.py:190} INFO - Requirement already satisfied: botocore<2.0.0,>=1.23.32 in /home/***/.local/lib/python3.8/site-packages (from awswrangler==3.6.0->-r /tmp/venv8qgl3nx0/requirements.txt (line 1)) (1.34.88)
[2024-04-24T23:43:48.234+0000] {process_utils.py:190} INFO - Requirement already satisfied: numpy<2.0,>=1.18 in /home/***/.local/lib/python3.8/site-packages (from awswrangler==3.6.0->-r /tmp/venv8qgl3nx0/requirements.txt (line 1)) (1.24.4)
[2024-04-24T23:43:48.234+0000] {process_utils.py:190} INFO - Requirement already satisfied: packaging<24.0,>=21.1 in /home/***/.local/lib/python3.8/site-packages (from awswrangler==3.6.0->-r /tmp/venv8qgl3nx0/requirements.txt (line 1)) (23.2)
[2024-04-24T23:43:48.235+0000] {process_utils.py:190} INFO - Requirement already satisfied: pandas<2.1.0,>=1.2.0 in /home/***/.local/lib/python3.8/site-packages (from awswrangler==3.6.0->-r /tmp/venv8qgl3nx0/requirements.txt (line 1)) (2.0.3)
[2024-04-24T23:43:48.236+0000] {process_utils.py:190} INFO - Requirement already satisfied: pyarrow>=7.0.0 in /home/***/.local/lib/python3.8/site-packages (from awswrangler==3.6.0->-r /tmp/venv8qgl3nx0/requirements.txt (line 1)) (14.0.2)
[2024-04-24T23:43:48.237+0000] {process_utils.py:190} INFO - Requirement already satisfied: typing-extensions<5.0.0,>=4.4.0 in /home/***/.local/lib/python3.8/site-packages (from awswrangler==3.6.0->-r /tmp/venv8qgl3nx0/requirements.txt (line 1)) (4.9.0)
[2024-04-24T23:43:48.274+0000] {process_utils.py:190} INFO - Requirement already satisfied: click<9,>=7.0 in /home/***/.local/lib/python3.8/site-packages (from mlflow==2.10.2->-r /tmp/venv8qgl3nx0/requirements.txt (line 2)) (8.1.7)
[2024-04-24T23:43:48.275+0000] {process_utils.py:190} INFO - Requirement already satisfied: cloudpickle<4 in /home/***/.local/lib/python3.8/site-packages (from mlflow==2.10.2->-r /tmp/venv8qgl3nx0/requirements.txt (line 2)) (3.0.0)
[2024-04-24T23:43:48.276+0000] {process_utils.py:190} INFO - Requirement already satisfied: entrypoints<1 in /home/***/.local/lib/python3.8/site-packages (from mlflow==2.10.2->-r /tmp/venv8qgl3nx0/requirements.txt (line 2)) (0.4)
[2024-04-24T23:43:48.276+0000] {process_utils.py:190} INFO - Requirement already satisfied: gitpython<4,>=2.1.0 in /home/***/.local/lib/python3.8/site-packages (from mlflow==2.10.2->-r /tmp/venv8qgl3nx0/requirements.txt (line 2)) (3.1.43)
[2024-04-24T23:43:48.277+0000] {process_utils.py:190} INFO - Requirement already satisfied: pyyaml<7,>=5.1 in /home/***/.local/lib/python3.8/site-packages (from mlflow==2.10.2->-r /tmp/venv8qgl3nx0/requirements.txt (line 2)) (6.0.1)
[2024-04-24T23:43:48.277+0000] {process_utils.py:190} INFO - Requirement already satisfied: protobuf<5,>=3.12.0 in /home/***/.local/lib/python3.8/site-packages (from mlflow==2.10.2->-r /tmp/venv8qgl3nx0/requirements.txt (line 2)) (4.25.2)
[2024-04-24T23:43:48.278+0000] {process_utils.py:190} INFO - Requirement already satisfied: pytz<2024 in /home/***/.local/lib/python3.8/site-packages (from mlflow==2.10.2->-r /tmp/venv8qgl3nx0/requirements.txt (line 2)) (2023.3.post1)
[2024-04-24T23:43:48.278+0000] {process_utils.py:190} INFO - Requirement already satisfied: requests<3,>=2.17.3 in /home/***/.local/lib/python3.8/site-packages (from mlflow==2.10.2->-r /tmp/venv8qgl3nx0/requirements.txt (line 2)) (2.31.0)
[2024-04-24T23:43:48.279+0000] {process_utils.py:190} INFO - Requirement already satisfied: importlib-metadata!=4.7.0,<8,>=3.7.0 in /home/***/.local/lib/python3.8/site-packages (from mlflow==2.10.2->-r /tmp/venv8qgl3nx0/requirements.txt (line 2)) (6.11.0)
[2024-04-24T23:43:48.279+0000] {process_utils.py:190} INFO - Requirement already satisfied: sqlparse<1,>=0.4.0 in /home/***/.local/lib/python3.8/site-packages (from mlflow==2.10.2->-r /tmp/venv8qgl3nx0/requirements.txt (line 2)) (0.4.4)
[2024-04-24T23:43:48.280+0000] {process_utils.py:190} INFO - Requirement already satisfied: alembic!=1.10.0,<2 in /home/***/.local/lib/python3.8/site-packages (from mlflow==2.10.2->-r /tmp/venv8qgl3nx0/requirements.txt (line 2)) (1.13.1)
[2024-04-24T23:43:48.280+0000] {process_utils.py:190} INFO - Requirement already satisfied: docker<8,>=4.0.0 in /home/***/.local/lib/python3.8/site-packages (from mlflow==2.10.2->-r /tmp/venv8qgl3nx0/requirements.txt (line 2)) (7.0.0)
[2024-04-24T23:43:48.281+0000] {process_utils.py:190} INFO - Requirement already satisfied: Flask<4 in /home/***/.local/lib/python3.8/site-packages (from mlflow==2.10.2->-r /tmp/venv8qgl3nx0/requirements.txt (line 2)) (2.2.5)
[2024-04-24T23:43:48.281+0000] {process_utils.py:190} INFO - Requirement already satisfied: scipy<2 in /home/***/.local/lib/python3.8/site-packages (from mlflow==2.10.2->-r /tmp/venv8qgl3nx0/requirements.txt (line 2)) (1.10.1)
[2024-04-24T23:43:48.282+0000] {process_utils.py:190} INFO - Requirement already satisfied: querystring-parser<2 in /home/***/.local/lib/python3.8/site-packages (from mlflow==2.10.2->-r /tmp/venv8qgl3nx0/requirements.txt (line 2)) (1.2.4)
[2024-04-24T23:43:48.282+0000] {process_utils.py:190} INFO - Requirement already satisfied: sqlalchemy<3,>=1.4.0 in /home/***/.local/lib/python3.8/site-packages (from mlflow==2.10.2->-r /tmp/venv8qgl3nx0/requirements.txt (line 2)) (1.4.51)
[2024-04-24T23:43:48.283+0000] {process_utils.py:190} INFO - Requirement already satisfied: markdown<4,>=3.3 in /home/***/.local/lib/python3.8/site-packages (from mlflow==2.10.2->-r /tmp/venv8qgl3nx0/requirements.txt (line 2)) (3.5.2)
[2024-04-24T23:43:48.283+0000] {process_utils.py:190} INFO - Requirement already satisfied: matplotlib<4 in /home/***/.local/lib/python3.8/site-packages (from mlflow==2.10.2->-r /tmp/venv8qgl3nx0/requirements.txt (line 2)) (3.7.5)
[2024-04-24T23:43:48.284+0000] {process_utils.py:190} INFO - Requirement already satisfied: gunicorn<22 in /home/***/.local/lib/python3.8/site-packages (from mlflow==2.10.2->-r /tmp/venv8qgl3nx0/requirements.txt (line 2)) (21.2.0)
[2024-04-24T23:43:48.285+0000] {process_utils.py:190} INFO - Requirement already satisfied: Jinja2<4,>=2.11 in /home/***/.local/lib/python3.8/site-packages (from mlflow==2.10.2->-r /tmp/venv8qgl3nx0/requirements.txt (line 2)) (3.1.3)
[2024-04-24T23:43:48.307+0000] {process_utils.py:190} INFO - Requirement already satisfied: joblib>=1.1.1 in /home/***/.local/lib/python3.8/site-packages (from scikit-learn==1.3.2->-r /tmp/venv8qgl3nx0/requirements.txt (line 3)) (1.4.0)
[2024-04-24T23:43:48.308+0000] {process_utils.py:190} INFO - Requirement already satisfied: threadpoolctl>=2.0.0 in /home/***/.local/lib/python3.8/site-packages (from scikit-learn==1.3.2->-r /tmp/venv8qgl3nx0/requirements.txt (line 3)) (3.4.0)
[2024-04-24T23:43:48.313+0000] {process_utils.py:190} INFO - Requirement already satisfied: Mako in /home/***/.local/lib/python3.8/site-packages (from alembic!=1.10.0,<2->mlflow==2.10.2->-r /tmp/venv8qgl3nx0/requirements.txt (line 2)) (1.3.0)
[2024-04-24T23:43:48.314+0000] {process_utils.py:190} INFO - Requirement already satisfied: importlib-resources in /home/***/.local/lib/python3.8/site-packages (from alembic!=1.10.0,<2->mlflow==2.10.2->-r /tmp/venv8qgl3nx0/requirements.txt (line 2)) (5.13.0)
[2024-04-24T23:43:48.318+0000] {process_utils.py:190} INFO - Requirement already satisfied: jmespath<2.0.0,>=0.7.1 in /home/***/.local/lib/python3.8/site-packages (from boto3<2.0.0,>=1.20.32->awswrangler==3.6.0->-r /tmp/venv8qgl3nx0/requirements.txt (line 1)) (0.10.0)
[2024-04-24T23:43:48.319+0000] {process_utils.py:190} INFO - Requirement already satisfied: s3transfer<0.11.0,>=0.10.0 in /home/***/.local/lib/python3.8/site-packages (from boto3<2.0.0,>=1.20.32->awswrangler==3.6.0->-r /tmp/venv8qgl3nx0/requirements.txt (line 1)) (0.10.1)
[2024-04-24T23:43:48.323+0000] {process_utils.py:190} INFO - Requirement already satisfied: python-dateutil<3.0.0,>=2.1 in /home/***/.local/lib/python3.8/site-packages (from botocore<2.0.0,>=1.23.32->awswrangler==3.6.0->-r /tmp/venv8qgl3nx0/requirements.txt (line 1)) (2.8.2)
[2024-04-24T23:43:48.324+0000] {process_utils.py:190} INFO - Requirement already satisfied: urllib3<1.27,>=1.25.4 in /home/***/.local/lib/python3.8/site-packages (from botocore<2.0.0,>=1.23.32->awswrangler==3.6.0->-r /tmp/venv8qgl3nx0/requirements.txt (line 1)) (1.26.18)
[2024-04-24T23:43:48.341+0000] {process_utils.py:190} INFO - Requirement already satisfied: Werkzeug>=2.2.2 in /home/***/.local/lib/python3.8/site-packages (from Flask<4->mlflow==2.10.2->-r /tmp/venv8qgl3nx0/requirements.txt (line 2)) (2.2.3)
[2024-04-24T23:43:48.342+0000] {process_utils.py:190} INFO - Requirement already satisfied: itsdangerous>=2.0 in /home/***/.local/lib/python3.8/site-packages (from Flask<4->mlflow==2.10.2->-r /tmp/venv8qgl3nx0/requirements.txt (line 2)) (2.1.2)
[2024-04-24T23:43:48.357+0000] {process_utils.py:190} INFO - Requirement already satisfied: gitdb<5,>=4.0.1 in /home/***/.local/lib/python3.8/site-packages (from gitpython<4,>=2.1.0->mlflow==2.10.2->-r /tmp/venv8qgl3nx0/requirements.txt (line 2)) (4.0.11)
[2024-04-24T23:43:48.403+0000] {process_utils.py:190} INFO - Requirement already satisfied: zipp>=0.5 in /home/***/.local/lib/python3.8/site-packages (from importlib-metadata!=4.7.0,<8,>=3.7.0->mlflow==2.10.2->-r /tmp/venv8qgl3nx0/requirements.txt (line 2)) (3.17.0)
[2024-04-24T23:43:48.407+0000] {process_utils.py:190} INFO - Requirement already satisfied: MarkupSafe>=2.0 in /home/***/.local/lib/python3.8/site-packages (from Jinja2<4,>=2.11->mlflow==2.10.2->-r /tmp/venv8qgl3nx0/requirements.txt (line 2)) (2.1.3)
[2024-04-24T23:43:48.424+0000] {process_utils.py:190} INFO - Requirement already satisfied: contourpy>=1.0.1 in /home/***/.local/lib/python3.8/site-packages (from matplotlib<4->mlflow==2.10.2->-r /tmp/venv8qgl3nx0/requirements.txt (line 2)) (1.1.1)
[2024-04-24T23:43:48.425+0000] {process_utils.py:190} INFO - Requirement already satisfied: cycler>=0.10 in /home/***/.local/lib/python3.8/site-packages (from matplotlib<4->mlflow==2.10.2->-r /tmp/venv8qgl3nx0/requirements.txt (line 2)) (0.12.1)
[2024-04-24T23:43:48.425+0000] {process_utils.py:190} INFO - Requirement already satisfied: fonttools>=4.22.0 in /home/***/.local/lib/python3.8/site-packages (from matplotlib<4->mlflow==2.10.2->-r /tmp/venv8qgl3nx0/requirements.txt (line 2)) (4.51.0)
[2024-04-24T23:43:48.425+0000] {process_utils.py:190} INFO - Requirement already satisfied: kiwisolver>=1.0.1 in /home/***/.local/lib/python3.8/site-packages (from matplotlib<4->mlflow==2.10.2->-r /tmp/venv8qgl3nx0/requirements.txt (line 2)) (1.4.5)
[2024-04-24T23:43:48.426+0000] {process_utils.py:190} INFO - Requirement already satisfied: pillow>=6.2.0 in /home/***/.local/lib/python3.8/site-packages (from matplotlib<4->mlflow==2.10.2->-r /tmp/venv8qgl3nx0/requirements.txt (line 2)) (10.3.0)
[2024-04-24T23:43:48.427+0000] {process_utils.py:190} INFO - Requirement already satisfied: pyparsing>=2.3.1 in /home/***/.local/lib/python3.8/site-packages (from matplotlib<4->mlflow==2.10.2->-r /tmp/venv8qgl3nx0/requirements.txt (line 2)) (3.1.1)
[2024-04-24T23:43:48.511+0000] {process_utils.py:190} INFO - Requirement already satisfied: tzdata>=2022.1 in /home/***/.local/lib/python3.8/site-packages (from pandas<2.1.0,>=1.2.0->awswrangler==3.6.0->-r /tmp/venv8qgl3nx0/requirements.txt (line 1)) (2023.4)
[2024-04-24T23:43:48.526+0000] {process_utils.py:190} INFO - Requirement already satisfied: six in /home/***/.local/lib/python3.8/site-packages (from querystring-parser<2->mlflow==2.10.2->-r /tmp/venv8qgl3nx0/requirements.txt (line 2)) (1.16.0)
[2024-04-24T23:43:48.534+0000] {process_utils.py:190} INFO - Requirement already satisfied: charset-normalizer<4,>=2 in /home/***/.local/lib/python3.8/site-packages (from requests<3,>=2.17.3->mlflow==2.10.2->-r /tmp/venv8qgl3nx0/requirements.txt (line 2)) (3.3.2)
[2024-04-24T23:43:48.534+0000] {process_utils.py:190} INFO - Requirement already satisfied: idna<4,>=2.5 in /home/***/.local/lib/python3.8/site-packages (from requests<3,>=2.17.3->mlflow==2.10.2->-r /tmp/venv8qgl3nx0/requirements.txt (line 2)) (3.6)
[2024-04-24T23:43:48.535+0000] {process_utils.py:190} INFO - Requirement already satisfied: certifi>=2017.4.17 in /home/***/.local/lib/python3.8/site-packages (from requests<3,>=2.17.3->mlflow==2.10.2->-r /tmp/venv8qgl3nx0/requirements.txt (line 2)) (2023.11.17)
[2024-04-24T23:43:48.619+0000] {process_utils.py:190} INFO - Requirement already satisfied: greenlet!=0.4.17 in /home/***/.local/lib/python3.8/site-packages (from sqlalchemy<3,>=1.4.0->mlflow==2.10.2->-r /tmp/venv8qgl3nx0/requirements.txt (line 2)) (3.0.3)
[2024-04-24T23:43:48.738+0000] {process_utils.py:190} INFO - Requirement already satisfied: smmap<6,>=3.0.1 in /home/***/.local/lib/python3.8/site-packages (from gitdb<5,>=4.0.1->gitpython<4,>=2.1.0->mlflow==2.10.2->-r /tmp/venv8qgl3nx0/requirements.txt (line 2)) (5.0.1)
[2024-04-24T23:43:48.890+0000] {process_utils.py:190} INFO - Using cached awswrangler-3.6.0-py3-none-any.whl (403 kB)
[2024-04-24T23:43:49.005+0000] {process_utils.py:190} INFO - Downloading mlflow-2.10.2-py3-none-any.whl (19.5 MB)
[2024-04-24T23:43:53.968+0000] {process_utils.py:190} INFO -    ━━━━━━━━━━━━━━━━━━━━━━━━━━━━━━━━━━━━━━━━ 19.5/19.5 MB 4.3 MB/s eta 0:00:00
[2024-04-24T23:43:56.126+0000] {process_utils.py:190} INFO - Installing collected packages: mlflow, awswrangler
[2024-04-24T23:43:56.126+0000] {process_utils.py:190} INFO -   Attempting uninstall: mlflow
[2024-04-24T23:43:56.128+0000] {process_utils.py:190} INFO -     Found existing installation: mlflow 2.12.1
[2024-04-24T23:43:56.129+0000] {process_utils.py:190} INFO -     Not uninstalling mlflow at /home/***/.local/lib/python3.8/site-packages, outside environment /tmp/venv8qgl3nx0
[2024-04-24T23:43:56.129+0000] {process_utils.py:190} INFO -     Can't uninstall 'mlflow'. No files were found to uninstall.
[2024-04-24T23:43:57.005+0000] {process_utils.py:190} INFO - Successfully installed awswrangler-3.6.0 mlflow-2.10.2
[2024-04-24T23:43:57.170+0000] {process_utils.py:190} INFO - 
[2024-04-24T23:43:57.171+0000] {process_utils.py:190} INFO - [notice] A new release of pip is available: 23.3.1 -> 24.0
[2024-04-24T23:43:57.171+0000] {process_utils.py:190} INFO - [notice] To update, run: python -m pip install --upgrade pip
[2024-04-24T23:43:57.303+0000] {process_utils.py:182} INFO - Executing cmd: /tmp/venv8qgl3nx0/bin/python /tmp/venv-callneqh2xwv/script.py /tmp/venv-callneqh2xwv/script.in /tmp/venv-callneqh2xwv/script.out /tmp/venv-callneqh2xwv/string_args.txt /tmp/venv-callneqh2xwv/termination.log
[2024-04-24T23:43:57.308+0000] {process_utils.py:186} INFO - Output:
[2024-04-24T23:43:59.568+0000] {process_utils.py:190} INFO - [[34m2024-04-24T23:43:59.567+0000[0m] {[34mconnectionpool.py:[0m824} WARNING[0m - Retrying (JitteredRetry(total=4, connect=4, read=5, redirect=5, status=5)) after connection broken by 'NewConnectionError('<urllib3.connection.HTTPConnection object at 0x7f2232888a60>: Failed to establish a new connection: [Errno 111] Connection refused')': /api/2.0/mlflow/registered-models/alias?name=mnist_784&alias=champion[0m
[2024-04-24T23:44:03.572+0000] {process_utils.py:190} INFO - [[34m2024-04-24T23:44:03.571+0000[0m] {[34mconnectionpool.py:[0m824} WARNING[0m - Retrying (JitteredRetry(total=3, connect=3, read=5, redirect=5, status=5)) after connection broken by 'NewConnectionError('<urllib3.connection.HTTPConnection object at 0x7f22328889d0>: Failed to establish a new connection: [Errno 111] Connection refused')': /api/2.0/mlflow/registered-models/alias?name=mnist_784&alias=champion[0m
[2024-04-24T23:44:11.581+0000] {process_utils.py:190} INFO - [[34m2024-04-24T23:44:11.581+0000[0m] {[34mconnectionpool.py:[0m824} WARNING[0m - Retrying (JitteredRetry(total=2, connect=2, read=5, redirect=5, status=5)) after connection broken by 'NewConnectionError('<urllib3.connection.HTTPConnection object at 0x7f2232888760>: Failed to establish a new connection: [Errno 111] Connection refused')': /api/2.0/mlflow/registered-models/alias?name=mnist_784&alias=champion[0m
[2024-04-24T23:44:27.614+0000] {process_utils.py:190} INFO - [[34m2024-04-24T23:44:27.613+0000[0m] {[34mconnectionpool.py:[0m824} WARNING[0m - Retrying (JitteredRetry(total=1, connect=1, read=5, redirect=5, status=5)) after connection broken by 'NewConnectionError('<urllib3.connection.HTTPConnection object at 0x7f22328f1d90>: Failed to establish a new connection: [Errno 111] Connection refused')': /api/2.0/mlflow/registered-models/alias?name=mnist_784&alias=champion[0m
[2024-04-24T23:44:59.633+0000] {process_utils.py:190} INFO - [[34m2024-04-24T23:44:59.633+0000[0m] {[34mconnectionpool.py:[0m824} WARNING[0m - Retrying (JitteredRetry(total=0, connect=0, read=5, redirect=5, status=5)) after connection broken by 'NewConnectionError('<urllib3.connection.HTTPConnection object at 0x7f22328f1a60>: Failed to establish a new connection: [Errno 111] Connection refused')': /api/2.0/mlflow/registered-models/alias?name=mnist_784&alias=champion[0m
[2024-04-24T23:44:59.636+0000] {process_utils.py:190} INFO - Traceback (most recent call last):
[2024-04-24T23:44:59.637+0000] {process_utils.py:190} INFO -   File "/home/***/.local/lib/python3.8/site-packages/urllib3/connection.py", line 174, in _new_conn
[2024-04-24T23:44:59.637+0000] {process_utils.py:190} INFO -     conn = connection.create_connection(
[2024-04-24T23:44:59.638+0000] {process_utils.py:190} INFO -   File "/home/***/.local/lib/python3.8/site-packages/urllib3/util/connection.py", line 95, in create_connection
[2024-04-24T23:44:59.638+0000] {process_utils.py:190} INFO -     raise err
[2024-04-24T23:44:59.638+0000] {process_utils.py:190} INFO -   File "/home/***/.local/lib/python3.8/site-packages/urllib3/util/connection.py", line 85, in create_connection
[2024-04-24T23:44:59.638+0000] {process_utils.py:190} INFO -     sock.connect(sa)
[2024-04-24T23:44:59.638+0000] {process_utils.py:190} INFO - ConnectionRefusedError: [Errno 111] Connection refused
[2024-04-24T23:44:59.639+0000] {process_utils.py:190} INFO - 
[2024-04-24T23:44:59.639+0000] {process_utils.py:190} INFO - During handling of the above exception, another exception occurred:
[2024-04-24T23:44:59.639+0000] {process_utils.py:190} INFO - 
[2024-04-24T23:44:59.639+0000] {process_utils.py:190} INFO - Traceback (most recent call last):
[2024-04-24T23:44:59.639+0000] {process_utils.py:190} INFO -   File "/home/***/.local/lib/python3.8/site-packages/urllib3/connectionpool.py", line 715, in urlopen
[2024-04-24T23:44:59.640+0000] {process_utils.py:190} INFO -     httplib_response = self._make_request(
[2024-04-24T23:44:59.640+0000] {process_utils.py:190} INFO -   File "/home/***/.local/lib/python3.8/site-packages/urllib3/connectionpool.py", line 416, in _make_request
[2024-04-24T23:44:59.640+0000] {process_utils.py:190} INFO -     conn.request(method, url, **httplib_request_kw)
[2024-04-24T23:44:59.640+0000] {process_utils.py:190} INFO -   File "/home/***/.local/lib/python3.8/site-packages/urllib3/connection.py", line 244, in request
[2024-04-24T23:44:59.641+0000] {process_utils.py:190} INFO -     super(HTTPConnection, self).request(method, url, body=body, headers=headers)
[2024-04-24T23:44:59.641+0000] {process_utils.py:190} INFO -   File "/usr/local/lib/python3.8/http/client.py", line 1256, in request
[2024-04-24T23:44:59.641+0000] {process_utils.py:190} INFO -     self._send_request(method, url, body, headers, encode_chunked)
[2024-04-24T23:44:59.641+0000] {process_utils.py:190} INFO -   File "/usr/local/lib/python3.8/http/client.py", line 1302, in _send_request
[2024-04-24T23:44:59.641+0000] {process_utils.py:190} INFO -     self.endheaders(body, encode_chunked=encode_chunked)
[2024-04-24T23:44:59.642+0000] {process_utils.py:190} INFO -   File "/usr/local/lib/python3.8/http/client.py", line 1251, in endheaders
[2024-04-24T23:44:59.642+0000] {process_utils.py:190} INFO -     self._send_output(message_body, encode_chunked=encode_chunked)
[2024-04-24T23:44:59.642+0000] {process_utils.py:190} INFO -   File "/usr/local/lib/python3.8/http/client.py", line 1011, in _send_output
[2024-04-24T23:44:59.642+0000] {process_utils.py:190} INFO -     self.send(msg)
[2024-04-24T23:44:59.643+0000] {process_utils.py:190} INFO -   File "/usr/local/lib/python3.8/http/client.py", line 951, in send
[2024-04-24T23:44:59.643+0000] {process_utils.py:190} INFO -     self.connect()
[2024-04-24T23:44:59.643+0000] {process_utils.py:190} INFO -   File "/home/***/.local/lib/python3.8/site-packages/urllib3/connection.py", line 205, in connect
[2024-04-24T23:44:59.643+0000] {process_utils.py:190} INFO -     conn = self._new_conn()
[2024-04-24T23:44:59.644+0000] {process_utils.py:190} INFO -   File "/home/***/.local/lib/python3.8/site-packages/urllib3/connection.py", line 186, in _new_conn
[2024-04-24T23:44:59.644+0000] {process_utils.py:190} INFO -     raise NewConnectionError(
[2024-04-24T23:44:59.644+0000] {process_utils.py:190} INFO - urllib3.exceptions.NewConnectionError: <urllib3.connection.HTTPConnection object at 0x7f22328f1d60>: Failed to establish a new connection: [Errno 111] Connection refused
[2024-04-24T23:44:59.644+0000] {process_utils.py:190} INFO - 
[2024-04-24T23:44:59.645+0000] {process_utils.py:190} INFO - During handling of the above exception, another exception occurred:
[2024-04-24T23:44:59.645+0000] {process_utils.py:190} INFO - 
[2024-04-24T23:44:59.645+0000] {process_utils.py:190} INFO - Traceback (most recent call last):
[2024-04-24T23:44:59.645+0000] {process_utils.py:190} INFO -   File "/home/***/.local/lib/python3.8/site-packages/requests/adapters.py", line 486, in send
[2024-04-24T23:44:59.645+0000] {process_utils.py:190} INFO -     resp = conn.urlopen(
[2024-04-24T23:44:59.646+0000] {process_utils.py:190} INFO -   File "/home/***/.local/lib/python3.8/site-packages/urllib3/connectionpool.py", line 827, in urlopen
[2024-04-24T23:44:59.646+0000] {process_utils.py:190} INFO -     return self.urlopen(
[2024-04-24T23:44:59.646+0000] {process_utils.py:190} INFO -   File "/home/***/.local/lib/python3.8/site-packages/urllib3/connectionpool.py", line 827, in urlopen
[2024-04-24T23:44:59.646+0000] {process_utils.py:190} INFO -     return self.urlopen(
[2024-04-24T23:44:59.647+0000] {process_utils.py:190} INFO -   File "/home/***/.local/lib/python3.8/site-packages/urllib3/connectionpool.py", line 827, in urlopen
[2024-04-24T23:44:59.647+0000] {process_utils.py:190} INFO -     return self.urlopen(
[2024-04-24T23:44:59.647+0000] {process_utils.py:190} INFO -   [Previous line repeated 2 more times]
[2024-04-24T23:44:59.647+0000] {process_utils.py:190} INFO -   File "/home/***/.local/lib/python3.8/site-packages/urllib3/connectionpool.py", line 799, in urlopen
[2024-04-24T23:44:59.647+0000] {process_utils.py:190} INFO -     retries = retries.increment(
[2024-04-24T23:44:59.648+0000] {process_utils.py:190} INFO -   File "/home/***/.local/lib/python3.8/site-packages/urllib3/util/retry.py", line 592, in increment
[2024-04-24T23:44:59.648+0000] {process_utils.py:190} INFO -     raise MaxRetryError(_pool, url, error or ResponseError(cause))
[2024-04-24T23:44:59.648+0000] {process_utils.py:190} INFO - urllib3.exceptions.MaxRetryError: HTTPConnectionPool(host='mlflow', port=5000): Max retries exceeded with url: /api/2.0/mlflow/registered-models/alias?name=mnist_784&alias=champion (Caused by NewConnectionError('<urllib3.connection.HTTPConnection object at 0x7f22328f1d60>: Failed to establish a new connection: [Errno 111] Connection refused'))
[2024-04-24T23:44:59.648+0000] {process_utils.py:190} INFO - 
[2024-04-24T23:44:59.649+0000] {process_utils.py:190} INFO - During handling of the above exception, another exception occurred:
[2024-04-24T23:44:59.649+0000] {process_utils.py:190} INFO - 
[2024-04-24T23:44:59.649+0000] {process_utils.py:190} INFO - Traceback (most recent call last):
[2024-04-24T23:44:59.649+0000] {process_utils.py:190} INFO -   File "/tmp/venv8qgl3nx0/lib/python3.8/site-packages/mlflow/utils/rest_utils.py", line 108, in http_request
[2024-04-24T23:44:59.650+0000] {process_utils.py:190} INFO -     return _get_http_response_with_retries(
[2024-04-24T23:44:59.650+0000] {process_utils.py:190} INFO -   File "/tmp/venv8qgl3nx0/lib/python3.8/site-packages/mlflow/utils/request_utils.py", line 212, in _get_http_response_with_retries
[2024-04-24T23:44:59.650+0000] {process_utils.py:190} INFO -     return session.request(method, url, allow_redirects=allow_redirects, **kwargs)
[2024-04-24T23:44:59.650+0000] {process_utils.py:190} INFO -   File "/home/***/.local/lib/python3.8/site-packages/requests/sessions.py", line 589, in request
[2024-04-24T23:44:59.651+0000] {process_utils.py:190} INFO -     resp = self.send(prep, **send_kwargs)
[2024-04-24T23:44:59.651+0000] {process_utils.py:190} INFO -   File "/home/***/.local/lib/python3.8/site-packages/requests/sessions.py", line 703, in send
[2024-04-24T23:44:59.651+0000] {process_utils.py:190} INFO -     r = adapter.send(request, **kwargs)
[2024-04-24T23:44:59.651+0000] {process_utils.py:190} INFO -   File "/home/***/.local/lib/python3.8/site-packages/requests/adapters.py", line 519, in send
[2024-04-24T23:44:59.652+0000] {process_utils.py:190} INFO -     raise ConnectionError(e, request=request)
[2024-04-24T23:44:59.652+0000] {process_utils.py:190} INFO - requests.exceptions.ConnectionError: HTTPConnectionPool(host='mlflow', port=5000): Max retries exceeded with url: /api/2.0/mlflow/registered-models/alias?name=mnist_784&alias=champion (Caused by NewConnectionError('<urllib3.connection.HTTPConnection object at 0x7f22328f1d60>: Failed to establish a new connection: [Errno 111] Connection refused'))
[2024-04-24T23:44:59.652+0000] {process_utils.py:190} INFO - 
[2024-04-24T23:44:59.653+0000] {process_utils.py:190} INFO - During handling of the above exception, another exception occurred:
[2024-04-24T23:44:59.653+0000] {process_utils.py:190} INFO - 
[2024-04-24T23:44:59.653+0000] {process_utils.py:190} INFO - Traceback (most recent call last):
[2024-04-24T23:44:59.654+0000] {process_utils.py:190} INFO -   File "/tmp/venv-callneqh2xwv/script.py", line 132, in <module>
[2024-04-24T23:44:59.654+0000] {process_utils.py:190} INFO -     res = train_the_challenger_model(*arg_dict["args"], **arg_dict["kwargs"])
[2024-04-24T23:44:59.654+0000] {process_utils.py:190} INFO -   File "/tmp/venv-callneqh2xwv/script.py", line 110, in train_the_challenger_model
[2024-04-24T23:44:59.654+0000] {process_utils.py:190} INFO -     champion_model = load_the_champion_model()
[2024-04-24T23:44:59.655+0000] {process_utils.py:190} INFO -   File "/tmp/venv-callneqh2xwv/script.py", line 42, in load_the_champion_model
[2024-04-24T23:44:59.655+0000] {process_utils.py:190} INFO -     model_data = client.get_model_version_by_alias(model_name, alias)
[2024-04-24T23:44:59.655+0000] {process_utils.py:190} INFO -   File "/tmp/venv8qgl3nx0/lib/python3.8/site-packages/mlflow/tracking/client.py", line 3745, in get_model_version_by_alias
[2024-04-24T23:44:59.655+0000] {process_utils.py:190} INFO -     return self._get_registry_client().get_model_version_by_alias(name, alias)
[2024-04-24T23:44:59.656+0000] {process_utils.py:190} INFO -   File "/tmp/venv8qgl3nx0/lib/python3.8/site-packages/mlflow/tracking/_model_registry/client.py", line 366, in get_model_version_by_alias
[2024-04-24T23:44:59.656+0000] {process_utils.py:190} INFO -     return self.store.get_model_version_by_alias(name, alias)
[2024-04-24T23:44:59.656+0000] {process_utils.py:190} INFO -   File "/tmp/venv8qgl3nx0/lib/python3.8/site-packages/mlflow/store/model_registry/rest_store.py", line 400, in get_model_version_by_alias
[2024-04-24T23:44:59.656+0000] {process_utils.py:190} INFO -     response_proto = self._call_endpoint(GetModelVersionByAlias, req_body)
[2024-04-24T23:44:59.657+0000] {process_utils.py:190} INFO -   File "/tmp/venv8qgl3nx0/lib/python3.8/site-packages/mlflow/store/model_registry/base_rest_store.py", line 44, in _call_endpoint
[2024-04-24T23:44:59.657+0000] {process_utils.py:190} INFO -     return call_endpoint(
[2024-04-24T23:44:59.657+0000] {process_utils.py:190} INFO -   File "/tmp/venv8qgl3nx0/lib/python3.8/site-packages/mlflow/utils/rest_utils.py", line 216, in call_endpoint
[2024-04-24T23:44:59.657+0000] {process_utils.py:190} INFO -     response = http_request(**call_kwargs)
[2024-04-24T23:44:59.658+0000] {process_utils.py:190} INFO -   File "/tmp/venv8qgl3nx0/lib/python3.8/site-packages/mlflow/utils/rest_utils.py", line 130, in http_request
[2024-04-24T23:44:59.658+0000] {process_utils.py:190} INFO -     raise MlflowException(f"API request to {url} failed with exception {e}")
[2024-04-24T23:44:59.658+0000] {process_utils.py:190} INFO - mlflow.exceptions.MlflowException: API request to http://mlflow:5000/api/2.0/mlflow/registered-models/alias failed with exception HTTPConnectionPool(host='mlflow', port=5000): Max retries exceeded with url: /api/2.0/mlflow/registered-models/alias?name=mnist_784&alias=champion (Caused by NewConnectionError('<urllib3.connection.HTTPConnection object at 0x7f22328f1d60>: Failed to establish a new connection: [Errno 111] Connection refused'))
[2024-04-24T23:45:01.381+0000] {taskinstance.py:2698} ERROR - Task failed with exception
Traceback (most recent call last):
  File "/home/airflow/.local/lib/python3.8/site-packages/airflow/models/taskinstance.py", line 433, in _execute_task
    result = execute_callable(context=context, **execute_callable_kwargs)
  File "/home/airflow/.local/lib/python3.8/site-packages/airflow/decorators/base.py", line 241, in execute
    return_value = super().execute(context)
  File "/home/airflow/.local/lib/python3.8/site-packages/airflow/operators/python.py", line 400, in execute
    return super().execute(context=serializable_context)
  File "/home/airflow/.local/lib/python3.8/site-packages/airflow/operators/python.py", line 199, in execute
    return_value = self.execute_callable()
  File "/home/airflow/.local/lib/python3.8/site-packages/airflow/operators/python.py", line 716, in execute_callable
    result = self._execute_python_callable_in_subprocess(python_path)
  File "/home/airflow/.local/lib/python3.8/site-packages/airflow/operators/python.py", line 471, in _execute_python_callable_in_subprocess
    raise AirflowException(error_msg) from None
airflow.exceptions.AirflowException: Process returned non-zero exit status 1.
API request to http://mlflow:5000/api/2.0/mlflow/registered-models/alias failed with exception HTTPConnectionPool(host='mlflow', port=5000): Max retries exceeded with url: /api/2.0/mlflow/registered-models/alias?name=mnist_784&alias=champion (Caused by NewConnectionError('<urllib3.connection.HTTPConnection object at 0x7f22328f1d60>: Failed to establish a new connection: [Errno 111] Connection refused'))
[2024-04-24T23:45:01.529+0000] {taskinstance.py:1138} INFO - Marking task as UP_FOR_RETRY. dag_id=retrain_the_model_mnist_784, task_id=train_the_challenger_model, execution_date=20240424T234344, start_date=20240424T234346, end_date=20240424T234501
[2024-04-24T23:45:01.542+0000] {standard_task_runner.py:107} ERROR - Failed to execute job 38 for task train_the_challenger_model (Process returned non-zero exit status 1.
API request to http://mlflow:5000/api/2.0/mlflow/registered-models/alias failed with exception HTTPConnectionPool(host='mlflow', port=5000): Max retries exceeded with url: /api/2.0/mlflow/registered-models/alias?name=mnist_784&alias=champion (Caused by NewConnectionError('<urllib3.connection.HTTPConnection object at 0x7f22328f1d60>: Failed to establish a new connection: [Errno 111] Connection refused')); 13411)
[2024-04-24T23:45:01.863+0000] {local_task_job_runner.py:234} INFO - Task exited with return code 1
[2024-04-24T23:45:01.894+0000] {taskinstance.py:3280} INFO - 0 downstream tasks scheduled from follow-on schedule check
