[2024-04-25T04:00:23.516+0000] {taskinstance.py:1956} INFO - Dependencies all met for dep_context=non-requeueable deps ti=<TaskInstance: process_etl_mnist_784_data.train_model scheduled__2024-04-24T00:00:00+00:00 [queued]>
[2024-04-25T04:00:23.524+0000] {taskinstance.py:1956} INFO - Dependencies all met for dep_context=requeueable deps ti=<TaskInstance: process_etl_mnist_784_data.train_model scheduled__2024-04-24T00:00:00+00:00 [queued]>
[2024-04-25T04:00:23.524+0000] {taskinstance.py:2170} INFO - Starting attempt 1 of 2
[2024-04-25T04:00:23.554+0000] {taskinstance.py:2191} INFO - Executing <Task(_PythonVirtualenvDecoratedOperator): train_model> on 2024-04-24 00:00:00+00:00
[2024-04-25T04:00:23.560+0000] {standard_task_runner.py:60} INFO - Started process 8875 to run task
[2024-04-25T04:00:23.563+0000] {standard_task_runner.py:87} INFO - Running: ['***', 'tasks', 'run', 'process_etl_mnist_784_data', 'train_model', 'scheduled__2024-04-24T00:00:00+00:00', '--job-id', '4', '--raw', '--subdir', 'DAGS_FOLDER/etl_process.py', '--cfg-path', '/tmp/tmp2yjaoe0g']
[2024-04-25T04:00:23.566+0000] {standard_task_runner.py:88} INFO - Job 4: Subtask train_model
[2024-04-25T04:00:23.646+0000] {task_command.py:423} INFO - Running <TaskInstance: process_etl_mnist_784_data.train_model scheduled__2024-04-24T00:00:00+00:00 [running]> on host b7ac1838226b
[2024-04-25T04:00:23.721+0000] {taskinstance.py:2480} INFO - Exporting env vars: AIRFLOW_CTX_DAG_OWNER='Carlos Rodriguez' AIRFLOW_CTX_DAG_ID='process_etl_mnist_784_data' AIRFLOW_CTX_TASK_ID='train_model' AIRFLOW_CTX_EXECUTION_DATE='2024-04-24T00:00:00+00:00' AIRFLOW_CTX_TRY_NUMBER='1' AIRFLOW_CTX_DAG_RUN_ID='scheduled__2024-04-24T00:00:00+00:00'
[2024-04-25T04:00:23.723+0000] {process_utils.py:182} INFO - Executing cmd: /usr/local/bin/python -m virtualenv /tmp/venv8132zar_ --system-site-packages --python=python
[2024-04-25T04:00:23.731+0000] {process_utils.py:186} INFO - Output:
[2024-04-25T04:00:24.294+0000] {process_utils.py:190} INFO - created virtual environment CPython3.8.18.final.0-64 in 182ms
[2024-04-25T04:00:24.294+0000] {process_utils.py:190} INFO -   creator CPython3Posix(dest=/tmp/venv8132zar_, clear=False, no_vcs_ignore=False, global=True)
[2024-04-25T04:00:24.295+0000] {process_utils.py:190} INFO -   seeder FromAppData(download=False, pip=bundle, setuptools=bundle, wheel=bundle, via=copy, app_data_dir=/home/***/.local/share/virtualenv)
[2024-04-25T04:00:24.295+0000] {process_utils.py:190} INFO -     added seed packages: pip==23.3.1, setuptools==69.0.2, wheel==0.42.0
[2024-04-25T04:00:24.295+0000] {process_utils.py:190} INFO -   activators BashActivator,CShellActivator,FishActivator,NushellActivator,PowerShellActivator,PythonActivator
[2024-04-25T04:00:24.329+0000] {process_utils.py:182} INFO - Executing cmd: /tmp/venv8132zar_/bin/pip install -r /tmp/venv8132zar_/requirements.txt
[2024-04-25T04:00:24.335+0000] {process_utils.py:186} INFO - Output:
[2024-04-25T04:00:25.197+0000] {process_utils.py:190} INFO - Collecting awswrangler==3.6.0 (from -r /tmp/venv8132zar_/requirements.txt (line 1))
[2024-04-25T04:00:25.198+0000] {process_utils.py:190} INFO -   Using cached awswrangler-3.6.0-py3-none-any.whl.metadata (23 kB)
[2024-04-25T04:00:25.230+0000] {process_utils.py:190} INFO - Requirement already satisfied: boto3<2.0.0,>=1.20.32 in /home/***/.local/lib/python3.8/site-packages (from awswrangler==3.6.0->-r /tmp/venv8132zar_/requirements.txt (line 1)) (1.34.88)
[2024-04-25T04:00:25.231+0000] {process_utils.py:190} INFO - Requirement already satisfied: botocore<2.0.0,>=1.23.32 in /home/***/.local/lib/python3.8/site-packages (from awswrangler==3.6.0->-r /tmp/venv8132zar_/requirements.txt (line 1)) (1.34.88)
[2024-04-25T04:00:25.232+0000] {process_utils.py:190} INFO - Requirement already satisfied: numpy<2.0,>=1.18 in /home/***/.local/lib/python3.8/site-packages (from awswrangler==3.6.0->-r /tmp/venv8132zar_/requirements.txt (line 1)) (1.24.4)
[2024-04-25T04:00:25.232+0000] {process_utils.py:190} INFO - Requirement already satisfied: packaging<24.0,>=21.1 in /home/***/.local/lib/python3.8/site-packages (from awswrangler==3.6.0->-r /tmp/venv8132zar_/requirements.txt (line 1)) (23.2)
[2024-04-25T04:00:25.233+0000] {process_utils.py:190} INFO - Requirement already satisfied: pandas<2.1.0,>=1.2.0 in /home/***/.local/lib/python3.8/site-packages (from awswrangler==3.6.0->-r /tmp/venv8132zar_/requirements.txt (line 1)) (2.0.3)
[2024-04-25T04:00:25.234+0000] {process_utils.py:190} INFO - Requirement already satisfied: pyarrow>=7.0.0 in /home/***/.local/lib/python3.8/site-packages (from awswrangler==3.6.0->-r /tmp/venv8132zar_/requirements.txt (line 1)) (14.0.2)
[2024-04-25T04:00:25.234+0000] {process_utils.py:190} INFO - Requirement already satisfied: typing-extensions<5.0.0,>=4.4.0 in /home/***/.local/lib/python3.8/site-packages (from awswrangler==3.6.0->-r /tmp/venv8132zar_/requirements.txt (line 1)) (4.9.0)
[2024-04-25T04:00:25.238+0000] {process_utils.py:190} INFO - Requirement already satisfied: jmespath<2.0.0,>=0.7.1 in /home/***/.local/lib/python3.8/site-packages (from boto3<2.0.0,>=1.20.32->awswrangler==3.6.0->-r /tmp/venv8132zar_/requirements.txt (line 1)) (0.10.0)
[2024-04-25T04:00:25.238+0000] {process_utils.py:190} INFO - Requirement already satisfied: s3transfer<0.11.0,>=0.10.0 in /home/***/.local/lib/python3.8/site-packages (from boto3<2.0.0,>=1.20.32->awswrangler==3.6.0->-r /tmp/venv8132zar_/requirements.txt (line 1)) (0.10.1)
[2024-04-25T04:00:25.243+0000] {process_utils.py:190} INFO - Requirement already satisfied: python-dateutil<3.0.0,>=2.1 in /home/***/.local/lib/python3.8/site-packages (from botocore<2.0.0,>=1.23.32->awswrangler==3.6.0->-r /tmp/venv8132zar_/requirements.txt (line 1)) (2.8.2)
[2024-04-25T04:00:25.243+0000] {process_utils.py:190} INFO - Requirement already satisfied: urllib3<1.27,>=1.25.4 in /home/***/.local/lib/python3.8/site-packages (from botocore<2.0.0,>=1.23.32->awswrangler==3.6.0->-r /tmp/venv8132zar_/requirements.txt (line 1)) (1.26.18)
[2024-04-25T04:00:25.305+0000] {process_utils.py:190} INFO - Requirement already satisfied: pytz>=2020.1 in /home/***/.local/lib/python3.8/site-packages (from pandas<2.1.0,>=1.2.0->awswrangler==3.6.0->-r /tmp/venv8132zar_/requirements.txt (line 1)) (2023.3.post1)
[2024-04-25T04:00:25.306+0000] {process_utils.py:190} INFO - Requirement already satisfied: tzdata>=2022.1 in /home/***/.local/lib/python3.8/site-packages (from pandas<2.1.0,>=1.2.0->awswrangler==3.6.0->-r /tmp/venv8132zar_/requirements.txt (line 1)) (2023.4)
[2024-04-25T04:00:25.317+0000] {process_utils.py:190} INFO - Requirement already satisfied: six>=1.5 in /home/***/.local/lib/python3.8/site-packages (from python-dateutil<3.0.0,>=2.1->botocore<2.0.0,>=1.23.32->awswrangler==3.6.0->-r /tmp/venv8132zar_/requirements.txt (line 1)) (1.16.0)
[2024-04-25T04:00:25.366+0000] {process_utils.py:190} INFO - Using cached awswrangler-3.6.0-py3-none-any.whl (403 kB)
[2024-04-25T04:00:27.587+0000] {process_utils.py:190} INFO - Installing collected packages: awswrangler
[2024-04-25T04:00:27.743+0000] {process_utils.py:190} INFO - Successfully installed awswrangler-3.6.0
[2024-04-25T04:00:27.885+0000] {process_utils.py:190} INFO - 
[2024-04-25T04:00:27.885+0000] {process_utils.py:190} INFO - [notice] A new release of pip is available: 23.3.1 -> 24.0
[2024-04-25T04:00:27.886+0000] {process_utils.py:190} INFO - [notice] To update, run: python -m pip install --upgrade pip
[2024-04-25T04:00:28.098+0000] {process_utils.py:182} INFO - Executing cmd: /tmp/venv8132zar_/bin/python /tmp/venv-call59enxetk/script.py /tmp/venv-call59enxetk/script.in /tmp/venv-call59enxetk/script.out /tmp/venv-call59enxetk/string_args.txt /tmp/venv-call59enxetk/termination.log
[2024-04-25T04:00:28.103+0000] {process_utils.py:186} INFO - Output:
[2024-04-25T04:00:30.237+0000] {process_utils.py:190} INFO - [[34m2024-04-25T04:00:30.237+0000[0m] {[34mcredentials.py:[0m1147} INFO[0m - Found credentials in environment variables.[0m
[2024-04-25T04:00:30.275+0000] {process_utils.py:190} INFO - [[34m2024-04-25T04:00:30.275+0000[0m] {[34mconfigprovider.py:[0m957} INFO[0m - Found endpoint for s3 via: environment_service.[0m
[2024-04-25T04:00:36.605+0000] {process_utils.py:190} INFO - [[34m2024-04-25T04:00:36.604+0000[0m] {[34mcredentials.py:[0m1147} INFO[0m - Found credentials in environment variables.[0m
[2024-04-25T04:00:36.667+0000] {process_utils.py:190} INFO - [[34m2024-04-25T04:00:36.666+0000[0m] {[34mconfigprovider.py:[0m957} INFO[0m - Found endpoint for s3 via: environment_service.[0m
[2024-04-25T04:00:36.678+0000] {process_utils.py:190} INFO - Traceback (most recent call last):
[2024-04-25T04:00:36.679+0000] {process_utils.py:190} INFO -   File "/tmp/venv-call59enxetk/script.py", line 127, in <module>
[2024-04-25T04:00:36.680+0000] {process_utils.py:190} INFO -     res = train_model(*arg_dict["args"], **arg_dict["kwargs"])
[2024-04-25T04:00:36.680+0000] {process_utils.py:190} INFO -   File "/tmp/venv-call59enxetk/script.py", line 64, in train_model
[2024-04-25T04:00:36.680+0000] {process_utils.py:190} INFO -     client.put_object(
[2024-04-25T04:00:36.681+0000] {process_utils.py:190} INFO -   File "/home/***/.local/lib/python3.8/site-packages/botocore/client.py", line 565, in _api_call
[2024-04-25T04:00:36.681+0000] {process_utils.py:190} INFO -     return self._make_api_call(operation_name, kwargs)
[2024-04-25T04:00:36.681+0000] {process_utils.py:190} INFO -   File "/home/***/.local/lib/python3.8/site-packages/botocore/client.py", line 974, in _make_api_call
[2024-04-25T04:00:36.681+0000] {process_utils.py:190} INFO -     request_dict = self._convert_to_request_dict(
[2024-04-25T04:00:36.682+0000] {process_utils.py:190} INFO -   File "/home/***/.local/lib/python3.8/site-packages/botocore/client.py", line 1048, in _convert_to_request_dict
[2024-04-25T04:00:36.682+0000] {process_utils.py:190} INFO -     request_dict = self._serializer.serialize_to_request(
[2024-04-25T04:00:36.682+0000] {process_utils.py:190} INFO -   File "/home/***/.local/lib/python3.8/site-packages/botocore/validate.py", line 381, in serialize_to_request
[2024-04-25T04:00:36.682+0000] {process_utils.py:190} INFO -     raise ParamValidationError(report=report.generate_report())
[2024-04-25T04:00:36.683+0000] {process_utils.py:190} INFO - botocore.exceptions.ParamValidationError: Parameter validation failed:
[2024-04-25T04:00:36.683+0000] {process_utils.py:190} INFO - Invalid type for parameter Body, value: Index(['pixel1', 'pixel2', 'pixel3', 'pixel4', 'pixel5', 'pixel6', 'pixel7',
[2024-04-25T04:00:36.683+0000] {process_utils.py:190} INFO -        'pixel8', 'pixel9', 'pixel10',
[2024-04-25T04:00:36.683+0000] {process_utils.py:190} INFO -        ...
[2024-04-25T04:00:36.684+0000] {process_utils.py:190} INFO -        'pixel776', 'pixel777', 'pixel778', 'pixel779', 'pixel780', 'pixel781',
[2024-04-25T04:00:36.684+0000] {process_utils.py:190} INFO -        'pixel782', 'pixel783', 'pixel784', 'label'],
[2024-04-25T04:00:36.684+0000] {process_utils.py:190} INFO -       dtype='object', length=785), type: <class 'pandas.core.indexes.base.Index'>, valid types: <class 'bytes'>, <class 'bytearray'>, file-like object
[2024-04-25T04:00:37.580+0000] {taskinstance.py:2698} ERROR - Task failed with exception
Traceback (most recent call last):
  File "/home/airflow/.local/lib/python3.8/site-packages/airflow/models/taskinstance.py", line 433, in _execute_task
    result = execute_callable(context=context, **execute_callable_kwargs)
  File "/home/airflow/.local/lib/python3.8/site-packages/airflow/decorators/base.py", line 241, in execute
    return_value = super().execute(context)
  File "/home/airflow/.local/lib/python3.8/site-packages/airflow/operators/python.py", line 400, in execute
    return super().execute(context=serializable_context)
  File "/home/airflow/.local/lib/python3.8/site-packages/airflow/operators/python.py", line 199, in execute
    return_value = self.execute_callable()
  File "/home/airflow/.local/lib/python3.8/site-packages/airflow/operators/python.py", line 716, in execute_callable
    result = self._execute_python_callable_in_subprocess(python_path)
  File "/home/airflow/.local/lib/python3.8/site-packages/airflow/operators/python.py", line 471, in _execute_python_callable_in_subprocess
    raise AirflowException(error_msg) from None
airflow.exceptions.AirflowException: Process returned non-zero exit status 1.
Parameter validation failed:
Invalid type for parameter Body, value: Index(['pixel1', 'pixel2', 'pixel3', 'pixel4', 'pixel5', 'pixel6', 'pixel7',
       'pixel8', 'pixel9', 'pixel10',
       ...
       'pixel776', 'pixel777', 'pixel778', 'pixel779', 'pixel780', 'pixel781',
       'pixel782', 'pixel783', 'pixel784', 'label'],
      dtype='object', length=785), type: <class 'pandas.core.indexes.base.Index'>, valid types: <class 'bytes'>, <class 'bytearray'>, file-like object
[2024-04-25T04:00:37.583+0000] {taskinstance.py:1138} INFO - Marking task as UP_FOR_RETRY. dag_id=process_etl_mnist_784_data, task_id=train_model, execution_date=20240424T000000, start_date=20240425T040023, end_date=20240425T040037
[2024-04-25T04:00:37.592+0000] {standard_task_runner.py:107} ERROR - Failed to execute job 4 for task train_model (Process returned non-zero exit status 1.
Parameter validation failed:
Invalid type for parameter Body, value: Index(['pixel1', 'pixel2', 'pixel3', 'pixel4', 'pixel5', 'pixel6', 'pixel7',
       'pixel8', 'pixel9', 'pixel10',
       ...
       'pixel776', 'pixel777', 'pixel778', 'pixel779', 'pixel780', 'pixel781',
       'pixel782', 'pixel783', 'pixel784', 'label'],
      dtype='object', length=785), type: <class 'pandas.core.indexes.base.Index'>, valid types: <class 'bytes'>, <class 'bytearray'>, file-like object; 8875)
[2024-04-25T04:00:37.606+0000] {local_task_job_runner.py:234} INFO - Task exited with return code 1
[2024-04-25T04:00:37.617+0000] {taskinstance.py:3280} INFO - 0 downstream tasks scheduled from follow-on schedule check
[2024-04-25T20:00:38.427+0000] {taskinstance.py:1956} INFO - Dependencies all met for dep_context=non-requeueable deps ti=<TaskInstance: process_etl_mnist_784_data.train_model scheduled__2024-04-24T00:00:00+00:00 [queued]>
[2024-04-25T20:00:38.432+0000] {taskinstance.py:1956} INFO - Dependencies all met for dep_context=requeueable deps ti=<TaskInstance: process_etl_mnist_784_data.train_model scheduled__2024-04-24T00:00:00+00:00 [queued]>
[2024-04-25T20:00:38.433+0000] {taskinstance.py:2170} INFO - Starting attempt 1 of 2
[2024-04-25T20:00:38.441+0000] {taskinstance.py:2191} INFO - Executing <Task(_PythonVirtualenvDecoratedOperator): train_model> on 2024-04-24 00:00:00+00:00
[2024-04-25T20:00:38.445+0000] {standard_task_runner.py:60} INFO - Started process 9252 to run task
[2024-04-25T20:00:38.447+0000] {standard_task_runner.py:87} INFO - Running: ['***', 'tasks', 'run', 'process_etl_mnist_784_data', 'train_model', 'scheduled__2024-04-24T00:00:00+00:00', '--job-id', '4', '--raw', '--subdir', 'DAGS_FOLDER/etl_process.py', '--cfg-path', '/tmp/tmpnb9kd3ht']
[2024-04-25T20:00:38.449+0000] {standard_task_runner.py:88} INFO - Job 4: Subtask train_model
[2024-04-25T20:00:38.478+0000] {task_command.py:423} INFO - Running <TaskInstance: process_etl_mnist_784_data.train_model scheduled__2024-04-24T00:00:00+00:00 [running]> on host fc2c8bd597e1
[2024-04-25T20:00:38.560+0000] {taskinstance.py:2480} INFO - Exporting env vars: AIRFLOW_CTX_DAG_OWNER='Carlos Rodriguez' AIRFLOW_CTX_DAG_ID='process_etl_mnist_784_data' AIRFLOW_CTX_TASK_ID='train_model' AIRFLOW_CTX_EXECUTION_DATE='2024-04-24T00:00:00+00:00' AIRFLOW_CTX_TRY_NUMBER='1' AIRFLOW_CTX_DAG_RUN_ID='scheduled__2024-04-24T00:00:00+00:00'
[2024-04-25T20:00:38.561+0000] {process_utils.py:182} INFO - Executing cmd: /usr/local/bin/python -m virtualenv /tmp/venvew0qys38 --system-site-packages --python=python
[2024-04-25T20:00:38.568+0000] {process_utils.py:186} INFO - Output:
[2024-04-25T20:00:39.033+0000] {process_utils.py:190} INFO - created virtual environment CPython3.8.18.final.0-64 in 200ms
[2024-04-25T20:00:39.034+0000] {process_utils.py:190} INFO -   creator CPython3Posix(dest=/tmp/venvew0qys38, clear=False, no_vcs_ignore=False, global=True)
[2024-04-25T20:00:39.034+0000] {process_utils.py:190} INFO -   seeder FromAppData(download=False, pip=bundle, setuptools=bundle, wheel=bundle, via=copy, app_data_dir=/home/***/.local/share/virtualenv)
[2024-04-25T20:00:39.035+0000] {process_utils.py:190} INFO -     added seed packages: pip==23.3.1, setuptools==69.0.2, wheel==0.42.0
[2024-04-25T20:00:39.035+0000] {process_utils.py:190} INFO -   activators BashActivator,CShellActivator,FishActivator,NushellActivator,PowerShellActivator,PythonActivator
[2024-04-25T20:00:39.072+0000] {process_utils.py:182} INFO - Executing cmd: /tmp/venvew0qys38/bin/pip install -r /tmp/venvew0qys38/requirements.txt
[2024-04-25T20:00:39.078+0000] {process_utils.py:186} INFO - Output:
[2024-04-25T20:00:39.969+0000] {process_utils.py:190} INFO - Collecting awswrangler==3.6.0 (from -r /tmp/venvew0qys38/requirements.txt (line 1))
[2024-04-25T20:00:39.971+0000] {process_utils.py:190} INFO -   Using cached awswrangler-3.6.0-py3-none-any.whl.metadata (23 kB)
[2024-04-25T20:00:40.008+0000] {process_utils.py:190} INFO - Requirement already satisfied: boto3<2.0.0,>=1.20.32 in /home/***/.local/lib/python3.8/site-packages (from awswrangler==3.6.0->-r /tmp/venvew0qys38/requirements.txt (line 1)) (1.34.88)
[2024-04-25T20:00:40.008+0000] {process_utils.py:190} INFO - Requirement already satisfied: botocore<2.0.0,>=1.23.32 in /home/***/.local/lib/python3.8/site-packages (from awswrangler==3.6.0->-r /tmp/venvew0qys38/requirements.txt (line 1)) (1.34.88)
[2024-04-25T20:00:40.009+0000] {process_utils.py:190} INFO - Requirement already satisfied: numpy<2.0,>=1.18 in /home/***/.local/lib/python3.8/site-packages (from awswrangler==3.6.0->-r /tmp/venvew0qys38/requirements.txt (line 1)) (1.24.4)
[2024-04-25T20:00:40.009+0000] {process_utils.py:190} INFO - Requirement already satisfied: packaging<24.0,>=21.1 in /home/***/.local/lib/python3.8/site-packages (from awswrangler==3.6.0->-r /tmp/venvew0qys38/requirements.txt (line 1)) (23.2)
[2024-04-25T20:00:40.010+0000] {process_utils.py:190} INFO - Requirement already satisfied: pandas<2.1.0,>=1.2.0 in /home/***/.local/lib/python3.8/site-packages (from awswrangler==3.6.0->-r /tmp/venvew0qys38/requirements.txt (line 1)) (2.0.3)
[2024-04-25T20:00:40.011+0000] {process_utils.py:190} INFO - Requirement already satisfied: pyarrow>=7.0.0 in /home/***/.local/lib/python3.8/site-packages (from awswrangler==3.6.0->-r /tmp/venvew0qys38/requirements.txt (line 1)) (14.0.2)
[2024-04-25T20:00:40.011+0000] {process_utils.py:190} INFO - Requirement already satisfied: typing-extensions<5.0.0,>=4.4.0 in /home/***/.local/lib/python3.8/site-packages (from awswrangler==3.6.0->-r /tmp/venvew0qys38/requirements.txt (line 1)) (4.9.0)
[2024-04-25T20:00:40.015+0000] {process_utils.py:190} INFO - Requirement already satisfied: jmespath<2.0.0,>=0.7.1 in /home/***/.local/lib/python3.8/site-packages (from boto3<2.0.0,>=1.20.32->awswrangler==3.6.0->-r /tmp/venvew0qys38/requirements.txt (line 1)) (0.10.0)
[2024-04-25T20:00:40.015+0000] {process_utils.py:190} INFO - Requirement already satisfied: s3transfer<0.11.0,>=0.10.0 in /home/***/.local/lib/python3.8/site-packages (from boto3<2.0.0,>=1.20.32->awswrangler==3.6.0->-r /tmp/venvew0qys38/requirements.txt (line 1)) (0.10.1)
[2024-04-25T20:00:40.020+0000] {process_utils.py:190} INFO - Requirement already satisfied: python-dateutil<3.0.0,>=2.1 in /home/***/.local/lib/python3.8/site-packages (from botocore<2.0.0,>=1.23.32->awswrangler==3.6.0->-r /tmp/venvew0qys38/requirements.txt (line 1)) (2.8.2)
[2024-04-25T20:00:40.021+0000] {process_utils.py:190} INFO - Requirement already satisfied: urllib3<1.27,>=1.25.4 in /home/***/.local/lib/python3.8/site-packages (from botocore<2.0.0,>=1.23.32->awswrangler==3.6.0->-r /tmp/venvew0qys38/requirements.txt (line 1)) (1.26.18)
[2024-04-25T20:00:40.078+0000] {process_utils.py:190} INFO - Requirement already satisfied: pytz>=2020.1 in /home/***/.local/lib/python3.8/site-packages (from pandas<2.1.0,>=1.2.0->awswrangler==3.6.0->-r /tmp/venvew0qys38/requirements.txt (line 1)) (2023.3.post1)
[2024-04-25T20:00:40.078+0000] {process_utils.py:190} INFO - Requirement already satisfied: tzdata>=2022.1 in /home/***/.local/lib/python3.8/site-packages (from pandas<2.1.0,>=1.2.0->awswrangler==3.6.0->-r /tmp/venvew0qys38/requirements.txt (line 1)) (2023.4)
[2024-04-25T20:00:40.084+0000] {process_utils.py:190} INFO - Requirement already satisfied: six>=1.5 in /home/***/.local/lib/python3.8/site-packages (from python-dateutil<3.0.0,>=2.1->botocore<2.0.0,>=1.23.32->awswrangler==3.6.0->-r /tmp/venvew0qys38/requirements.txt (line 1)) (1.16.0)
[2024-04-25T20:00:40.105+0000] {process_utils.py:190} INFO - Using cached awswrangler-3.6.0-py3-none-any.whl (403 kB)
[2024-04-25T20:00:42.216+0000] {process_utils.py:190} INFO - Installing collected packages: awswrangler
[2024-04-25T20:00:42.377+0000] {process_utils.py:190} INFO - Successfully installed awswrangler-3.6.0
[2024-04-25T20:00:42.503+0000] {process_utils.py:190} INFO - 
[2024-04-25T20:00:42.504+0000] {process_utils.py:190} INFO - [notice] A new release of pip is available: 23.3.1 -> 24.0
[2024-04-25T20:00:42.504+0000] {process_utils.py:190} INFO - [notice] To update, run: python -m pip install --upgrade pip
[2024-04-25T20:00:42.597+0000] {process_utils.py:182} INFO - Executing cmd: /tmp/venvew0qys38/bin/python /tmp/venv-calltw1j9k9b/script.py /tmp/venv-calltw1j9k9b/script.in /tmp/venv-calltw1j9k9b/script.out /tmp/venv-calltw1j9k9b/string_args.txt /tmp/venv-calltw1j9k9b/termination.log
[2024-04-25T20:00:42.604+0000] {process_utils.py:186} INFO - Output:
[2024-04-25T20:00:44.854+0000] {process_utils.py:190} INFO - [[34m2024-04-25T20:00:44.854+0000[0m] {[34mcredentials.py:[0m1147} INFO[0m - Found credentials in environment variables.[0m
[2024-04-25T20:00:44.896+0000] {process_utils.py:190} INFO - [[34m2024-04-25T20:00:44.895+0000[0m] {[34mconfigprovider.py:[0m957} INFO[0m - Found endpoint for s3 via: environment_service.[0m
[2024-04-25T20:04:49.376+0000] {job.py:213} ERROR - Job heartbeat got an exception
Traceback (most recent call last):
  File "/home/airflow/.local/lib/python3.8/site-packages/sqlalchemy/engine/base.py", line 3371, in _wrap_pool_connect
    return fn()
  File "/home/airflow/.local/lib/python3.8/site-packages/sqlalchemy/pool/base.py", line 327, in connect
    return _ConnectionFairy._checkout(self)
  File "/home/airflow/.local/lib/python3.8/site-packages/sqlalchemy/pool/base.py", line 894, in _checkout
    fairy = _ConnectionRecord.checkout(pool)
  File "/home/airflow/.local/lib/python3.8/site-packages/sqlalchemy/pool/base.py", line 493, in checkout
    rec = pool._do_get()
  File "/home/airflow/.local/lib/python3.8/site-packages/sqlalchemy/pool/impl.py", line 256, in _do_get
    return self._create_connection()
  File "/home/airflow/.local/lib/python3.8/site-packages/sqlalchemy/pool/base.py", line 273, in _create_connection
    return _ConnectionRecord(self)
  File "/home/airflow/.local/lib/python3.8/site-packages/sqlalchemy/pool/base.py", line 388, in __init__
    self.__connect()
  File "/home/airflow/.local/lib/python3.8/site-packages/sqlalchemy/pool/base.py", line 691, in __connect
    pool.logger.debug("Error on connect(): %s", e)
  File "/home/airflow/.local/lib/python3.8/site-packages/sqlalchemy/util/langhelpers.py", line 70, in __exit__
    compat.raise_(
  File "/home/airflow/.local/lib/python3.8/site-packages/sqlalchemy/util/compat.py", line 211, in raise_
    raise exception
  File "/home/airflow/.local/lib/python3.8/site-packages/sqlalchemy/pool/base.py", line 686, in __connect
    self.dbapi_connection = connection = pool._invoke_creator(self)
  File "/home/airflow/.local/lib/python3.8/site-packages/sqlalchemy/engine/create.py", line 574, in connect
    return dialect.connect(*cargs, **cparams)
  File "/home/airflow/.local/lib/python3.8/site-packages/sqlalchemy/engine/default.py", line 598, in connect
    return self.dbapi.connect(*cargs, **cparams)
  File "/home/airflow/.local/lib/python3.8/site-packages/psycopg2/__init__.py", line 122, in connect
    conn = _connect(dsn, connection_factory=connection_factory, **kwasync)
psycopg2.OperationalError: connection to server at "postgres" (172.20.0.3), port 5432 failed: server closed the connection unexpectedly
	This probably means the server terminated abnormally
	before or while processing the request.


The above exception was the direct cause of the following exception:

Traceback (most recent call last):
  File "/home/airflow/.local/lib/python3.8/site-packages/airflow/jobs/job.py", line 187, in heartbeat
    self._merge_from(Job._fetch_from_db(self, session))
  File "/home/airflow/.local/lib/python3.8/site-packages/airflow/api_internal/internal_api_call.py", line 114, in wrapper
    return func(*args, **kwargs)
  File "/home/airflow/.local/lib/python3.8/site-packages/airflow/utils/session.py", line 76, in wrapper
    return func(*args, **kwargs)
  File "/home/airflow/.local/lib/python3.8/site-packages/airflow/jobs/job.py", line 308, in _fetch_from_db
    session.merge(job)
  File "/home/airflow/.local/lib/python3.8/site-packages/sqlalchemy/orm/session.py", line 3056, in merge
    return self._merge(
  File "/home/airflow/.local/lib/python3.8/site-packages/sqlalchemy/orm/session.py", line 3136, in _merge
    merged = self.get(
  File "/home/airflow/.local/lib/python3.8/site-packages/sqlalchemy/orm/session.py", line 2853, in get
    return self._get_impl(
  File "/home/airflow/.local/lib/python3.8/site-packages/sqlalchemy/orm/session.py", line 2975, in _get_impl
    return db_load_fn(
  File "/home/airflow/.local/lib/python3.8/site-packages/sqlalchemy/orm/loading.py", line 530, in load_on_pk_identity
    session.execute(
  File "/home/airflow/.local/lib/python3.8/site-packages/sqlalchemy/orm/session.py", line 1716, in execute
    conn = self._connection_for_bind(bind)
  File "/home/airflow/.local/lib/python3.8/site-packages/sqlalchemy/orm/session.py", line 1555, in _connection_for_bind
    return self._transaction._connection_for_bind(
  File "/home/airflow/.local/lib/python3.8/site-packages/sqlalchemy/orm/session.py", line 750, in _connection_for_bind
    conn = bind.connect()
  File "/home/airflow/.local/lib/python3.8/site-packages/sqlalchemy/future/engine.py", line 412, in connect
    return super(Engine, self).connect()
  File "/home/airflow/.local/lib/python3.8/site-packages/sqlalchemy/engine/base.py", line 3325, in connect
    return self._connection_cls(self, close_with_result=close_with_result)
  File "/home/airflow/.local/lib/python3.8/site-packages/sqlalchemy/engine/base.py", line 96, in __init__
    else engine.raw_connection()
  File "/home/airflow/.local/lib/python3.8/site-packages/sqlalchemy/engine/base.py", line 3404, in raw_connection
    return self._wrap_pool_connect(self.pool.connect, _connection)
  File "/home/airflow/.local/lib/python3.8/site-packages/sqlalchemy/engine/base.py", line 3374, in _wrap_pool_connect
    Connection._handle_dbapi_exception_noconnection(
  File "/home/airflow/.local/lib/python3.8/site-packages/sqlalchemy/engine/base.py", line 2208, in _handle_dbapi_exception_noconnection
    util.raise_(
  File "/home/airflow/.local/lib/python3.8/site-packages/sqlalchemy/util/compat.py", line 211, in raise_
    raise exception
  File "/home/airflow/.local/lib/python3.8/site-packages/sqlalchemy/engine/base.py", line 3371, in _wrap_pool_connect
    return fn()
  File "/home/airflow/.local/lib/python3.8/site-packages/sqlalchemy/pool/base.py", line 327, in connect
    return _ConnectionFairy._checkout(self)
  File "/home/airflow/.local/lib/python3.8/site-packages/sqlalchemy/pool/base.py", line 894, in _checkout
    fairy = _ConnectionRecord.checkout(pool)
  File "/home/airflow/.local/lib/python3.8/site-packages/sqlalchemy/pool/base.py", line 493, in checkout
    rec = pool._do_get()
  File "/home/airflow/.local/lib/python3.8/site-packages/sqlalchemy/pool/impl.py", line 256, in _do_get
    return self._create_connection()
  File "/home/airflow/.local/lib/python3.8/site-packages/sqlalchemy/pool/base.py", line 273, in _create_connection
    return _ConnectionRecord(self)
  File "/home/airflow/.local/lib/python3.8/site-packages/sqlalchemy/pool/base.py", line 388, in __init__
    self.__connect()
  File "/home/airflow/.local/lib/python3.8/site-packages/sqlalchemy/pool/base.py", line 691, in __connect
    pool.logger.debug("Error on connect(): %s", e)
  File "/home/airflow/.local/lib/python3.8/site-packages/sqlalchemy/util/langhelpers.py", line 70, in __exit__
    compat.raise_(
  File "/home/airflow/.local/lib/python3.8/site-packages/sqlalchemy/util/compat.py", line 211, in raise_
    raise exception
  File "/home/airflow/.local/lib/python3.8/site-packages/sqlalchemy/pool/base.py", line 686, in __connect
    self.dbapi_connection = connection = pool._invoke_creator(self)
  File "/home/airflow/.local/lib/python3.8/site-packages/sqlalchemy/engine/create.py", line 574, in connect
    return dialect.connect(*cargs, **cparams)
  File "/home/airflow/.local/lib/python3.8/site-packages/sqlalchemy/engine/default.py", line 598, in connect
    return self.dbapi.connect(*cargs, **cparams)
  File "/home/airflow/.local/lib/python3.8/site-packages/psycopg2/__init__.py", line 122, in connect
    conn = _connect(dsn, connection_factory=connection_factory, **kwasync)
sqlalchemy.exc.OperationalError: (psycopg2.OperationalError) connection to server at "postgres" (172.20.0.3), port 5432 failed: server closed the connection unexpectedly
	This probably means the server terminated abnormally
	before or while processing the request.

(Background on this error at: https://sqlalche.me/e/14/e3q8)
[2024-04-25T20:04:53.681+0000] {job.py:221} ERROR - Job heartbeat failed with error. Scheduler is in unhealthy state
[2024-04-25T20:07:58.188+0000] {job.py:221} ERROR - Job heartbeat failed with error. Scheduler is in unhealthy state
[2024-04-25T20:09:45.213+0000] {job.py:221} ERROR - Job heartbeat failed with error. Scheduler is in unhealthy state
[2024-04-25T20:10:28.740+0000] {local_task_job_runner.py:211} ERROR - Heartbeat time limit exceeded!
[2024-04-25T20:10:28.997+0000] {process_utils.py:131} INFO - Sending 15 to group 9252. PIDs of all processes in the group: [9306, 9252]
[2024-04-25T20:10:29.027+0000] {process_utils.py:86} INFO - Sending the signal 15 to group 9252
[2024-04-25T20:10:29.312+0000] {taskinstance.py:2450} ERROR - Received SIGTERM. Terminating subprocesses.
[2024-04-25T20:10:30.105+0000] {process_utils.py:79} INFO - Process psutil.Process(pid=9306, status='terminated', started='20:00:42') (9306) terminated with exit code None
[2024-04-25T20:10:34.132+0000] {taskinstance.py:2698} ERROR - Task failed with exception
Traceback (most recent call last):
  File "/home/airflow/.local/lib/python3.8/site-packages/airflow/models/taskinstance.py", line 433, in _execute_task
    result = execute_callable(context=context, **execute_callable_kwargs)
  File "/home/airflow/.local/lib/python3.8/site-packages/airflow/decorators/base.py", line 241, in execute
    return_value = super().execute(context)
  File "/home/airflow/.local/lib/python3.8/site-packages/airflow/operators/python.py", line 400, in execute
    return super().execute(context=serializable_context)
  File "/home/airflow/.local/lib/python3.8/site-packages/airflow/operators/python.py", line 199, in execute
    return_value = self.execute_callable()
  File "/home/airflow/.local/lib/python3.8/site-packages/airflow/operators/python.py", line 716, in execute_callable
    result = self._execute_python_callable_in_subprocess(python_path)
  File "/home/airflow/.local/lib/python3.8/site-packages/airflow/operators/python.py", line 454, in _execute_python_callable_in_subprocess
    execute_in_subprocess(
  File "/home/airflow/.local/lib/python3.8/site-packages/airflow/utils/process_utils.py", line 171, in execute_in_subprocess
    execute_in_subprocess_with_kwargs(cmd, cwd=cwd)
  File "/home/airflow/.local/lib/python3.8/site-packages/airflow/utils/process_utils.py", line 189, in execute_in_subprocess_with_kwargs
    for line in iter(proc.stdout.readline, b""):
  File "/home/airflow/.local/lib/python3.8/site-packages/airflow/models/taskinstance.py", line 2452, in signal_handler
    raise AirflowException("Task received SIGTERM signal")
airflow.exceptions.AirflowException: Task received SIGTERM signal
[2024-04-25T20:10:34.264+0000] {taskinstance.py:1138} INFO - Marking task as UP_FOR_RETRY. dag_id=process_etl_mnist_784_data, task_id=train_model, execution_date=20240424T000000, start_date=20240425T200038, end_date=20240425T201034
[2024-04-25T20:10:38.805+0000] {standard_task_runner.py:107} ERROR - Failed to execute job 4 for task train_model (Task received SIGTERM signal; 9252)
[2024-04-25T20:10:38.832+0000] {process_utils.py:79} INFO - Process psutil.Process(pid=9252, status='terminated', exitcode=1, started='20:00:38') (9252) terminated with exit code 1
[2024-04-25T20:33:33.399+0000] {taskinstance.py:1956} INFO - Dependencies all met for dep_context=non-requeueable deps ti=<TaskInstance: process_etl_mnist_784_data.train_model scheduled__2024-04-24T00:00:00+00:00 [queued]>
[2024-04-25T20:33:33.404+0000] {taskinstance.py:1956} INFO - Dependencies all met for dep_context=requeueable deps ti=<TaskInstance: process_etl_mnist_784_data.train_model scheduled__2024-04-24T00:00:00+00:00 [queued]>
[2024-04-25T20:33:33.404+0000] {taskinstance.py:2170} INFO - Starting attempt 1 of 2
[2024-04-25T20:33:33.412+0000] {taskinstance.py:2191} INFO - Executing <Task(_PythonVirtualenvDecoratedOperator): train_model> on 2024-04-24 00:00:00+00:00
[2024-04-25T20:33:33.416+0000] {standard_task_runner.py:60} INFO - Started process 4941 to run task
[2024-04-25T20:33:33.418+0000] {standard_task_runner.py:87} INFO - Running: ['***', 'tasks', 'run', 'process_etl_mnist_784_data', 'train_model', 'scheduled__2024-04-24T00:00:00+00:00', '--job-id', '4', '--raw', '--subdir', 'DAGS_FOLDER/etl_process.py', '--cfg-path', '/tmp/tmp722v94wu']
[2024-04-25T20:33:33.420+0000] {standard_task_runner.py:88} INFO - Job 4: Subtask train_model
[2024-04-25T20:33:33.449+0000] {task_command.py:423} INFO - Running <TaskInstance: process_etl_mnist_784_data.train_model scheduled__2024-04-24T00:00:00+00:00 [running]> on host b1d103f3af44
[2024-04-25T20:33:33.549+0000] {taskinstance.py:2480} INFO - Exporting env vars: AIRFLOW_CTX_DAG_OWNER='Carlos Rodriguez' AIRFLOW_CTX_DAG_ID='process_etl_mnist_784_data' AIRFLOW_CTX_TASK_ID='train_model' AIRFLOW_CTX_EXECUTION_DATE='2024-04-24T00:00:00+00:00' AIRFLOW_CTX_TRY_NUMBER='1' AIRFLOW_CTX_DAG_RUN_ID='scheduled__2024-04-24T00:00:00+00:00'
[2024-04-25T20:33:33.550+0000] {process_utils.py:182} INFO - Executing cmd: /usr/local/bin/python -m virtualenv /tmp/venvnofutvmb --system-site-packages --python=python
[2024-04-25T20:33:33.556+0000] {process_utils.py:186} INFO - Output:
[2024-04-25T20:33:33.948+0000] {process_utils.py:190} INFO - created virtual environment CPython3.8.18.final.0-64 in 126ms
[2024-04-25T20:33:33.948+0000] {process_utils.py:190} INFO -   creator CPython3Posix(dest=/tmp/venvnofutvmb, clear=False, no_vcs_ignore=False, global=True)
[2024-04-25T20:33:33.948+0000] {process_utils.py:190} INFO -   seeder FromAppData(download=False, pip=bundle, setuptools=bundle, wheel=bundle, via=copy, app_data_dir=/home/***/.local/share/virtualenv)
[2024-04-25T20:33:33.949+0000] {process_utils.py:190} INFO -     added seed packages: pip==23.3.1, setuptools==69.0.2, wheel==0.42.0
[2024-04-25T20:33:33.949+0000] {process_utils.py:190} INFO -   activators BashActivator,CShellActivator,FishActivator,NushellActivator,PowerShellActivator,PythonActivator
[2024-04-25T20:33:33.969+0000] {process_utils.py:182} INFO - Executing cmd: /tmp/venvnofutvmb/bin/pip install -r /tmp/venvnofutvmb/requirements.txt
[2024-04-25T20:33:33.974+0000] {process_utils.py:186} INFO - Output:
[2024-04-25T20:33:34.783+0000] {process_utils.py:190} INFO - Collecting awswrangler==3.6.0 (from -r /tmp/venvnofutvmb/requirements.txt (line 1))
[2024-04-25T20:33:34.784+0000] {process_utils.py:190} INFO -   Using cached awswrangler-3.6.0-py3-none-any.whl.metadata (23 kB)
[2024-04-25T20:33:34.814+0000] {process_utils.py:190} INFO - Requirement already satisfied: boto3<2.0.0,>=1.20.32 in /home/***/.local/lib/python3.8/site-packages (from awswrangler==3.6.0->-r /tmp/venvnofutvmb/requirements.txt (line 1)) (1.34.88)
[2024-04-25T20:33:34.815+0000] {process_utils.py:190} INFO - Requirement already satisfied: botocore<2.0.0,>=1.23.32 in /home/***/.local/lib/python3.8/site-packages (from awswrangler==3.6.0->-r /tmp/venvnofutvmb/requirements.txt (line 1)) (1.34.88)
[2024-04-25T20:33:34.816+0000] {process_utils.py:190} INFO - Requirement already satisfied: numpy<2.0,>=1.18 in /home/***/.local/lib/python3.8/site-packages (from awswrangler==3.6.0->-r /tmp/venvnofutvmb/requirements.txt (line 1)) (1.24.4)
[2024-04-25T20:33:34.816+0000] {process_utils.py:190} INFO - Requirement already satisfied: packaging<24.0,>=21.1 in /home/***/.local/lib/python3.8/site-packages (from awswrangler==3.6.0->-r /tmp/venvnofutvmb/requirements.txt (line 1)) (23.2)
[2024-04-25T20:33:34.817+0000] {process_utils.py:190} INFO - Requirement already satisfied: pandas<2.1.0,>=1.2.0 in /home/***/.local/lib/python3.8/site-packages (from awswrangler==3.6.0->-r /tmp/venvnofutvmb/requirements.txt (line 1)) (2.0.3)
[2024-04-25T20:33:34.818+0000] {process_utils.py:190} INFO - Requirement already satisfied: pyarrow>=7.0.0 in /home/***/.local/lib/python3.8/site-packages (from awswrangler==3.6.0->-r /tmp/venvnofutvmb/requirements.txt (line 1)) (14.0.2)
[2024-04-25T20:33:34.818+0000] {process_utils.py:190} INFO - Requirement already satisfied: typing-extensions<5.0.0,>=4.4.0 in /home/***/.local/lib/python3.8/site-packages (from awswrangler==3.6.0->-r /tmp/venvnofutvmb/requirements.txt (line 1)) (4.9.0)
[2024-04-25T20:33:34.822+0000] {process_utils.py:190} INFO - Requirement already satisfied: jmespath<2.0.0,>=0.7.1 in /home/***/.local/lib/python3.8/site-packages (from boto3<2.0.0,>=1.20.32->awswrangler==3.6.0->-r /tmp/venvnofutvmb/requirements.txt (line 1)) (0.10.0)
[2024-04-25T20:33:34.822+0000] {process_utils.py:190} INFO - Requirement already satisfied: s3transfer<0.11.0,>=0.10.0 in /home/***/.local/lib/python3.8/site-packages (from boto3<2.0.0,>=1.20.32->awswrangler==3.6.0->-r /tmp/venvnofutvmb/requirements.txt (line 1)) (0.10.1)
[2024-04-25T20:33:34.827+0000] {process_utils.py:190} INFO - Requirement already satisfied: python-dateutil<3.0.0,>=2.1 in /home/***/.local/lib/python3.8/site-packages (from botocore<2.0.0,>=1.23.32->awswrangler==3.6.0->-r /tmp/venvnofutvmb/requirements.txt (line 1)) (2.8.2)
[2024-04-25T20:33:34.828+0000] {process_utils.py:190} INFO - Requirement already satisfied: urllib3<1.27,>=1.25.4 in /home/***/.local/lib/python3.8/site-packages (from botocore<2.0.0,>=1.23.32->awswrangler==3.6.0->-r /tmp/venvnofutvmb/requirements.txt (line 1)) (1.26.18)
[2024-04-25T20:33:34.888+0000] {process_utils.py:190} INFO - Requirement already satisfied: pytz>=2020.1 in /home/***/.local/lib/python3.8/site-packages (from pandas<2.1.0,>=1.2.0->awswrangler==3.6.0->-r /tmp/venvnofutvmb/requirements.txt (line 1)) (2023.3.post1)
[2024-04-25T20:33:34.889+0000] {process_utils.py:190} INFO - Requirement already satisfied: tzdata>=2022.1 in /home/***/.local/lib/python3.8/site-packages (from pandas<2.1.0,>=1.2.0->awswrangler==3.6.0->-r /tmp/venvnofutvmb/requirements.txt (line 1)) (2023.4)
[2024-04-25T20:33:34.895+0000] {process_utils.py:190} INFO - Requirement already satisfied: six>=1.5 in /home/***/.local/lib/python3.8/site-packages (from python-dateutil<3.0.0,>=2.1->botocore<2.0.0,>=1.23.32->awswrangler==3.6.0->-r /tmp/venvnofutvmb/requirements.txt (line 1)) (1.16.0)
[2024-04-25T20:33:34.915+0000] {process_utils.py:190} INFO - Using cached awswrangler-3.6.0-py3-none-any.whl (403 kB)
[2024-04-25T20:33:37.036+0000] {process_utils.py:190} INFO - Installing collected packages: awswrangler
[2024-04-25T20:33:37.216+0000] {process_utils.py:190} INFO - Successfully installed awswrangler-3.6.0
[2024-04-25T20:33:37.344+0000] {process_utils.py:190} INFO - 
[2024-04-25T20:33:37.345+0000] {process_utils.py:190} INFO - [notice] A new release of pip is available: 23.3.1 -> 24.0
[2024-04-25T20:33:37.345+0000] {process_utils.py:190} INFO - [notice] To update, run: python -m pip install --upgrade pip
[2024-04-25T20:33:37.507+0000] {process_utils.py:182} INFO - Executing cmd: /tmp/venvnofutvmb/bin/python /tmp/venv-call5f7xch9q/script.py /tmp/venv-call5f7xch9q/script.in /tmp/venv-call5f7xch9q/script.out /tmp/venv-call5f7xch9q/string_args.txt /tmp/venv-call5f7xch9q/termination.log
[2024-04-25T20:33:37.515+0000] {process_utils.py:186} INFO - Output:
[2024-04-25T20:33:39.762+0000] {process_utils.py:190} INFO - [[34m2024-04-25T20:33:39.762+0000[0m] {[34mcredentials.py:[0m1147} INFO[0m - Found credentials in environment variables.[0m
[2024-04-25T20:33:39.799+0000] {process_utils.py:190} INFO - [[34m2024-04-25T20:33:39.799+0000[0m] {[34mconfigprovider.py:[0m957} INFO[0m - Found endpoint for s3 via: environment_service.[0m
[2024-04-25T20:40:04.653+0000] {job.py:213} ERROR - Job heartbeat got an exception
Traceback (most recent call last):
  File "/home/airflow/.local/lib/python3.8/site-packages/sqlalchemy/engine/base.py", line 3371, in _wrap_pool_connect
    return fn()
  File "/home/airflow/.local/lib/python3.8/site-packages/sqlalchemy/pool/base.py", line 327, in connect
    return _ConnectionFairy._checkout(self)
  File "/home/airflow/.local/lib/python3.8/site-packages/sqlalchemy/pool/base.py", line 894, in _checkout
    fairy = _ConnectionRecord.checkout(pool)
  File "/home/airflow/.local/lib/python3.8/site-packages/sqlalchemy/pool/base.py", line 493, in checkout
    rec = pool._do_get()
  File "/home/airflow/.local/lib/python3.8/site-packages/sqlalchemy/pool/impl.py", line 256, in _do_get
    return self._create_connection()
  File "/home/airflow/.local/lib/python3.8/site-packages/sqlalchemy/pool/base.py", line 273, in _create_connection
    return _ConnectionRecord(self)
  File "/home/airflow/.local/lib/python3.8/site-packages/sqlalchemy/pool/base.py", line 388, in __init__
    self.__connect()
  File "/home/airflow/.local/lib/python3.8/site-packages/sqlalchemy/pool/base.py", line 691, in __connect
    pool.logger.debug("Error on connect(): %s", e)
  File "/home/airflow/.local/lib/python3.8/site-packages/sqlalchemy/util/langhelpers.py", line 70, in __exit__
    compat.raise_(
  File "/home/airflow/.local/lib/python3.8/site-packages/sqlalchemy/util/compat.py", line 211, in raise_
    raise exception
  File "/home/airflow/.local/lib/python3.8/site-packages/sqlalchemy/pool/base.py", line 686, in __connect
    self.dbapi_connection = connection = pool._invoke_creator(self)
  File "/home/airflow/.local/lib/python3.8/site-packages/sqlalchemy/engine/create.py", line 574, in connect
    return dialect.connect(*cargs, **cparams)
  File "/home/airflow/.local/lib/python3.8/site-packages/sqlalchemy/engine/default.py", line 598, in connect
    return self.dbapi.connect(*cargs, **cparams)
  File "/home/airflow/.local/lib/python3.8/site-packages/psycopg2/__init__.py", line 122, in connect
    conn = _connect(dsn, connection_factory=connection_factory, **kwasync)
psycopg2.OperationalError: could not translate host name "postgres" to address: Temporary failure in name resolution


The above exception was the direct cause of the following exception:

Traceback (most recent call last):
  File "/home/airflow/.local/lib/python3.8/site-packages/airflow/jobs/job.py", line 187, in heartbeat
    self._merge_from(Job._fetch_from_db(self, session))
  File "/home/airflow/.local/lib/python3.8/site-packages/airflow/api_internal/internal_api_call.py", line 114, in wrapper
    return func(*args, **kwargs)
  File "/home/airflow/.local/lib/python3.8/site-packages/airflow/utils/session.py", line 76, in wrapper
    return func(*args, **kwargs)
  File "/home/airflow/.local/lib/python3.8/site-packages/airflow/jobs/job.py", line 308, in _fetch_from_db
    session.merge(job)
  File "/home/airflow/.local/lib/python3.8/site-packages/sqlalchemy/orm/session.py", line 3056, in merge
    return self._merge(
  File "/home/airflow/.local/lib/python3.8/site-packages/sqlalchemy/orm/session.py", line 3136, in _merge
    merged = self.get(
  File "/home/airflow/.local/lib/python3.8/site-packages/sqlalchemy/orm/session.py", line 2853, in get
    return self._get_impl(
  File "/home/airflow/.local/lib/python3.8/site-packages/sqlalchemy/orm/session.py", line 2975, in _get_impl
    return db_load_fn(
  File "/home/airflow/.local/lib/python3.8/site-packages/sqlalchemy/orm/loading.py", line 530, in load_on_pk_identity
    session.execute(
  File "/home/airflow/.local/lib/python3.8/site-packages/sqlalchemy/orm/session.py", line 1716, in execute
    conn = self._connection_for_bind(bind)
  File "/home/airflow/.local/lib/python3.8/site-packages/sqlalchemy/orm/session.py", line 1555, in _connection_for_bind
    return self._transaction._connection_for_bind(
  File "/home/airflow/.local/lib/python3.8/site-packages/sqlalchemy/orm/session.py", line 750, in _connection_for_bind
    conn = bind.connect()
  File "/home/airflow/.local/lib/python3.8/site-packages/sqlalchemy/future/engine.py", line 412, in connect
    return super(Engine, self).connect()
  File "/home/airflow/.local/lib/python3.8/site-packages/sqlalchemy/engine/base.py", line 3325, in connect
    return self._connection_cls(self, close_with_result=close_with_result)
  File "/home/airflow/.local/lib/python3.8/site-packages/sqlalchemy/engine/base.py", line 96, in __init__
    else engine.raw_connection()
  File "/home/airflow/.local/lib/python3.8/site-packages/sqlalchemy/engine/base.py", line 3404, in raw_connection
    return self._wrap_pool_connect(self.pool.connect, _connection)
  File "/home/airflow/.local/lib/python3.8/site-packages/sqlalchemy/engine/base.py", line 3374, in _wrap_pool_connect
    Connection._handle_dbapi_exception_noconnection(
  File "/home/airflow/.local/lib/python3.8/site-packages/sqlalchemy/engine/base.py", line 2208, in _handle_dbapi_exception_noconnection
    util.raise_(
  File "/home/airflow/.local/lib/python3.8/site-packages/sqlalchemy/util/compat.py", line 211, in raise_
    raise exception
  File "/home/airflow/.local/lib/python3.8/site-packages/sqlalchemy/engine/base.py", line 3371, in _wrap_pool_connect
    return fn()
  File "/home/airflow/.local/lib/python3.8/site-packages/sqlalchemy/pool/base.py", line 327, in connect
    return _ConnectionFairy._checkout(self)
  File "/home/airflow/.local/lib/python3.8/site-packages/sqlalchemy/pool/base.py", line 894, in _checkout
    fairy = _ConnectionRecord.checkout(pool)
  File "/home/airflow/.local/lib/python3.8/site-packages/sqlalchemy/pool/base.py", line 493, in checkout
    rec = pool._do_get()
  File "/home/airflow/.local/lib/python3.8/site-packages/sqlalchemy/pool/impl.py", line 256, in _do_get
    return self._create_connection()
  File "/home/airflow/.local/lib/python3.8/site-packages/sqlalchemy/pool/base.py", line 273, in _create_connection
    return _ConnectionRecord(self)
  File "/home/airflow/.local/lib/python3.8/site-packages/sqlalchemy/pool/base.py", line 388, in __init__
    self.__connect()
  File "/home/airflow/.local/lib/python3.8/site-packages/sqlalchemy/pool/base.py", line 691, in __connect
    pool.logger.debug("Error on connect(): %s", e)
  File "/home/airflow/.local/lib/python3.8/site-packages/sqlalchemy/util/langhelpers.py", line 70, in __exit__
    compat.raise_(
  File "/home/airflow/.local/lib/python3.8/site-packages/sqlalchemy/util/compat.py", line 211, in raise_
    raise exception
  File "/home/airflow/.local/lib/python3.8/site-packages/sqlalchemy/pool/base.py", line 686, in __connect
    self.dbapi_connection = connection = pool._invoke_creator(self)
  File "/home/airflow/.local/lib/python3.8/site-packages/sqlalchemy/engine/create.py", line 574, in connect
    return dialect.connect(*cargs, **cparams)
  File "/home/airflow/.local/lib/python3.8/site-packages/sqlalchemy/engine/default.py", line 598, in connect
    return self.dbapi.connect(*cargs, **cparams)
  File "/home/airflow/.local/lib/python3.8/site-packages/psycopg2/__init__.py", line 122, in connect
    conn = _connect(dsn, connection_factory=connection_factory, **kwasync)
sqlalchemy.exc.OperationalError: (psycopg2.OperationalError) could not translate host name "postgres" to address: Temporary failure in name resolution

(Background on this error at: https://sqlalche.me/e/14/e3q8)
[2024-04-25T20:40:45.806+0000] {job.py:221} ERROR - Job heartbeat failed with error. Scheduler is in unhealthy state
[2024-04-25T20:41:28.569+0000] {job.py:221} ERROR - Job heartbeat failed with error. Scheduler is in unhealthy state
[2024-04-25T20:42:43.165+0000] {job.py:221} ERROR - Job heartbeat failed with error. Scheduler is in unhealthy state
[2024-04-25T20:44:06.662+0000] {job.py:221} ERROR - Job heartbeat failed with error. Scheduler is in unhealthy state
[2024-04-25T20:44:26.131+0000] {local_task_job_runner.py:211} ERROR - Heartbeat time limit exceeded!
[2024-04-25T20:44:29.863+0000] {process_utils.py:131} INFO - Sending 15 to group 4941. PIDs of all processes in the group: [4994, 4941]
[2024-04-25T20:44:30.155+0000] {process_utils.py:86} INFO - Sending the signal 15 to group 4941
[2024-04-25T20:44:52.901+0000] {taskinstance.py:2450} ERROR - Received SIGTERM. Terminating subprocesses.
[2024-04-25T20:44:53.695+0000] {process_utils.py:79} INFO - Process psutil.Process(pid=4994, status='terminated', started='20:33:37') (4994) terminated with exit code None
[2024-04-25T20:44:58.161+0000] {taskinstance.py:2698} ERROR - Task failed with exception
Traceback (most recent call last):
  File "/home/airflow/.local/lib/python3.8/site-packages/airflow/models/taskinstance.py", line 433, in _execute_task
    result = execute_callable(context=context, **execute_callable_kwargs)
  File "/home/airflow/.local/lib/python3.8/site-packages/airflow/decorators/base.py", line 241, in execute
    return_value = super().execute(context)
  File "/home/airflow/.local/lib/python3.8/site-packages/airflow/operators/python.py", line 400, in execute
    return super().execute(context=serializable_context)
  File "/home/airflow/.local/lib/python3.8/site-packages/airflow/operators/python.py", line 199, in execute
    return_value = self.execute_callable()
  File "/home/airflow/.local/lib/python3.8/site-packages/airflow/operators/python.py", line 716, in execute_callable
    result = self._execute_python_callable_in_subprocess(python_path)
  File "/home/airflow/.local/lib/python3.8/site-packages/airflow/operators/python.py", line 454, in _execute_python_callable_in_subprocess
    execute_in_subprocess(
  File "/home/airflow/.local/lib/python3.8/site-packages/airflow/utils/process_utils.py", line 171, in execute_in_subprocess
    execute_in_subprocess_with_kwargs(cmd, cwd=cwd)
  File "/home/airflow/.local/lib/python3.8/site-packages/airflow/utils/process_utils.py", line 189, in execute_in_subprocess_with_kwargs
    for line in iter(proc.stdout.readline, b""):
  File "/home/airflow/.local/lib/python3.8/site-packages/airflow/models/taskinstance.py", line 2452, in signal_handler
    raise AirflowException("Task received SIGTERM signal")
airflow.exceptions.AirflowException: Task received SIGTERM signal
[2024-04-25T20:44:58.385+0000] {taskinstance.py:1138} INFO - Marking task as UP_FOR_RETRY. dag_id=process_etl_mnist_784_data, task_id=train_model, execution_date=20240424T000000, start_date=20240425T203333, end_date=20240425T204458
[2024-04-25T20:44:59.617+0000] {standard_task_runner.py:107} ERROR - Failed to execute job 4 for task train_model (Task received SIGTERM signal; 4941)
[2024-04-25T20:44:59.814+0000] {process_utils.py:79} INFO - Process psutil.Process(pid=4941, status='terminated', exitcode=1, started='20:33:33') (4941) terminated with exit code 1
