[2024-04-25T04:05:38.398+0000] {taskinstance.py:1956} INFO - Dependencies all met for dep_context=non-requeueable deps ti=<TaskInstance: process_etl_mnist_784_data.train_model scheduled__2024-04-24T00:00:00+00:00 [queued]>
[2024-04-25T04:05:38.402+0000] {taskinstance.py:1956} INFO - Dependencies all met for dep_context=requeueable deps ti=<TaskInstance: process_etl_mnist_784_data.train_model scheduled__2024-04-24T00:00:00+00:00 [queued]>
[2024-04-25T04:05:38.403+0000] {taskinstance.py:2170} INFO - Starting attempt 2 of 2
[2024-04-25T04:05:38.410+0000] {taskinstance.py:2191} INFO - Executing <Task(_PythonVirtualenvDecoratedOperator): train_model> on 2024-04-24 00:00:00+00:00
[2024-04-25T04:05:38.413+0000] {standard_task_runner.py:60} INFO - Started process 11709 to run task
[2024-04-25T04:05:38.416+0000] {standard_task_runner.py:87} INFO - Running: ['***', 'tasks', 'run', 'process_etl_mnist_784_data', 'train_model', 'scheduled__2024-04-24T00:00:00+00:00', '--job-id', '9', '--raw', '--subdir', 'DAGS_FOLDER/etl_process.py', '--cfg-path', '/tmp/tmpfd38wu_s']
[2024-04-25T04:05:38.417+0000] {standard_task_runner.py:88} INFO - Job 9: Subtask train_model
[2024-04-25T04:05:38.446+0000] {task_command.py:423} INFO - Running <TaskInstance: process_etl_mnist_784_data.train_model scheduled__2024-04-24T00:00:00+00:00 [running]> on host b7ac1838226b
[2024-04-25T04:05:38.486+0000] {taskinstance.py:2480} INFO - Exporting env vars: AIRFLOW_CTX_DAG_OWNER='Carlos Rodriguez' AIRFLOW_CTX_DAG_ID='process_etl_mnist_784_data' AIRFLOW_CTX_TASK_ID='train_model' AIRFLOW_CTX_EXECUTION_DATE='2024-04-24T00:00:00+00:00' AIRFLOW_CTX_TRY_NUMBER='2' AIRFLOW_CTX_DAG_RUN_ID='scheduled__2024-04-24T00:00:00+00:00'
[2024-04-25T04:05:38.488+0000] {process_utils.py:182} INFO - Executing cmd: /usr/local/bin/python -m virtualenv /tmp/venvvxcucxie --system-site-packages --python=python
[2024-04-25T04:05:38.494+0000] {process_utils.py:186} INFO - Output:
[2024-04-25T04:05:38.914+0000] {process_utils.py:190} INFO - created virtual environment CPython3.8.18.final.0-64 in 160ms
[2024-04-25T04:05:38.914+0000] {process_utils.py:190} INFO -   creator CPython3Posix(dest=/tmp/venvvxcucxie, clear=False, no_vcs_ignore=False, global=True)
[2024-04-25T04:05:38.915+0000] {process_utils.py:190} INFO -   seeder FromAppData(download=False, pip=bundle, setuptools=bundle, wheel=bundle, via=copy, app_data_dir=/home/***/.local/share/virtualenv)
[2024-04-25T04:05:38.915+0000] {process_utils.py:190} INFO -     added seed packages: pip==23.3.1, setuptools==69.0.2, wheel==0.42.0
[2024-04-25T04:05:38.915+0000] {process_utils.py:190} INFO -   activators BashActivator,CShellActivator,FishActivator,NushellActivator,PowerShellActivator,PythonActivator
[2024-04-25T04:05:38.935+0000] {process_utils.py:182} INFO - Executing cmd: /tmp/venvvxcucxie/bin/pip install -r /tmp/venvvxcucxie/requirements.txt
[2024-04-25T04:05:38.940+0000] {process_utils.py:186} INFO - Output:
[2024-04-25T04:05:39.787+0000] {process_utils.py:190} INFO - Collecting awswrangler==3.6.0 (from -r /tmp/venvvxcucxie/requirements.txt (line 1))
[2024-04-25T04:05:39.789+0000] {process_utils.py:190} INFO -   Using cached awswrangler-3.6.0-py3-none-any.whl.metadata (23 kB)
[2024-04-25T04:05:39.819+0000] {process_utils.py:190} INFO - Requirement already satisfied: boto3<2.0.0,>=1.20.32 in /home/***/.local/lib/python3.8/site-packages (from awswrangler==3.6.0->-r /tmp/venvvxcucxie/requirements.txt (line 1)) (1.34.88)
[2024-04-25T04:05:39.819+0000] {process_utils.py:190} INFO - Requirement already satisfied: botocore<2.0.0,>=1.23.32 in /home/***/.local/lib/python3.8/site-packages (from awswrangler==3.6.0->-r /tmp/venvvxcucxie/requirements.txt (line 1)) (1.34.88)
[2024-04-25T04:05:39.820+0000] {process_utils.py:190} INFO - Requirement already satisfied: numpy<2.0,>=1.18 in /home/***/.local/lib/python3.8/site-packages (from awswrangler==3.6.0->-r /tmp/venvvxcucxie/requirements.txt (line 1)) (1.24.4)
[2024-04-25T04:05:39.821+0000] {process_utils.py:190} INFO - Requirement already satisfied: packaging<24.0,>=21.1 in /home/***/.local/lib/python3.8/site-packages (from awswrangler==3.6.0->-r /tmp/venvvxcucxie/requirements.txt (line 1)) (23.2)
[2024-04-25T04:05:39.821+0000] {process_utils.py:190} INFO - Requirement already satisfied: pandas<2.1.0,>=1.2.0 in /home/***/.local/lib/python3.8/site-packages (from awswrangler==3.6.0->-r /tmp/venvvxcucxie/requirements.txt (line 1)) (2.0.3)
[2024-04-25T04:05:39.822+0000] {process_utils.py:190} INFO - Requirement already satisfied: pyarrow>=7.0.0 in /home/***/.local/lib/python3.8/site-packages (from awswrangler==3.6.0->-r /tmp/venvvxcucxie/requirements.txt (line 1)) (14.0.2)
[2024-04-25T04:05:39.822+0000] {process_utils.py:190} INFO - Requirement already satisfied: typing-extensions<5.0.0,>=4.4.0 in /home/***/.local/lib/python3.8/site-packages (from awswrangler==3.6.0->-r /tmp/venvvxcucxie/requirements.txt (line 1)) (4.9.0)
[2024-04-25T04:05:39.826+0000] {process_utils.py:190} INFO - Requirement already satisfied: jmespath<2.0.0,>=0.7.1 in /home/***/.local/lib/python3.8/site-packages (from boto3<2.0.0,>=1.20.32->awswrangler==3.6.0->-r /tmp/venvvxcucxie/requirements.txt (line 1)) (0.10.0)
[2024-04-25T04:05:39.826+0000] {process_utils.py:190} INFO - Requirement already satisfied: s3transfer<0.11.0,>=0.10.0 in /home/***/.local/lib/python3.8/site-packages (from boto3<2.0.0,>=1.20.32->awswrangler==3.6.0->-r /tmp/venvvxcucxie/requirements.txt (line 1)) (0.10.1)
[2024-04-25T04:05:39.831+0000] {process_utils.py:190} INFO - Requirement already satisfied: python-dateutil<3.0.0,>=2.1 in /home/***/.local/lib/python3.8/site-packages (from botocore<2.0.0,>=1.23.32->awswrangler==3.6.0->-r /tmp/venvvxcucxie/requirements.txt (line 1)) (2.8.2)
[2024-04-25T04:05:39.832+0000] {process_utils.py:190} INFO - Requirement already satisfied: urllib3<1.27,>=1.25.4 in /home/***/.local/lib/python3.8/site-packages (from botocore<2.0.0,>=1.23.32->awswrangler==3.6.0->-r /tmp/venvvxcucxie/requirements.txt (line 1)) (1.26.18)
[2024-04-25T04:05:39.888+0000] {process_utils.py:190} INFO - Requirement already satisfied: pytz>=2020.1 in /home/***/.local/lib/python3.8/site-packages (from pandas<2.1.0,>=1.2.0->awswrangler==3.6.0->-r /tmp/venvvxcucxie/requirements.txt (line 1)) (2023.3.post1)
[2024-04-25T04:05:39.889+0000] {process_utils.py:190} INFO - Requirement already satisfied: tzdata>=2022.1 in /home/***/.local/lib/python3.8/site-packages (from pandas<2.1.0,>=1.2.0->awswrangler==3.6.0->-r /tmp/venvvxcucxie/requirements.txt (line 1)) (2023.4)
[2024-04-25T04:05:39.894+0000] {process_utils.py:190} INFO - Requirement already satisfied: six>=1.5 in /home/***/.local/lib/python3.8/site-packages (from python-dateutil<3.0.0,>=2.1->botocore<2.0.0,>=1.23.32->awswrangler==3.6.0->-r /tmp/venvvxcucxie/requirements.txt (line 1)) (1.16.0)
[2024-04-25T04:05:39.916+0000] {process_utils.py:190} INFO - Using cached awswrangler-3.6.0-py3-none-any.whl (403 kB)
[2024-04-25T04:05:41.932+0000] {process_utils.py:190} INFO - Installing collected packages: awswrangler
[2024-04-25T04:05:42.115+0000] {process_utils.py:190} INFO - Successfully installed awswrangler-3.6.0
[2024-04-25T04:05:42.260+0000] {process_utils.py:190} INFO - 
[2024-04-25T04:05:42.260+0000] {process_utils.py:190} INFO - [notice] A new release of pip is available: 23.3.1 -> 24.0
[2024-04-25T04:05:42.260+0000] {process_utils.py:190} INFO - [notice] To update, run: python -m pip install --upgrade pip
[2024-04-25T04:05:42.392+0000] {process_utils.py:182} INFO - Executing cmd: /tmp/venvvxcucxie/bin/python /tmp/venv-callllhadqf5/script.py /tmp/venv-callllhadqf5/script.in /tmp/venv-callllhadqf5/script.out /tmp/venv-callllhadqf5/string_args.txt /tmp/venv-callllhadqf5/termination.log
[2024-04-25T04:05:42.398+0000] {process_utils.py:186} INFO - Output:
[2024-04-25T04:05:44.264+0000] {process_utils.py:190} INFO - [[34m2024-04-25T04:05:44.264+0000[0m] {[34mcredentials.py:[0m1147} INFO[0m - Found credentials in environment variables.[0m
[2024-04-25T04:05:44.304+0000] {process_utils.py:190} INFO - [[34m2024-04-25T04:05:44.304+0000[0m] {[34mconfigprovider.py:[0m957} INFO[0m - Found endpoint for s3 via: environment_service.[0m
[2024-04-25T04:05:48.140+0000] {process_utils.py:190} INFO - [[34m2024-04-25T04:05:48.140+0000[0m] {[34mcredentials.py:[0m1147} INFO[0m - Found credentials in environment variables.[0m
[2024-04-25T04:05:48.175+0000] {process_utils.py:190} INFO - [[34m2024-04-25T04:05:48.175+0000[0m] {[34mconfigprovider.py:[0m957} INFO[0m - Found endpoint for s3 via: environment_service.[0m
[2024-04-25T04:05:48.180+0000] {process_utils.py:190} INFO - Traceback (most recent call last):
[2024-04-25T04:05:48.180+0000] {process_utils.py:190} INFO -   File "/tmp/venv-callllhadqf5/script.py", line 127, in <module>
[2024-04-25T04:05:48.181+0000] {process_utils.py:190} INFO -     res = train_model(*arg_dict["args"], **arg_dict["kwargs"])
[2024-04-25T04:05:48.181+0000] {process_utils.py:190} INFO -   File "/tmp/venv-callllhadqf5/script.py", line 64, in train_model
[2024-04-25T04:05:48.181+0000] {process_utils.py:190} INFO -     client.put_object(
[2024-04-25T04:05:48.182+0000] {process_utils.py:190} INFO -   File "/home/***/.local/lib/python3.8/site-packages/botocore/client.py", line 565, in _api_call
[2024-04-25T04:05:48.182+0000] {process_utils.py:190} INFO -     return self._make_api_call(operation_name, kwargs)
[2024-04-25T04:05:48.182+0000] {process_utils.py:190} INFO -   File "/home/***/.local/lib/python3.8/site-packages/botocore/client.py", line 974, in _make_api_call
[2024-04-25T04:05:48.182+0000] {process_utils.py:190} INFO -     request_dict = self._convert_to_request_dict(
[2024-04-25T04:05:48.182+0000] {process_utils.py:190} INFO -   File "/home/***/.local/lib/python3.8/site-packages/botocore/client.py", line 1048, in _convert_to_request_dict
[2024-04-25T04:05:48.183+0000] {process_utils.py:190} INFO -     request_dict = self._serializer.serialize_to_request(
[2024-04-25T04:05:48.183+0000] {process_utils.py:190} INFO -   File "/home/***/.local/lib/python3.8/site-packages/botocore/validate.py", line 381, in serialize_to_request
[2024-04-25T04:05:48.183+0000] {process_utils.py:190} INFO -     raise ParamValidationError(report=report.generate_report())
[2024-04-25T04:05:48.183+0000] {process_utils.py:190} INFO - botocore.exceptions.ParamValidationError: Parameter validation failed:
[2024-04-25T04:05:48.184+0000] {process_utils.py:190} INFO - Invalid type for parameter Body, value: Index(['pixel1', 'pixel2', 'pixel3', 'pixel4', 'pixel5', 'pixel6', 'pixel7',
[2024-04-25T04:05:48.184+0000] {process_utils.py:190} INFO -        'pixel8', 'pixel9', 'pixel10',
[2024-04-25T04:05:48.184+0000] {process_utils.py:190} INFO -        ...
[2024-04-25T04:05:48.184+0000] {process_utils.py:190} INFO -        'pixel776', 'pixel777', 'pixel778', 'pixel779', 'pixel780', 'pixel781',
[2024-04-25T04:05:48.184+0000] {process_utils.py:190} INFO -        'pixel782', 'pixel783', 'pixel784', 'label'],
[2024-04-25T04:05:48.185+0000] {process_utils.py:190} INFO -       dtype='object', length=785), type: <class 'pandas.core.indexes.base.Index'>, valid types: <class 'bytes'>, <class 'bytearray'>, file-like object
[2024-04-25T04:05:48.655+0000] {taskinstance.py:2698} ERROR - Task failed with exception
Traceback (most recent call last):
  File "/home/airflow/.local/lib/python3.8/site-packages/airflow/models/taskinstance.py", line 433, in _execute_task
    result = execute_callable(context=context, **execute_callable_kwargs)
  File "/home/airflow/.local/lib/python3.8/site-packages/airflow/decorators/base.py", line 241, in execute
    return_value = super().execute(context)
  File "/home/airflow/.local/lib/python3.8/site-packages/airflow/operators/python.py", line 400, in execute
    return super().execute(context=serializable_context)
  File "/home/airflow/.local/lib/python3.8/site-packages/airflow/operators/python.py", line 199, in execute
    return_value = self.execute_callable()
  File "/home/airflow/.local/lib/python3.8/site-packages/airflow/operators/python.py", line 716, in execute_callable
    result = self._execute_python_callable_in_subprocess(python_path)
  File "/home/airflow/.local/lib/python3.8/site-packages/airflow/operators/python.py", line 471, in _execute_python_callable_in_subprocess
    raise AirflowException(error_msg) from None
airflow.exceptions.AirflowException: Process returned non-zero exit status 1.
Parameter validation failed:
Invalid type for parameter Body, value: Index(['pixel1', 'pixel2', 'pixel3', 'pixel4', 'pixel5', 'pixel6', 'pixel7',
       'pixel8', 'pixel9', 'pixel10',
       ...
       'pixel776', 'pixel777', 'pixel778', 'pixel779', 'pixel780', 'pixel781',
       'pixel782', 'pixel783', 'pixel784', 'label'],
      dtype='object', length=785), type: <class 'pandas.core.indexes.base.Index'>, valid types: <class 'bytes'>, <class 'bytearray'>, file-like object
[2024-04-25T04:05:48.658+0000] {taskinstance.py:1138} INFO - Marking task as FAILED. dag_id=process_etl_mnist_784_data, task_id=train_model, execution_date=20240424T000000, start_date=20240425T040538, end_date=20240425T040548
[2024-04-25T04:05:48.666+0000] {standard_task_runner.py:107} ERROR - Failed to execute job 9 for task train_model (Process returned non-zero exit status 1.
Parameter validation failed:
Invalid type for parameter Body, value: Index(['pixel1', 'pixel2', 'pixel3', 'pixel4', 'pixel5', 'pixel6', 'pixel7',
       'pixel8', 'pixel9', 'pixel10',
       ...
       'pixel776', 'pixel777', 'pixel778', 'pixel779', 'pixel780', 'pixel781',
       'pixel782', 'pixel783', 'pixel784', 'label'],
      dtype='object', length=785), type: <class 'pandas.core.indexes.base.Index'>, valid types: <class 'bytes'>, <class 'bytearray'>, file-like object; 11709)
[2024-04-25T04:05:48.680+0000] {local_task_job_runner.py:234} INFO - Task exited with return code 1
[2024-04-25T04:05:48.690+0000] {taskinstance.py:3280} INFO - 0 downstream tasks scheduled from follow-on schedule check
[2024-04-25T20:15:35.712+0000] {taskinstance.py:1956} INFO - Dependencies all met for dep_context=non-requeueable deps ti=<TaskInstance: process_etl_mnist_784_data.train_model scheduled__2024-04-24T00:00:00+00:00 [queued]>
[2024-04-25T20:15:35.717+0000] {taskinstance.py:1956} INFO - Dependencies all met for dep_context=requeueable deps ti=<TaskInstance: process_etl_mnist_784_data.train_model scheduled__2024-04-24T00:00:00+00:00 [queued]>
[2024-04-25T20:15:35.717+0000] {taskinstance.py:2170} INFO - Starting attempt 2 of 2
[2024-04-25T20:15:35.845+0000] {taskinstance.py:2191} INFO - Executing <Task(_PythonVirtualenvDecoratedOperator): train_model> on 2024-04-24 00:00:00+00:00
[2024-04-25T20:15:35.850+0000] {standard_task_runner.py:60} INFO - Started process 12543 to run task
[2024-04-25T20:15:35.852+0000] {standard_task_runner.py:87} INFO - Running: ['***', 'tasks', 'run', 'process_etl_mnist_784_data', 'train_model', 'scheduled__2024-04-24T00:00:00+00:00', '--job-id', '6', '--raw', '--subdir', 'DAGS_FOLDER/etl_process.py', '--cfg-path', '/tmp/tmpmgr6fq9m']
[2024-04-25T20:15:35.854+0000] {standard_task_runner.py:88} INFO - Job 6: Subtask train_model
[2024-04-25T20:15:35.883+0000] {task_command.py:423} INFO - Running <TaskInstance: process_etl_mnist_784_data.train_model scheduled__2024-04-24T00:00:00+00:00 [running]> on host fc2c8bd597e1
[2024-04-25T20:15:35.927+0000] {taskinstance.py:2480} INFO - Exporting env vars: AIRFLOW_CTX_DAG_OWNER='Carlos Rodriguez' AIRFLOW_CTX_DAG_ID='process_etl_mnist_784_data' AIRFLOW_CTX_TASK_ID='train_model' AIRFLOW_CTX_EXECUTION_DATE='2024-04-24T00:00:00+00:00' AIRFLOW_CTX_TRY_NUMBER='2' AIRFLOW_CTX_DAG_RUN_ID='scheduled__2024-04-24T00:00:00+00:00'
[2024-04-25T20:15:35.928+0000] {process_utils.py:182} INFO - Executing cmd: /usr/local/bin/python -m virtualenv /tmp/venv2uzaa801 --system-site-packages --python=python
[2024-04-25T20:15:35.934+0000] {process_utils.py:186} INFO - Output:
[2024-04-25T20:15:36.583+0000] {process_utils.py:190} INFO - created virtual environment CPython3.8.18.final.0-64 in 342ms
[2024-04-25T20:15:36.583+0000] {process_utils.py:190} INFO -   creator CPython3Posix(dest=/tmp/venv2uzaa801, clear=False, no_vcs_ignore=False, global=True)
[2024-04-25T20:15:36.583+0000] {process_utils.py:190} INFO -   seeder FromAppData(download=False, pip=bundle, setuptools=bundle, wheel=bundle, via=copy, app_data_dir=/home/***/.local/share/virtualenv)
[2024-04-25T20:15:36.584+0000] {process_utils.py:190} INFO -     added seed packages: pip==23.3.1, setuptools==69.0.2, wheel==0.42.0
[2024-04-25T20:15:36.585+0000] {process_utils.py:190} INFO -   activators BashActivator,CShellActivator,FishActivator,NushellActivator,PowerShellActivator,PythonActivator
[2024-04-25T20:15:36.608+0000] {process_utils.py:182} INFO - Executing cmd: /tmp/venv2uzaa801/bin/pip install -r /tmp/venv2uzaa801/requirements.txt
[2024-04-25T20:15:36.614+0000] {process_utils.py:186} INFO - Output:
[2024-04-25T20:15:37.879+0000] {process_utils.py:190} INFO - Collecting awswrangler==3.6.0 (from -r /tmp/venv2uzaa801/requirements.txt (line 1))
[2024-04-25T20:15:37.882+0000] {process_utils.py:190} INFO -   Using cached awswrangler-3.6.0-py3-none-any.whl.metadata (23 kB)
[2024-04-25T20:15:37.921+0000] {process_utils.py:190} INFO - Requirement already satisfied: boto3<2.0.0,>=1.20.32 in /home/***/.local/lib/python3.8/site-packages (from awswrangler==3.6.0->-r /tmp/venv2uzaa801/requirements.txt (line 1)) (1.34.88)
[2024-04-25T20:15:37.922+0000] {process_utils.py:190} INFO - Requirement already satisfied: botocore<2.0.0,>=1.23.32 in /home/***/.local/lib/python3.8/site-packages (from awswrangler==3.6.0->-r /tmp/venv2uzaa801/requirements.txt (line 1)) (1.34.88)
[2024-04-25T20:15:37.923+0000] {process_utils.py:190} INFO - Requirement already satisfied: numpy<2.0,>=1.18 in /home/***/.local/lib/python3.8/site-packages (from awswrangler==3.6.0->-r /tmp/venv2uzaa801/requirements.txt (line 1)) (1.24.4)
[2024-04-25T20:15:37.923+0000] {process_utils.py:190} INFO - Requirement already satisfied: packaging<24.0,>=21.1 in /home/***/.local/lib/python3.8/site-packages (from awswrangler==3.6.0->-r /tmp/venv2uzaa801/requirements.txt (line 1)) (23.2)
[2024-04-25T20:15:37.924+0000] {process_utils.py:190} INFO - Requirement already satisfied: pandas<2.1.0,>=1.2.0 in /home/***/.local/lib/python3.8/site-packages (from awswrangler==3.6.0->-r /tmp/venv2uzaa801/requirements.txt (line 1)) (2.0.3)
[2024-04-25T20:15:37.925+0000] {process_utils.py:190} INFO - Requirement already satisfied: pyarrow>=7.0.0 in /home/***/.local/lib/python3.8/site-packages (from awswrangler==3.6.0->-r /tmp/venv2uzaa801/requirements.txt (line 1)) (14.0.2)
[2024-04-25T20:15:37.925+0000] {process_utils.py:190} INFO - Requirement already satisfied: typing-extensions<5.0.0,>=4.4.0 in /home/***/.local/lib/python3.8/site-packages (from awswrangler==3.6.0->-r /tmp/venv2uzaa801/requirements.txt (line 1)) (4.9.0)
[2024-04-25T20:15:37.929+0000] {process_utils.py:190} INFO - Requirement already satisfied: jmespath<2.0.0,>=0.7.1 in /home/***/.local/lib/python3.8/site-packages (from boto3<2.0.0,>=1.20.32->awswrangler==3.6.0->-r /tmp/venv2uzaa801/requirements.txt (line 1)) (0.10.0)
[2024-04-25T20:15:37.929+0000] {process_utils.py:190} INFO - Requirement already satisfied: s3transfer<0.11.0,>=0.10.0 in /home/***/.local/lib/python3.8/site-packages (from boto3<2.0.0,>=1.20.32->awswrangler==3.6.0->-r /tmp/venv2uzaa801/requirements.txt (line 1)) (0.10.1)
[2024-04-25T20:15:37.934+0000] {process_utils.py:190} INFO - Requirement already satisfied: python-dateutil<3.0.0,>=2.1 in /home/***/.local/lib/python3.8/site-packages (from botocore<2.0.0,>=1.23.32->awswrangler==3.6.0->-r /tmp/venv2uzaa801/requirements.txt (line 1)) (2.8.2)
[2024-04-25T20:15:37.935+0000] {process_utils.py:190} INFO - Requirement already satisfied: urllib3<1.27,>=1.25.4 in /home/***/.local/lib/python3.8/site-packages (from botocore<2.0.0,>=1.23.32->awswrangler==3.6.0->-r /tmp/venv2uzaa801/requirements.txt (line 1)) (1.26.18)
[2024-04-25T20:15:37.994+0000] {process_utils.py:190} INFO - Requirement already satisfied: pytz>=2020.1 in /home/***/.local/lib/python3.8/site-packages (from pandas<2.1.0,>=1.2.0->awswrangler==3.6.0->-r /tmp/venv2uzaa801/requirements.txt (line 1)) (2023.3.post1)
[2024-04-25T20:15:37.994+0000] {process_utils.py:190} INFO - Requirement already satisfied: tzdata>=2022.1 in /home/***/.local/lib/python3.8/site-packages (from pandas<2.1.0,>=1.2.0->awswrangler==3.6.0->-r /tmp/venv2uzaa801/requirements.txt (line 1)) (2023.4)
[2024-04-25T20:15:38.000+0000] {process_utils.py:190} INFO - Requirement already satisfied: six>=1.5 in /home/***/.local/lib/python3.8/site-packages (from python-dateutil<3.0.0,>=2.1->botocore<2.0.0,>=1.23.32->awswrangler==3.6.0->-r /tmp/venv2uzaa801/requirements.txt (line 1)) (1.16.0)
[2024-04-25T20:15:38.027+0000] {process_utils.py:190} INFO - Using cached awswrangler-3.6.0-py3-none-any.whl (403 kB)
[2024-04-25T20:15:40.210+0000] {process_utils.py:190} INFO - Installing collected packages: awswrangler
[2024-04-25T20:15:40.479+0000] {process_utils.py:190} INFO - Successfully installed awswrangler-3.6.0
[2024-04-25T20:15:40.642+0000] {process_utils.py:190} INFO - 
[2024-04-25T20:15:40.643+0000] {process_utils.py:190} INFO - [notice] A new release of pip is available: 23.3.1 -> 24.0
[2024-04-25T20:15:40.643+0000] {process_utils.py:190} INFO - [notice] To update, run: python -m pip install --upgrade pip
[2024-04-25T20:15:40.795+0000] {process_utils.py:182} INFO - Executing cmd: /tmp/venv2uzaa801/bin/python /tmp/venv-callsqigld21/script.py /tmp/venv-callsqigld21/script.in /tmp/venv-callsqigld21/script.out /tmp/venv-callsqigld21/string_args.txt /tmp/venv-callsqigld21/termination.log
[2024-04-25T20:15:40.800+0000] {process_utils.py:186} INFO - Output:
[2024-04-25T20:15:44.080+0000] {process_utils.py:190} INFO - [[34m2024-04-25T20:15:44.079+0000[0m] {[34mcredentials.py:[0m1147} INFO[0m - Found credentials in environment variables.[0m
[2024-04-25T20:15:44.144+0000] {process_utils.py:190} INFO - [[34m2024-04-25T20:15:44.144+0000[0m] {[34mconfigprovider.py:[0m957} INFO[0m - Found endpoint for s3 via: environment_service.[0m
[2024-04-25T20:20:22.299+0000] {job.py:213} ERROR - Job heartbeat got an exception
Traceback (most recent call last):
  File "/home/airflow/.local/lib/python3.8/site-packages/sqlalchemy/engine/base.py", line 3371, in _wrap_pool_connect
    return fn()
  File "/home/airflow/.local/lib/python3.8/site-packages/sqlalchemy/pool/base.py", line 327, in connect
    return _ConnectionFairy._checkout(self)
  File "/home/airflow/.local/lib/python3.8/site-packages/sqlalchemy/pool/base.py", line 894, in _checkout
    fairy = _ConnectionRecord.checkout(pool)
  File "/home/airflow/.local/lib/python3.8/site-packages/sqlalchemy/pool/base.py", line 493, in checkout
    rec = pool._do_get()
  File "/home/airflow/.local/lib/python3.8/site-packages/sqlalchemy/pool/impl.py", line 256, in _do_get
    return self._create_connection()
  File "/home/airflow/.local/lib/python3.8/site-packages/sqlalchemy/pool/base.py", line 273, in _create_connection
    return _ConnectionRecord(self)
  File "/home/airflow/.local/lib/python3.8/site-packages/sqlalchemy/pool/base.py", line 388, in __init__
    self.__connect()
  File "/home/airflow/.local/lib/python3.8/site-packages/sqlalchemy/pool/base.py", line 691, in __connect
    pool.logger.debug("Error on connect(): %s", e)
  File "/home/airflow/.local/lib/python3.8/site-packages/sqlalchemy/util/langhelpers.py", line 70, in __exit__
    compat.raise_(
  File "/home/airflow/.local/lib/python3.8/site-packages/sqlalchemy/util/compat.py", line 211, in raise_
    raise exception
  File "/home/airflow/.local/lib/python3.8/site-packages/sqlalchemy/pool/base.py", line 686, in __connect
    self.dbapi_connection = connection = pool._invoke_creator(self)
  File "/home/airflow/.local/lib/python3.8/site-packages/sqlalchemy/engine/create.py", line 574, in connect
    return dialect.connect(*cargs, **cparams)
  File "/home/airflow/.local/lib/python3.8/site-packages/sqlalchemy/engine/default.py", line 598, in connect
    return self.dbapi.connect(*cargs, **cparams)
  File "/home/airflow/.local/lib/python3.8/site-packages/psycopg2/__init__.py", line 122, in connect
    conn = _connect(dsn, connection_factory=connection_factory, **kwasync)
psycopg2.OperationalError: could not translate host name "postgres" to address: Temporary failure in name resolution


The above exception was the direct cause of the following exception:

Traceback (most recent call last):
  File "/home/airflow/.local/lib/python3.8/site-packages/airflow/jobs/job.py", line 208, in heartbeat
    heartbeat_callback(session)
  File "/home/airflow/.local/lib/python3.8/site-packages/airflow/utils/session.py", line 76, in wrapper
    return func(*args, **kwargs)
  File "/home/airflow/.local/lib/python3.8/site-packages/airflow/jobs/local_task_job_runner.py", line 252, in heartbeat_callback
    self.task_instance.refresh_from_db()
  File "/home/airflow/.local/lib/python3.8/site-packages/airflow/utils/session.py", line 79, in wrapper
    return func(*args, session=session, **kwargs)
  File "/home/airflow/.local/lib/python3.8/site-packages/airflow/models/taskinstance.py", line 1725, in refresh_from_db
    _refresh_from_db(task_instance=self, session=session, lock_for_update=lock_for_update)
  File "/home/airflow/.local/lib/python3.8/site-packages/airflow/models/taskinstance.py", line 464, in _refresh_from_db
    ti = TaskInstance.get_task_instance(
  File "/home/airflow/.local/lib/python3.8/site-packages/airflow/api_internal/internal_api_call.py", line 114, in wrapper
    return func(*args, **kwargs)
  File "/home/airflow/.local/lib/python3.8/site-packages/airflow/utils/session.py", line 76, in wrapper
    return func(*args, **kwargs)
  File "/home/airflow/.local/lib/python3.8/site-packages/airflow/models/taskinstance.py", line 1711, in get_task_instance
    return query.one_or_none()
  File "/home/airflow/.local/lib/python3.8/site-packages/sqlalchemy/orm/query.py", line 2850, in one_or_none
    return self._iter().one_or_none()
  File "/home/airflow/.local/lib/python3.8/site-packages/sqlalchemy/orm/query.py", line 2916, in _iter
    result = self.session.execute(
  File "/home/airflow/.local/lib/python3.8/site-packages/sqlalchemy/orm/session.py", line 1716, in execute
    conn = self._connection_for_bind(bind)
  File "/home/airflow/.local/lib/python3.8/site-packages/sqlalchemy/orm/session.py", line 1555, in _connection_for_bind
    return self._transaction._connection_for_bind(
  File "/home/airflow/.local/lib/python3.8/site-packages/sqlalchemy/orm/session.py", line 750, in _connection_for_bind
    conn = bind.connect()
  File "/home/airflow/.local/lib/python3.8/site-packages/sqlalchemy/future/engine.py", line 412, in connect
    return super(Engine, self).connect()
  File "/home/airflow/.local/lib/python3.8/site-packages/sqlalchemy/engine/base.py", line 3325, in connect
    return self._connection_cls(self, close_with_result=close_with_result)
  File "/home/airflow/.local/lib/python3.8/site-packages/sqlalchemy/engine/base.py", line 96, in __init__
    else engine.raw_connection()
  File "/home/airflow/.local/lib/python3.8/site-packages/sqlalchemy/engine/base.py", line 3404, in raw_connection
    return self._wrap_pool_connect(self.pool.connect, _connection)
  File "/home/airflow/.local/lib/python3.8/site-packages/sqlalchemy/engine/base.py", line 3374, in _wrap_pool_connect
    Connection._handle_dbapi_exception_noconnection(
  File "/home/airflow/.local/lib/python3.8/site-packages/sqlalchemy/engine/base.py", line 2208, in _handle_dbapi_exception_noconnection
    util.raise_(
  File "/home/airflow/.local/lib/python3.8/site-packages/sqlalchemy/util/compat.py", line 211, in raise_
    raise exception
  File "/home/airflow/.local/lib/python3.8/site-packages/sqlalchemy/engine/base.py", line 3371, in _wrap_pool_connect
    return fn()
  File "/home/airflow/.local/lib/python3.8/site-packages/sqlalchemy/pool/base.py", line 327, in connect
    return _ConnectionFairy._checkout(self)
  File "/home/airflow/.local/lib/python3.8/site-packages/sqlalchemy/pool/base.py", line 894, in _checkout
    fairy = _ConnectionRecord.checkout(pool)
  File "/home/airflow/.local/lib/python3.8/site-packages/sqlalchemy/pool/base.py", line 493, in checkout
    rec = pool._do_get()
  File "/home/airflow/.local/lib/python3.8/site-packages/sqlalchemy/pool/impl.py", line 256, in _do_get
    return self._create_connection()
  File "/home/airflow/.local/lib/python3.8/site-packages/sqlalchemy/pool/base.py", line 273, in _create_connection
    return _ConnectionRecord(self)
  File "/home/airflow/.local/lib/python3.8/site-packages/sqlalchemy/pool/base.py", line 388, in __init__
    self.__connect()
  File "/home/airflow/.local/lib/python3.8/site-packages/sqlalchemy/pool/base.py", line 691, in __connect
    pool.logger.debug("Error on connect(): %s", e)
  File "/home/airflow/.local/lib/python3.8/site-packages/sqlalchemy/util/langhelpers.py", line 70, in __exit__
    compat.raise_(
  File "/home/airflow/.local/lib/python3.8/site-packages/sqlalchemy/util/compat.py", line 211, in raise_
    raise exception
  File "/home/airflow/.local/lib/python3.8/site-packages/sqlalchemy/pool/base.py", line 686, in __connect
    self.dbapi_connection = connection = pool._invoke_creator(self)
  File "/home/airflow/.local/lib/python3.8/site-packages/sqlalchemy/engine/create.py", line 574, in connect
    return dialect.connect(*cargs, **cparams)
  File "/home/airflow/.local/lib/python3.8/site-packages/sqlalchemy/engine/default.py", line 598, in connect
    return self.dbapi.connect(*cargs, **cparams)
  File "/home/airflow/.local/lib/python3.8/site-packages/psycopg2/__init__.py", line 122, in connect
    conn = _connect(dsn, connection_factory=connection_factory, **kwasync)
sqlalchemy.exc.OperationalError: (psycopg2.OperationalError) could not translate host name "postgres" to address: Temporary failure in name resolution

(Background on this error at: https://sqlalche.me/e/14/e3q8)
[2024-04-25T20:20:31.362+0000] {job.py:221} ERROR - Job heartbeat failed with error. Scheduler is in unhealthy state
[2024-04-25T20:21:44.243+0000] {local_task_job_runner.py:121} ERROR - Received SIGTERM. Terminating subprocesses
[2024-04-25T20:21:45.216+0000] {process_utils.py:131} INFO - Sending 15 to group 12543. PIDs of all processes in the group: [12606, 12543]
[2024-04-25T20:21:45.235+0000] {process_utils.py:86} INFO - Sending the signal 15 to group 12543
[2024-04-25T20:21:45.361+0000] {taskinstance.py:2450} ERROR - Received SIGTERM. Terminating subprocesses.
[2024-04-25T20:21:45.782+0000] {process_utils.py:79} INFO - Process psutil.Process(pid=12606, status='terminated', started='20:15:40') (12606) terminated with exit code None
[2024-04-25T20:21:46.949+0000] {taskinstance.py:2698} ERROR - Task failed with exception
Traceback (most recent call last):
  File "/home/airflow/.local/lib/python3.8/site-packages/airflow/models/taskinstance.py", line 433, in _execute_task
    result = execute_callable(context=context, **execute_callable_kwargs)
  File "/home/airflow/.local/lib/python3.8/site-packages/airflow/decorators/base.py", line 241, in execute
    return_value = super().execute(context)
  File "/home/airflow/.local/lib/python3.8/site-packages/airflow/operators/python.py", line 400, in execute
    return super().execute(context=serializable_context)
  File "/home/airflow/.local/lib/python3.8/site-packages/airflow/operators/python.py", line 199, in execute
    return_value = self.execute_callable()
  File "/home/airflow/.local/lib/python3.8/site-packages/airflow/operators/python.py", line 716, in execute_callable
    result = self._execute_python_callable_in_subprocess(python_path)
  File "/home/airflow/.local/lib/python3.8/site-packages/airflow/operators/python.py", line 454, in _execute_python_callable_in_subprocess
    execute_in_subprocess(
  File "/home/airflow/.local/lib/python3.8/site-packages/airflow/utils/process_utils.py", line 171, in execute_in_subprocess
    execute_in_subprocess_with_kwargs(cmd, cwd=cwd)
  File "/home/airflow/.local/lib/python3.8/site-packages/airflow/utils/process_utils.py", line 189, in execute_in_subprocess_with_kwargs
    for line in iter(proc.stdout.readline, b""):
  File "/home/airflow/.local/lib/python3.8/site-packages/airflow/models/taskinstance.py", line 2452, in signal_handler
    raise AirflowException("Task received SIGTERM signal")
airflow.exceptions.AirflowException: Task received SIGTERM signal
[2024-04-25T20:21:47.150+0000] {taskinstance.py:1138} INFO - Marking task as FAILED. dag_id=process_etl_mnist_784_data, task_id=train_model, execution_date=20240424T000000, start_date=20240425T201535, end_date=20240425T202147
[2024-04-25T20:21:47.757+0000] {standard_task_runner.py:107} ERROR - Failed to execute job 6 for task train_model (Task received SIGTERM signal; 12543)
[2024-04-25T20:21:47.876+0000] {process_utils.py:79} INFO - Process psutil.Process(pid=12543, status='terminated', exitcode=1, started='20:15:35') (12543) terminated with exit code 1
[2024-04-25T20:21:47.904+0000] {local_task_job_runner.py:234} INFO - Task exited with return code 143
[2024-04-25T20:21:48.431+0000] {taskinstance.py:3280} INFO - 0 downstream tasks scheduled from follow-on schedule check
[2024-04-25T20:50:00.012+0000] {taskinstance.py:1956} INFO - Dependencies all met for dep_context=non-requeueable deps ti=<TaskInstance: process_etl_mnist_784_data.train_model scheduled__2024-04-24T00:00:00+00:00 [queued]>
[2024-04-25T20:50:00.016+0000] {taskinstance.py:1956} INFO - Dependencies all met for dep_context=requeueable deps ti=<TaskInstance: process_etl_mnist_784_data.train_model scheduled__2024-04-24T00:00:00+00:00 [queued]>
[2024-04-25T20:50:00.016+0000] {taskinstance.py:2170} INFO - Starting attempt 2 of 2
[2024-04-25T20:50:00.025+0000] {taskinstance.py:2191} INFO - Executing <Task(_PythonVirtualenvDecoratedOperator): train_model> on 2024-04-24 00:00:00+00:00
[2024-04-25T20:50:00.028+0000] {standard_task_runner.py:60} INFO - Started process 8317 to run task
[2024-04-25T20:50:00.030+0000] {standard_task_runner.py:87} INFO - Running: ['***', 'tasks', 'run', 'process_etl_mnist_784_data', 'train_model', 'scheduled__2024-04-24T00:00:00+00:00', '--job-id', '6', '--raw', '--subdir', 'DAGS_FOLDER/etl_process.py', '--cfg-path', '/tmp/tmp7hsb2yvo']
[2024-04-25T20:50:00.032+0000] {standard_task_runner.py:88} INFO - Job 6: Subtask train_model
[2024-04-25T20:50:00.061+0000] {task_command.py:423} INFO - Running <TaskInstance: process_etl_mnist_784_data.train_model scheduled__2024-04-24T00:00:00+00:00 [running]> on host b1d103f3af44
[2024-04-25T20:50:00.107+0000] {taskinstance.py:2480} INFO - Exporting env vars: AIRFLOW_CTX_DAG_OWNER='Carlos Rodriguez' AIRFLOW_CTX_DAG_ID='process_etl_mnist_784_data' AIRFLOW_CTX_TASK_ID='train_model' AIRFLOW_CTX_EXECUTION_DATE='2024-04-24T00:00:00+00:00' AIRFLOW_CTX_TRY_NUMBER='2' AIRFLOW_CTX_DAG_RUN_ID='scheduled__2024-04-24T00:00:00+00:00'
[2024-04-25T20:50:00.109+0000] {process_utils.py:182} INFO - Executing cmd: /usr/local/bin/python -m virtualenv /tmp/venvprel7jsp --system-site-packages --python=python
[2024-04-25T20:50:00.114+0000] {process_utils.py:186} INFO - Output:
[2024-04-25T20:50:01.126+0000] {process_utils.py:190} INFO - created virtual environment CPython3.8.18.final.0-64 in 602ms
[2024-04-25T20:50:01.127+0000] {process_utils.py:190} INFO -   creator CPython3Posix(dest=/tmp/venvprel7jsp, clear=False, no_vcs_ignore=False, global=True)
[2024-04-25T20:50:01.127+0000] {process_utils.py:190} INFO -   seeder FromAppData(download=False, pip=bundle, setuptools=bundle, wheel=bundle, via=copy, app_data_dir=/home/***/.local/share/virtualenv)
[2024-04-25T20:50:01.128+0000] {process_utils.py:190} INFO -     added seed packages: pip==23.3.1, setuptools==69.0.2, wheel==0.42.0
[2024-04-25T20:50:01.128+0000] {process_utils.py:190} INFO -   activators BashActivator,CShellActivator,FishActivator,NushellActivator,PowerShellActivator,PythonActivator
[2024-04-25T20:50:01.146+0000] {process_utils.py:182} INFO - Executing cmd: /tmp/venvprel7jsp/bin/pip install -r /tmp/venvprel7jsp/requirements.txt
[2024-04-25T20:50:01.151+0000] {process_utils.py:186} INFO - Output:
[2024-04-25T20:50:02.246+0000] {process_utils.py:190} INFO - Collecting awswrangler==3.6.0 (from -r /tmp/venvprel7jsp/requirements.txt (line 1))
[2024-04-25T20:50:02.248+0000] {process_utils.py:190} INFO -   Using cached awswrangler-3.6.0-py3-none-any.whl.metadata (23 kB)
[2024-04-25T20:50:02.282+0000] {process_utils.py:190} INFO - Requirement already satisfied: boto3<2.0.0,>=1.20.32 in /home/***/.local/lib/python3.8/site-packages (from awswrangler==3.6.0->-r /tmp/venvprel7jsp/requirements.txt (line 1)) (1.34.88)
[2024-04-25T20:50:02.283+0000] {process_utils.py:190} INFO - Requirement already satisfied: botocore<2.0.0,>=1.23.32 in /home/***/.local/lib/python3.8/site-packages (from awswrangler==3.6.0->-r /tmp/venvprel7jsp/requirements.txt (line 1)) (1.34.88)
[2024-04-25T20:50:02.284+0000] {process_utils.py:190} INFO - Requirement already satisfied: numpy<2.0,>=1.18 in /home/***/.local/lib/python3.8/site-packages (from awswrangler==3.6.0->-r /tmp/venvprel7jsp/requirements.txt (line 1)) (1.24.4)
[2024-04-25T20:50:02.285+0000] {process_utils.py:190} INFO - Requirement already satisfied: packaging<24.0,>=21.1 in /home/***/.local/lib/python3.8/site-packages (from awswrangler==3.6.0->-r /tmp/venvprel7jsp/requirements.txt (line 1)) (23.2)
[2024-04-25T20:50:02.286+0000] {process_utils.py:190} INFO - Requirement already satisfied: pandas<2.1.0,>=1.2.0 in /home/***/.local/lib/python3.8/site-packages (from awswrangler==3.6.0->-r /tmp/venvprel7jsp/requirements.txt (line 1)) (2.0.3)
[2024-04-25T20:50:02.287+0000] {process_utils.py:190} INFO - Requirement already satisfied: pyarrow>=7.0.0 in /home/***/.local/lib/python3.8/site-packages (from awswrangler==3.6.0->-r /tmp/venvprel7jsp/requirements.txt (line 1)) (14.0.2)
[2024-04-25T20:50:02.287+0000] {process_utils.py:190} INFO - Requirement already satisfied: typing-extensions<5.0.0,>=4.4.0 in /home/***/.local/lib/python3.8/site-packages (from awswrangler==3.6.0->-r /tmp/venvprel7jsp/requirements.txt (line 1)) (4.9.0)
[2024-04-25T20:50:02.291+0000] {process_utils.py:190} INFO - Requirement already satisfied: jmespath<2.0.0,>=0.7.1 in /home/***/.local/lib/python3.8/site-packages (from boto3<2.0.0,>=1.20.32->awswrangler==3.6.0->-r /tmp/venvprel7jsp/requirements.txt (line 1)) (0.10.0)
[2024-04-25T20:50:02.292+0000] {process_utils.py:190} INFO - Requirement already satisfied: s3transfer<0.11.0,>=0.10.0 in /home/***/.local/lib/python3.8/site-packages (from boto3<2.0.0,>=1.20.32->awswrangler==3.6.0->-r /tmp/venvprel7jsp/requirements.txt (line 1)) (0.10.1)
[2024-04-25T20:50:02.297+0000] {process_utils.py:190} INFO - Requirement already satisfied: python-dateutil<3.0.0,>=2.1 in /home/***/.local/lib/python3.8/site-packages (from botocore<2.0.0,>=1.23.32->awswrangler==3.6.0->-r /tmp/venvprel7jsp/requirements.txt (line 1)) (2.8.2)
[2024-04-25T20:50:02.298+0000] {process_utils.py:190} INFO - Requirement already satisfied: urllib3<1.27,>=1.25.4 in /home/***/.local/lib/python3.8/site-packages (from botocore<2.0.0,>=1.23.32->awswrangler==3.6.0->-r /tmp/venvprel7jsp/requirements.txt (line 1)) (1.26.18)
[2024-04-25T20:50:02.356+0000] {process_utils.py:190} INFO - Requirement already satisfied: pytz>=2020.1 in /home/***/.local/lib/python3.8/site-packages (from pandas<2.1.0,>=1.2.0->awswrangler==3.6.0->-r /tmp/venvprel7jsp/requirements.txt (line 1)) (2023.3.post1)
[2024-04-25T20:50:02.357+0000] {process_utils.py:190} INFO - Requirement already satisfied: tzdata>=2022.1 in /home/***/.local/lib/python3.8/site-packages (from pandas<2.1.0,>=1.2.0->awswrangler==3.6.0->-r /tmp/venvprel7jsp/requirements.txt (line 1)) (2023.4)
[2024-04-25T20:50:02.363+0000] {process_utils.py:190} INFO - Requirement already satisfied: six>=1.5 in /home/***/.local/lib/python3.8/site-packages (from python-dateutil<3.0.0,>=2.1->botocore<2.0.0,>=1.23.32->awswrangler==3.6.0->-r /tmp/venvprel7jsp/requirements.txt (line 1)) (1.16.0)
[2024-04-25T20:50:02.387+0000] {process_utils.py:190} INFO - Using cached awswrangler-3.6.0-py3-none-any.whl (403 kB)
[2024-04-25T20:50:04.488+0000] {process_utils.py:190} INFO - Installing collected packages: awswrangler
[2024-04-25T20:50:04.765+0000] {process_utils.py:190} INFO - Successfully installed awswrangler-3.6.0
[2024-04-25T20:50:04.907+0000] {process_utils.py:190} INFO - 
[2024-04-25T20:50:04.907+0000] {process_utils.py:190} INFO - [notice] A new release of pip is available: 23.3.1 -> 24.0
[2024-04-25T20:50:04.908+0000] {process_utils.py:190} INFO - [notice] To update, run: python -m pip install --upgrade pip
[2024-04-25T20:50:05.087+0000] {process_utils.py:182} INFO - Executing cmd: /tmp/venvprel7jsp/bin/python /tmp/venv-callj_26v9z7/script.py /tmp/venv-callj_26v9z7/script.in /tmp/venv-callj_26v9z7/script.out /tmp/venv-callj_26v9z7/string_args.txt /tmp/venv-callj_26v9z7/termination.log
[2024-04-25T20:50:05.092+0000] {process_utils.py:186} INFO - Output:
[2024-04-25T20:50:10.176+0000] {process_utils.py:190} INFO - [[34m2024-04-25T20:50:10.175+0000[0m] {[34mcredentials.py:[0m1147} INFO[0m - Found credentials in environment variables.[0m
[2024-04-25T20:50:10.232+0000] {process_utils.py:190} INFO - [[34m2024-04-25T20:50:10.232+0000[0m] {[34mconfigprovider.py:[0m957} INFO[0m - Found endpoint for s3 via: environment_service.[0m
[2024-04-25T20:54:09.936+0000] {taskinstance.py:2698} ERROR - Task failed with exception
Traceback (most recent call last):
  File "/home/airflow/.local/lib/python3.8/site-packages/airflow/models/taskinstance.py", line 433, in _execute_task
    result = execute_callable(context=context, **execute_callable_kwargs)
  File "/home/airflow/.local/lib/python3.8/site-packages/airflow/decorators/base.py", line 241, in execute
    return_value = super().execute(context)
  File "/home/airflow/.local/lib/python3.8/site-packages/airflow/operators/python.py", line 400, in execute
    return super().execute(context=serializable_context)
  File "/home/airflow/.local/lib/python3.8/site-packages/airflow/operators/python.py", line 199, in execute
    return_value = self.execute_callable()
  File "/home/airflow/.local/lib/python3.8/site-packages/airflow/operators/python.py", line 716, in execute_callable
    result = self._execute_python_callable_in_subprocess(python_path)
  File "/home/airflow/.local/lib/python3.8/site-packages/airflow/operators/python.py", line 454, in _execute_python_callable_in_subprocess
    execute_in_subprocess(
  File "/home/airflow/.local/lib/python3.8/site-packages/airflow/utils/process_utils.py", line 171, in execute_in_subprocess
    execute_in_subprocess_with_kwargs(cmd, cwd=cwd)
  File "/home/airflow/.local/lib/python3.8/site-packages/airflow/utils/process_utils.py", line 194, in execute_in_subprocess_with_kwargs
    raise subprocess.CalledProcessError(exit_code, cmd)
subprocess.CalledProcessError: Command '['/tmp/venvprel7jsp/bin/python', '/tmp/venv-callj_26v9z7/script.py', '/tmp/venv-callj_26v9z7/script.in', '/tmp/venv-callj_26v9z7/script.out', '/tmp/venv-callj_26v9z7/string_args.txt', '/tmp/venv-callj_26v9z7/termination.log']' died with <Signals.SIGKILL: 9>.
[2024-04-25T20:54:14.450+0000] {taskinstance.py:1138} INFO - Marking task as FAILED. dag_id=process_etl_mnist_784_data, task_id=train_model, execution_date=20240424T000000, start_date=20240425T205000, end_date=20240425T205414
[2024-04-25T20:54:14.975+0000] {standard_task_runner.py:107} ERROR - Failed to execute job 6 for task train_model (Command '['/tmp/venvprel7jsp/bin/python', '/tmp/venv-callj_26v9z7/script.py', '/tmp/venv-callj_26v9z7/script.in', '/tmp/venv-callj_26v9z7/script.out', '/tmp/venv-callj_26v9z7/string_args.txt', '/tmp/venv-callj_26v9z7/termination.log']' died with <Signals.SIGKILL: 9>.; 8317)
[2024-04-25T20:54:15.070+0000] {local_task_job_runner.py:234} INFO - Task exited with return code 1
[2024-04-25T20:54:15.354+0000] {taskinstance.py:3280} INFO - 0 downstream tasks scheduled from follow-on schedule check
