[2024-04-24T23:43:46.017+0000] {taskinstance.py:1956} INFO - Dependencies all met for dep_context=non-requeueable deps ti=<TaskInstance: retrain_the_model_mnist_784.train_the_challenger_model scheduled__2024-04-23T00:00:00+00:00 [queued]>
[2024-04-24T23:43:46.024+0000] {taskinstance.py:1956} INFO - Dependencies all met for dep_context=requeueable deps ti=<TaskInstance: retrain_the_model_mnist_784.train_the_challenger_model scheduled__2024-04-23T00:00:00+00:00 [queued]>
[2024-04-24T23:43:46.025+0000] {taskinstance.py:2170} INFO - Starting attempt 1 of 2
[2024-04-24T23:43:46.037+0000] {taskinstance.py:2191} INFO - Executing <Task(_PythonVirtualenvDecoratedOperator): train_the_challenger_model> on 2024-04-23 00:00:00+00:00
[2024-04-24T23:43:46.043+0000] {standard_task_runner.py:60} INFO - Started process 13410 to run task
[2024-04-24T23:43:46.045+0000] {standard_task_runner.py:87} INFO - Running: ['***', 'tasks', 'run', 'retrain_the_model_mnist_784', 'train_the_challenger_model', 'scheduled__2024-04-23T00:00:00+00:00', '--job-id', '37', '--raw', '--subdir', 'DAGS_FOLDER/retrain_the_model.py', '--cfg-path', '/tmp/tmpv9mc885c']
[2024-04-24T23:43:46.048+0000] {standard_task_runner.py:88} INFO - Job 37: Subtask train_the_challenger_model
[2024-04-24T23:43:46.266+0000] {task_command.py:423} INFO - Running <TaskInstance: retrain_the_model_mnist_784.train_the_challenger_model scheduled__2024-04-23T00:00:00+00:00 [running]> on host 6bdddfadcc67
[2024-04-24T23:43:46.317+0000] {taskinstance.py:2480} INFO - Exporting env vars: AIRFLOW_CTX_DAG_OWNER='Carlos Rodriguez' AIRFLOW_CTX_DAG_ID='retrain_the_model_mnist_784' AIRFLOW_CTX_TASK_ID='train_the_challenger_model' AIRFLOW_CTX_EXECUTION_DATE='2024-04-23T00:00:00+00:00' AIRFLOW_CTX_TRY_NUMBER='1' AIRFLOW_CTX_DAG_RUN_ID='scheduled__2024-04-23T00:00:00+00:00'
[2024-04-24T23:43:46.319+0000] {process_utils.py:182} INFO - Executing cmd: /usr/local/bin/python -m virtualenv /tmp/venv9718v237 --system-site-packages --python=python
[2024-04-24T23:43:46.326+0000] {process_utils.py:186} INFO - Output:
[2024-04-24T23:43:46.845+0000] {process_utils.py:190} INFO - created virtual environment CPython3.8.18.final.0-64 in 188ms
[2024-04-24T23:43:46.845+0000] {process_utils.py:190} INFO -   creator CPython3Posix(dest=/tmp/venv9718v237, clear=False, no_vcs_ignore=False, global=True)
[2024-04-24T23:43:46.846+0000] {process_utils.py:190} INFO -   seeder FromAppData(download=False, pip=bundle, setuptools=bundle, wheel=bundle, via=copy, app_data_dir=/home/***/.local/share/virtualenv)
[2024-04-24T23:43:46.846+0000] {process_utils.py:190} INFO -     added seed packages: pip==23.3.1, setuptools==69.0.2, wheel==0.42.0
[2024-04-24T23:43:46.846+0000] {process_utils.py:190} INFO -   activators BashActivator,CShellActivator,FishActivator,NushellActivator,PowerShellActivator,PythonActivator
[2024-04-24T23:43:46.879+0000] {process_utils.py:182} INFO - Executing cmd: /tmp/venv9718v237/bin/pip install -r /tmp/venv9718v237/requirements.txt
[2024-04-24T23:43:46.885+0000] {process_utils.py:186} INFO - Output:
[2024-04-24T23:43:47.848+0000] {process_utils.py:190} INFO - Collecting awswrangler==3.6.0 (from -r /tmp/venv9718v237/requirements.txt (line 1))
[2024-04-24T23:43:47.850+0000] {process_utils.py:190} INFO -   Using cached awswrangler-3.6.0-py3-none-any.whl.metadata (23 kB)
[2024-04-24T23:43:48.064+0000] {process_utils.py:190} INFO - Collecting mlflow==2.10.2 (from -r /tmp/venv9718v237/requirements.txt (line 2))
[2024-04-24T23:43:48.196+0000] {process_utils.py:190} INFO -   Downloading mlflow-2.10.2-py3-none-any.whl.metadata (13 kB)
[2024-04-24T23:43:48.203+0000] {process_utils.py:190} INFO - Requirement already satisfied: scikit-learn==1.3.2 in /home/***/.local/lib/python3.8/site-packages (from -r /tmp/venv9718v237/requirements.txt (line 3)) (1.3.2)
[2024-04-24T23:43:48.234+0000] {process_utils.py:190} INFO - Requirement already satisfied: boto3<2.0.0,>=1.20.32 in /home/***/.local/lib/python3.8/site-packages (from awswrangler==3.6.0->-r /tmp/venv9718v237/requirements.txt (line 1)) (1.34.88)
[2024-04-24T23:43:48.234+0000] {process_utils.py:190} INFO - Requirement already satisfied: botocore<2.0.0,>=1.23.32 in /home/***/.local/lib/python3.8/site-packages (from awswrangler==3.6.0->-r /tmp/venv9718v237/requirements.txt (line 1)) (1.34.88)
[2024-04-24T23:43:48.235+0000] {process_utils.py:190} INFO - Requirement already satisfied: numpy<2.0,>=1.18 in /home/***/.local/lib/python3.8/site-packages (from awswrangler==3.6.0->-r /tmp/venv9718v237/requirements.txt (line 1)) (1.24.4)
[2024-04-24T23:43:48.236+0000] {process_utils.py:190} INFO - Requirement already satisfied: packaging<24.0,>=21.1 in /home/***/.local/lib/python3.8/site-packages (from awswrangler==3.6.0->-r /tmp/venv9718v237/requirements.txt (line 1)) (23.2)
[2024-04-24T23:43:48.236+0000] {process_utils.py:190} INFO - Requirement already satisfied: pandas<2.1.0,>=1.2.0 in /home/***/.local/lib/python3.8/site-packages (from awswrangler==3.6.0->-r /tmp/venv9718v237/requirements.txt (line 1)) (2.0.3)
[2024-04-24T23:43:48.237+0000] {process_utils.py:190} INFO - Requirement already satisfied: pyarrow>=7.0.0 in /home/***/.local/lib/python3.8/site-packages (from awswrangler==3.6.0->-r /tmp/venv9718v237/requirements.txt (line 1)) (14.0.2)
[2024-04-24T23:43:48.238+0000] {process_utils.py:190} INFO - Requirement already satisfied: typing-extensions<5.0.0,>=4.4.0 in /home/***/.local/lib/python3.8/site-packages (from awswrangler==3.6.0->-r /tmp/venv9718v237/requirements.txt (line 1)) (4.9.0)
[2024-04-24T23:43:48.276+0000] {process_utils.py:190} INFO - Requirement already satisfied: click<9,>=7.0 in /home/***/.local/lib/python3.8/site-packages (from mlflow==2.10.2->-r /tmp/venv9718v237/requirements.txt (line 2)) (8.1.7)
[2024-04-24T23:43:48.277+0000] {process_utils.py:190} INFO - Requirement already satisfied: cloudpickle<4 in /home/***/.local/lib/python3.8/site-packages (from mlflow==2.10.2->-r /tmp/venv9718v237/requirements.txt (line 2)) (3.0.0)
[2024-04-24T23:43:48.277+0000] {process_utils.py:190} INFO - Requirement already satisfied: entrypoints<1 in /home/***/.local/lib/python3.8/site-packages (from mlflow==2.10.2->-r /tmp/venv9718v237/requirements.txt (line 2)) (0.4)
[2024-04-24T23:43:48.277+0000] {process_utils.py:190} INFO - Requirement already satisfied: gitpython<4,>=2.1.0 in /home/***/.local/lib/python3.8/site-packages (from mlflow==2.10.2->-r /tmp/venv9718v237/requirements.txt (line 2)) (3.1.43)
[2024-04-24T23:43:48.278+0000] {process_utils.py:190} INFO - Requirement already satisfied: pyyaml<7,>=5.1 in /home/***/.local/lib/python3.8/site-packages (from mlflow==2.10.2->-r /tmp/venv9718v237/requirements.txt (line 2)) (6.0.1)
[2024-04-24T23:43:48.278+0000] {process_utils.py:190} INFO - Requirement already satisfied: protobuf<5,>=3.12.0 in /home/***/.local/lib/python3.8/site-packages (from mlflow==2.10.2->-r /tmp/venv9718v237/requirements.txt (line 2)) (4.25.2)
[2024-04-24T23:43:48.279+0000] {process_utils.py:190} INFO - Requirement already satisfied: pytz<2024 in /home/***/.local/lib/python3.8/site-packages (from mlflow==2.10.2->-r /tmp/venv9718v237/requirements.txt (line 2)) (2023.3.post1)
[2024-04-24T23:43:48.280+0000] {process_utils.py:190} INFO - Requirement already satisfied: requests<3,>=2.17.3 in /home/***/.local/lib/python3.8/site-packages (from mlflow==2.10.2->-r /tmp/venv9718v237/requirements.txt (line 2)) (2.31.0)
[2024-04-24T23:43:48.280+0000] {process_utils.py:190} INFO - Requirement already satisfied: importlib-metadata!=4.7.0,<8,>=3.7.0 in /home/***/.local/lib/python3.8/site-packages (from mlflow==2.10.2->-r /tmp/venv9718v237/requirements.txt (line 2)) (6.11.0)
[2024-04-24T23:43:48.281+0000] {process_utils.py:190} INFO - Requirement already satisfied: sqlparse<1,>=0.4.0 in /home/***/.local/lib/python3.8/site-packages (from mlflow==2.10.2->-r /tmp/venv9718v237/requirements.txt (line 2)) (0.4.4)
[2024-04-24T23:43:48.281+0000] {process_utils.py:190} INFO - Requirement already satisfied: alembic!=1.10.0,<2 in /home/***/.local/lib/python3.8/site-packages (from mlflow==2.10.2->-r /tmp/venv9718v237/requirements.txt (line 2)) (1.13.1)
[2024-04-24T23:43:48.282+0000] {process_utils.py:190} INFO - Requirement already satisfied: docker<8,>=4.0.0 in /home/***/.local/lib/python3.8/site-packages (from mlflow==2.10.2->-r /tmp/venv9718v237/requirements.txt (line 2)) (7.0.0)
[2024-04-24T23:43:48.282+0000] {process_utils.py:190} INFO - Requirement already satisfied: Flask<4 in /home/***/.local/lib/python3.8/site-packages (from mlflow==2.10.2->-r /tmp/venv9718v237/requirements.txt (line 2)) (2.2.5)
[2024-04-24T23:43:48.283+0000] {process_utils.py:190} INFO - Requirement already satisfied: scipy<2 in /home/***/.local/lib/python3.8/site-packages (from mlflow==2.10.2->-r /tmp/venv9718v237/requirements.txt (line 2)) (1.10.1)
[2024-04-24T23:43:48.284+0000] {process_utils.py:190} INFO - Requirement already satisfied: querystring-parser<2 in /home/***/.local/lib/python3.8/site-packages (from mlflow==2.10.2->-r /tmp/venv9718v237/requirements.txt (line 2)) (1.2.4)
[2024-04-24T23:43:48.284+0000] {process_utils.py:190} INFO - Requirement already satisfied: sqlalchemy<3,>=1.4.0 in /home/***/.local/lib/python3.8/site-packages (from mlflow==2.10.2->-r /tmp/venv9718v237/requirements.txt (line 2)) (1.4.51)
[2024-04-24T23:43:48.285+0000] {process_utils.py:190} INFO - Requirement already satisfied: markdown<4,>=3.3 in /home/***/.local/lib/python3.8/site-packages (from mlflow==2.10.2->-r /tmp/venv9718v237/requirements.txt (line 2)) (3.5.2)
[2024-04-24T23:43:48.285+0000] {process_utils.py:190} INFO - Requirement already satisfied: matplotlib<4 in /home/***/.local/lib/python3.8/site-packages (from mlflow==2.10.2->-r /tmp/venv9718v237/requirements.txt (line 2)) (3.7.5)
[2024-04-24T23:43:48.286+0000] {process_utils.py:190} INFO - Requirement already satisfied: gunicorn<22 in /home/***/.local/lib/python3.8/site-packages (from mlflow==2.10.2->-r /tmp/venv9718v237/requirements.txt (line 2)) (21.2.0)
[2024-04-24T23:43:48.287+0000] {process_utils.py:190} INFO - Requirement already satisfied: Jinja2<4,>=2.11 in /home/***/.local/lib/python3.8/site-packages (from mlflow==2.10.2->-r /tmp/venv9718v237/requirements.txt (line 2)) (3.1.3)
[2024-04-24T23:43:48.309+0000] {process_utils.py:190} INFO - Requirement already satisfied: joblib>=1.1.1 in /home/***/.local/lib/python3.8/site-packages (from scikit-learn==1.3.2->-r /tmp/venv9718v237/requirements.txt (line 3)) (1.4.0)
[2024-04-24T23:43:48.309+0000] {process_utils.py:190} INFO - Requirement already satisfied: threadpoolctl>=2.0.0 in /home/***/.local/lib/python3.8/site-packages (from scikit-learn==1.3.2->-r /tmp/venv9718v237/requirements.txt (line 3)) (3.4.0)
[2024-04-24T23:43:48.314+0000] {process_utils.py:190} INFO - Requirement already satisfied: Mako in /home/***/.local/lib/python3.8/site-packages (from alembic!=1.10.0,<2->mlflow==2.10.2->-r /tmp/venv9718v237/requirements.txt (line 2)) (1.3.0)
[2024-04-24T23:43:48.315+0000] {process_utils.py:190} INFO - Requirement already satisfied: importlib-resources in /home/***/.local/lib/python3.8/site-packages (from alembic!=1.10.0,<2->mlflow==2.10.2->-r /tmp/venv9718v237/requirements.txt (line 2)) (5.13.0)
[2024-04-24T23:43:48.319+0000] {process_utils.py:190} INFO - Requirement already satisfied: jmespath<2.0.0,>=0.7.1 in /home/***/.local/lib/python3.8/site-packages (from boto3<2.0.0,>=1.20.32->awswrangler==3.6.0->-r /tmp/venv9718v237/requirements.txt (line 1)) (0.10.0)
[2024-04-24T23:43:48.320+0000] {process_utils.py:190} INFO - Requirement already satisfied: s3transfer<0.11.0,>=0.10.0 in /home/***/.local/lib/python3.8/site-packages (from boto3<2.0.0,>=1.20.32->awswrangler==3.6.0->-r /tmp/venv9718v237/requirements.txt (line 1)) (0.10.1)
[2024-04-24T23:43:48.326+0000] {process_utils.py:190} INFO - Requirement already satisfied: python-dateutil<3.0.0,>=2.1 in /home/***/.local/lib/python3.8/site-packages (from botocore<2.0.0,>=1.23.32->awswrangler==3.6.0->-r /tmp/venv9718v237/requirements.txt (line 1)) (2.8.2)
[2024-04-24T23:43:48.327+0000] {process_utils.py:190} INFO - Requirement already satisfied: urllib3<1.27,>=1.25.4 in /home/***/.local/lib/python3.8/site-packages (from botocore<2.0.0,>=1.23.32->awswrangler==3.6.0->-r /tmp/venv9718v237/requirements.txt (line 1)) (1.26.18)
[2024-04-24T23:43:48.344+0000] {process_utils.py:190} INFO - Requirement already satisfied: Werkzeug>=2.2.2 in /home/***/.local/lib/python3.8/site-packages (from Flask<4->mlflow==2.10.2->-r /tmp/venv9718v237/requirements.txt (line 2)) (2.2.3)
[2024-04-24T23:43:48.345+0000] {process_utils.py:190} INFO - Requirement already satisfied: itsdangerous>=2.0 in /home/***/.local/lib/python3.8/site-packages (from Flask<4->mlflow==2.10.2->-r /tmp/venv9718v237/requirements.txt (line 2)) (2.1.2)
[2024-04-24T23:43:48.361+0000] {process_utils.py:190} INFO - Requirement already satisfied: gitdb<5,>=4.0.1 in /home/***/.local/lib/python3.8/site-packages (from gitpython<4,>=2.1.0->mlflow==2.10.2->-r /tmp/venv9718v237/requirements.txt (line 2)) (4.0.11)
[2024-04-24T23:43:48.408+0000] {process_utils.py:190} INFO - Requirement already satisfied: zipp>=0.5 in /home/***/.local/lib/python3.8/site-packages (from importlib-metadata!=4.7.0,<8,>=3.7.0->mlflow==2.10.2->-r /tmp/venv9718v237/requirements.txt (line 2)) (3.17.0)
[2024-04-24T23:43:48.411+0000] {process_utils.py:190} INFO - Requirement already satisfied: MarkupSafe>=2.0 in /home/***/.local/lib/python3.8/site-packages (from Jinja2<4,>=2.11->mlflow==2.10.2->-r /tmp/venv9718v237/requirements.txt (line 2)) (2.1.3)
[2024-04-24T23:43:48.428+0000] {process_utils.py:190} INFO - Requirement already satisfied: contourpy>=1.0.1 in /home/***/.local/lib/python3.8/site-packages (from matplotlib<4->mlflow==2.10.2->-r /tmp/venv9718v237/requirements.txt (line 2)) (1.1.1)
[2024-04-24T23:43:48.429+0000] {process_utils.py:190} INFO - Requirement already satisfied: cycler>=0.10 in /home/***/.local/lib/python3.8/site-packages (from matplotlib<4->mlflow==2.10.2->-r /tmp/venv9718v237/requirements.txt (line 2)) (0.12.1)
[2024-04-24T23:43:48.430+0000] {process_utils.py:190} INFO - Requirement already satisfied: fonttools>=4.22.0 in /home/***/.local/lib/python3.8/site-packages (from matplotlib<4->mlflow==2.10.2->-r /tmp/venv9718v237/requirements.txt (line 2)) (4.51.0)
[2024-04-24T23:43:48.431+0000] {process_utils.py:190} INFO - Requirement already satisfied: kiwisolver>=1.0.1 in /home/***/.local/lib/python3.8/site-packages (from matplotlib<4->mlflow==2.10.2->-r /tmp/venv9718v237/requirements.txt (line 2)) (1.4.5)
[2024-04-24T23:43:48.432+0000] {process_utils.py:190} INFO - Requirement already satisfied: pillow>=6.2.0 in /home/***/.local/lib/python3.8/site-packages (from matplotlib<4->mlflow==2.10.2->-r /tmp/venv9718v237/requirements.txt (line 2)) (10.3.0)
[2024-04-24T23:43:48.433+0000] {process_utils.py:190} INFO - Requirement already satisfied: pyparsing>=2.3.1 in /home/***/.local/lib/python3.8/site-packages (from matplotlib<4->mlflow==2.10.2->-r /tmp/venv9718v237/requirements.txt (line 2)) (3.1.1)
[2024-04-24T23:43:48.516+0000] {process_utils.py:190} INFO - Requirement already satisfied: tzdata>=2022.1 in /home/***/.local/lib/python3.8/site-packages (from pandas<2.1.0,>=1.2.0->awswrangler==3.6.0->-r /tmp/venv9718v237/requirements.txt (line 1)) (2023.4)
[2024-04-24T23:43:48.530+0000] {process_utils.py:190} INFO - Requirement already satisfied: six in /home/***/.local/lib/python3.8/site-packages (from querystring-parser<2->mlflow==2.10.2->-r /tmp/venv9718v237/requirements.txt (line 2)) (1.16.0)
[2024-04-24T23:43:48.537+0000] {process_utils.py:190} INFO - Requirement already satisfied: charset-normalizer<4,>=2 in /home/***/.local/lib/python3.8/site-packages (from requests<3,>=2.17.3->mlflow==2.10.2->-r /tmp/venv9718v237/requirements.txt (line 2)) (3.3.2)
[2024-04-24T23:43:48.538+0000] {process_utils.py:190} INFO - Requirement already satisfied: idna<4,>=2.5 in /home/***/.local/lib/python3.8/site-packages (from requests<3,>=2.17.3->mlflow==2.10.2->-r /tmp/venv9718v237/requirements.txt (line 2)) (3.6)
[2024-04-24T23:43:48.538+0000] {process_utils.py:190} INFO - Requirement already satisfied: certifi>=2017.4.17 in /home/***/.local/lib/python3.8/site-packages (from requests<3,>=2.17.3->mlflow==2.10.2->-r /tmp/venv9718v237/requirements.txt (line 2)) (2023.11.17)
[2024-04-24T23:43:48.623+0000] {process_utils.py:190} INFO - Requirement already satisfied: greenlet!=0.4.17 in /home/***/.local/lib/python3.8/site-packages (from sqlalchemy<3,>=1.4.0->mlflow==2.10.2->-r /tmp/venv9718v237/requirements.txt (line 2)) (3.0.3)
[2024-04-24T23:43:48.740+0000] {process_utils.py:190} INFO - Requirement already satisfied: smmap<6,>=3.0.1 in /home/***/.local/lib/python3.8/site-packages (from gitdb<5,>=4.0.1->gitpython<4,>=2.1.0->mlflow==2.10.2->-r /tmp/venv9718v237/requirements.txt (line 2)) (5.0.1)
[2024-04-24T23:43:48.884+0000] {process_utils.py:190} INFO - Using cached awswrangler-3.6.0-py3-none-any.whl (403 kB)
[2024-04-24T23:43:48.982+0000] {process_utils.py:190} INFO - Downloading mlflow-2.10.2-py3-none-any.whl (19.5 MB)
[2024-04-24T23:43:55.403+0000] {process_utils.py:190} INFO -    ━━━━━━━━━━━━━━━━━━━━━━━━━━━━━━━━━━━━━━━━ 19.5/19.5 MB 4.7 MB/s eta 0:00:00
[2024-04-24T23:43:57.529+0000] {process_utils.py:190} INFO - Installing collected packages: mlflow, awswrangler
[2024-04-24T23:43:57.529+0000] {process_utils.py:190} INFO -   Attempting uninstall: mlflow
[2024-04-24T23:43:57.530+0000] {process_utils.py:190} INFO -     Found existing installation: mlflow 2.12.1
[2024-04-24T23:43:57.531+0000] {process_utils.py:190} INFO -     Not uninstalling mlflow at /home/***/.local/lib/python3.8/site-packages, outside environment /tmp/venv9718v237
[2024-04-24T23:43:57.531+0000] {process_utils.py:190} INFO -     Can't uninstall 'mlflow'. No files were found to uninstall.
[2024-04-24T23:43:58.438+0000] {process_utils.py:190} INFO - Successfully installed awswrangler-3.6.0 mlflow-2.10.2
[2024-04-24T23:43:58.659+0000] {process_utils.py:190} INFO - 
[2024-04-24T23:43:58.660+0000] {process_utils.py:190} INFO - [notice] A new release of pip is available: 23.3.1 -> 24.0
[2024-04-24T23:43:58.660+0000] {process_utils.py:190} INFO - [notice] To update, run: python -m pip install --upgrade pip
[2024-04-24T23:43:58.824+0000] {process_utils.py:182} INFO - Executing cmd: /tmp/venv9718v237/bin/python /tmp/venv-callwv7drmi_/script.py /tmp/venv-callwv7drmi_/script.in /tmp/venv-callwv7drmi_/script.out /tmp/venv-callwv7drmi_/string_args.txt /tmp/venv-callwv7drmi_/termination.log
[2024-04-24T23:43:58.832+0000] {process_utils.py:186} INFO - Output:
[2024-04-24T23:44:03.482+0000] {process_utils.py:190} INFO - [[34m2024-04-24T23:44:03.481+0000[0m] {[34mconnectionpool.py:[0m824} WARNING[0m - Retrying (JitteredRetry(total=4, connect=4, read=5, redirect=5, status=5)) after connection broken by 'NewConnectionError('<urllib3.connection.HTTPConnection object at 0x7f523e5a7ac0>: Failed to establish a new connection: [Errno 111] Connection refused')': /api/2.0/mlflow/registered-models/alias?name=mnist_784&alias=champion[0m
[2024-04-24T23:44:07.487+0000] {process_utils.py:190} INFO - [[34m2024-04-24T23:44:07.487+0000[0m] {[34mconnectionpool.py:[0m824} WARNING[0m - Retrying (JitteredRetry(total=3, connect=3, read=5, redirect=5, status=5)) after connection broken by 'NewConnectionError('<urllib3.connection.HTTPConnection object at 0x7f523e5a7a30>: Failed to establish a new connection: [Errno 111] Connection refused')': /api/2.0/mlflow/registered-models/alias?name=mnist_784&alias=champion[0m
[2024-04-24T23:44:15.497+0000] {process_utils.py:190} INFO - [[34m2024-04-24T23:44:15.496+0000[0m] {[34mconnectionpool.py:[0m824} WARNING[0m - Retrying (JitteredRetry(total=2, connect=2, read=5, redirect=5, status=5)) after connection broken by 'NewConnectionError('<urllib3.connection.HTTPConnection object at 0x7f523e5a7610>: Failed to establish a new connection: [Errno 111] Connection refused')': /api/2.0/mlflow/registered-models/alias?name=mnist_784&alias=champion[0m
[2024-04-24T23:44:31.530+0000] {process_utils.py:190} INFO - [[34m2024-04-24T23:44:31.529+0000[0m] {[34mconnectionpool.py:[0m824} WARNING[0m - Retrying (JitteredRetry(total=1, connect=1, read=5, redirect=5, status=5)) after connection broken by 'NewConnectionError('<urllib3.connection.HTTPConnection object at 0x7f523e60fc40>: Failed to establish a new connection: [Errno 111] Connection refused')': /api/2.0/mlflow/registered-models/alias?name=mnist_784&alias=champion[0m
[2024-04-24T23:45:03.521+0000] {process_utils.py:190} INFO - [[34m2024-04-24T23:45:03.521+0000[0m] {[34mconnectionpool.py:[0m824} WARNING[0m - Retrying (JitteredRetry(total=0, connect=0, read=5, redirect=5, status=5)) after connection broken by 'NewConnectionError('<urllib3.connection.HTTPConnection object at 0x7f523e60f100>: Failed to establish a new connection: [Errno 111] Connection refused')': /api/2.0/mlflow/registered-models/alias?name=mnist_784&alias=champion[0m
[2024-04-24T23:45:03.524+0000] {process_utils.py:190} INFO - Traceback (most recent call last):
[2024-04-24T23:45:03.525+0000] {process_utils.py:190} INFO -   File "/home/***/.local/lib/python3.8/site-packages/urllib3/connection.py", line 174, in _new_conn
[2024-04-24T23:45:03.525+0000] {process_utils.py:190} INFO -     conn = connection.create_connection(
[2024-04-24T23:45:03.525+0000] {process_utils.py:190} INFO -   File "/home/***/.local/lib/python3.8/site-packages/urllib3/util/connection.py", line 95, in create_connection
[2024-04-24T23:45:03.526+0000] {process_utils.py:190} INFO -     raise err
[2024-04-24T23:45:03.526+0000] {process_utils.py:190} INFO -   File "/home/***/.local/lib/python3.8/site-packages/urllib3/util/connection.py", line 85, in create_connection
[2024-04-24T23:45:03.526+0000] {process_utils.py:190} INFO -     sock.connect(sa)
[2024-04-24T23:45:03.526+0000] {process_utils.py:190} INFO - ConnectionRefusedError: [Errno 111] Connection refused
[2024-04-24T23:45:03.527+0000] {process_utils.py:190} INFO - 
[2024-04-24T23:45:03.527+0000] {process_utils.py:190} INFO - During handling of the above exception, another exception occurred:
[2024-04-24T23:45:03.527+0000] {process_utils.py:190} INFO - 
[2024-04-24T23:45:03.527+0000] {process_utils.py:190} INFO - Traceback (most recent call last):
[2024-04-24T23:45:03.528+0000] {process_utils.py:190} INFO -   File "/home/***/.local/lib/python3.8/site-packages/urllib3/connectionpool.py", line 715, in urlopen
[2024-04-24T23:45:03.528+0000] {process_utils.py:190} INFO -     httplib_response = self._make_request(
[2024-04-24T23:45:03.528+0000] {process_utils.py:190} INFO -   File "/home/***/.local/lib/python3.8/site-packages/urllib3/connectionpool.py", line 416, in _make_request
[2024-04-24T23:45:03.529+0000] {process_utils.py:190} INFO -     conn.request(method, url, **httplib_request_kw)
[2024-04-24T23:45:03.529+0000] {process_utils.py:190} INFO -   File "/home/***/.local/lib/python3.8/site-packages/urllib3/connection.py", line 244, in request
[2024-04-24T23:45:03.529+0000] {process_utils.py:190} INFO -     super(HTTPConnection, self).request(method, url, body=body, headers=headers)
[2024-04-24T23:45:03.529+0000] {process_utils.py:190} INFO -   File "/usr/local/lib/python3.8/http/client.py", line 1256, in request
[2024-04-24T23:45:03.530+0000] {process_utils.py:190} INFO -     self._send_request(method, url, body, headers, encode_chunked)
[2024-04-24T23:45:03.530+0000] {process_utils.py:190} INFO -   File "/usr/local/lib/python3.8/http/client.py", line 1302, in _send_request
[2024-04-24T23:45:03.530+0000] {process_utils.py:190} INFO -     self.endheaders(body, encode_chunked=encode_chunked)
[2024-04-24T23:45:03.530+0000] {process_utils.py:190} INFO -   File "/usr/local/lib/python3.8/http/client.py", line 1251, in endheaders
[2024-04-24T23:45:03.531+0000] {process_utils.py:190} INFO -     self._send_output(message_body, encode_chunked=encode_chunked)
[2024-04-24T23:45:03.531+0000] {process_utils.py:190} INFO -   File "/usr/local/lib/python3.8/http/client.py", line 1011, in _send_output
[2024-04-24T23:45:03.531+0000] {process_utils.py:190} INFO -     self.send(msg)
[2024-04-24T23:45:03.531+0000] {process_utils.py:190} INFO -   File "/usr/local/lib/python3.8/http/client.py", line 951, in send
[2024-04-24T23:45:03.532+0000] {process_utils.py:190} INFO -     self.connect()
[2024-04-24T23:45:03.532+0000] {process_utils.py:190} INFO -   File "/home/***/.local/lib/python3.8/site-packages/urllib3/connection.py", line 205, in connect
[2024-04-24T23:45:03.532+0000] {process_utils.py:190} INFO -     conn = self._new_conn()
[2024-04-24T23:45:03.533+0000] {process_utils.py:190} INFO -   File "/home/***/.local/lib/python3.8/site-packages/urllib3/connection.py", line 186, in _new_conn
[2024-04-24T23:45:03.533+0000] {process_utils.py:190} INFO -     raise NewConnectionError(
[2024-04-24T23:45:03.533+0000] {process_utils.py:190} INFO - urllib3.exceptions.NewConnectionError: <urllib3.connection.HTTPConnection object at 0x7f523e60fca0>: Failed to establish a new connection: [Errno 111] Connection refused
[2024-04-24T23:45:03.533+0000] {process_utils.py:190} INFO - 
[2024-04-24T23:45:03.534+0000] {process_utils.py:190} INFO - During handling of the above exception, another exception occurred:
[2024-04-24T23:45:03.534+0000] {process_utils.py:190} INFO - 
[2024-04-24T23:45:03.534+0000] {process_utils.py:190} INFO - Traceback (most recent call last):
[2024-04-24T23:45:03.534+0000] {process_utils.py:190} INFO -   File "/home/***/.local/lib/python3.8/site-packages/requests/adapters.py", line 486, in send
[2024-04-24T23:45:03.535+0000] {process_utils.py:190} INFO -     resp = conn.urlopen(
[2024-04-24T23:45:03.535+0000] {process_utils.py:190} INFO -   File "/home/***/.local/lib/python3.8/site-packages/urllib3/connectionpool.py", line 827, in urlopen
[2024-04-24T23:45:03.535+0000] {process_utils.py:190} INFO -     return self.urlopen(
[2024-04-24T23:45:03.536+0000] {process_utils.py:190} INFO -   File "/home/***/.local/lib/python3.8/site-packages/urllib3/connectionpool.py", line 827, in urlopen
[2024-04-24T23:45:03.536+0000] {process_utils.py:190} INFO -     return self.urlopen(
[2024-04-24T23:45:03.536+0000] {process_utils.py:190} INFO -   File "/home/***/.local/lib/python3.8/site-packages/urllib3/connectionpool.py", line 827, in urlopen
[2024-04-24T23:45:03.537+0000] {process_utils.py:190} INFO -     return self.urlopen(
[2024-04-24T23:45:03.537+0000] {process_utils.py:190} INFO -   [Previous line repeated 2 more times]
[2024-04-24T23:45:03.537+0000] {process_utils.py:190} INFO -   File "/home/***/.local/lib/python3.8/site-packages/urllib3/connectionpool.py", line 799, in urlopen
[2024-04-24T23:45:03.538+0000] {process_utils.py:190} INFO -     retries = retries.increment(
[2024-04-24T23:45:03.538+0000] {process_utils.py:190} INFO -   File "/home/***/.local/lib/python3.8/site-packages/urllib3/util/retry.py", line 592, in increment
[2024-04-24T23:45:03.538+0000] {process_utils.py:190} INFO -     raise MaxRetryError(_pool, url, error or ResponseError(cause))
[2024-04-24T23:45:03.538+0000] {process_utils.py:190} INFO - urllib3.exceptions.MaxRetryError: HTTPConnectionPool(host='mlflow', port=5000): Max retries exceeded with url: /api/2.0/mlflow/registered-models/alias?name=mnist_784&alias=champion (Caused by NewConnectionError('<urllib3.connection.HTTPConnection object at 0x7f523e60fca0>: Failed to establish a new connection: [Errno 111] Connection refused'))
[2024-04-24T23:45:03.539+0000] {process_utils.py:190} INFO - 
[2024-04-24T23:45:03.539+0000] {process_utils.py:190} INFO - During handling of the above exception, another exception occurred:
[2024-04-24T23:45:03.539+0000] {process_utils.py:190} INFO - 
[2024-04-24T23:45:03.539+0000] {process_utils.py:190} INFO - Traceback (most recent call last):
[2024-04-24T23:45:03.540+0000] {process_utils.py:190} INFO -   File "/tmp/venv9718v237/lib/python3.8/site-packages/mlflow/utils/rest_utils.py", line 108, in http_request
[2024-04-24T23:45:03.540+0000] {process_utils.py:190} INFO -     return _get_http_response_with_retries(
[2024-04-24T23:45:03.540+0000] {process_utils.py:190} INFO -   File "/tmp/venv9718v237/lib/python3.8/site-packages/mlflow/utils/request_utils.py", line 212, in _get_http_response_with_retries
[2024-04-24T23:45:03.540+0000] {process_utils.py:190} INFO -     return session.request(method, url, allow_redirects=allow_redirects, **kwargs)
[2024-04-24T23:45:03.540+0000] {process_utils.py:190} INFO -   File "/home/***/.local/lib/python3.8/site-packages/requests/sessions.py", line 589, in request
[2024-04-24T23:45:03.541+0000] {process_utils.py:190} INFO -     resp = self.send(prep, **send_kwargs)
[2024-04-24T23:45:03.541+0000] {process_utils.py:190} INFO -   File "/home/***/.local/lib/python3.8/site-packages/requests/sessions.py", line 703, in send
[2024-04-24T23:45:03.541+0000] {process_utils.py:190} INFO -     r = adapter.send(request, **kwargs)
[2024-04-24T23:45:03.541+0000] {process_utils.py:190} INFO -   File "/home/***/.local/lib/python3.8/site-packages/requests/adapters.py", line 519, in send
[2024-04-24T23:45:03.542+0000] {process_utils.py:190} INFO -     raise ConnectionError(e, request=request)
[2024-04-24T23:45:03.542+0000] {process_utils.py:190} INFO - requests.exceptions.ConnectionError: HTTPConnectionPool(host='mlflow', port=5000): Max retries exceeded with url: /api/2.0/mlflow/registered-models/alias?name=mnist_784&alias=champion (Caused by NewConnectionError('<urllib3.connection.HTTPConnection object at 0x7f523e60fca0>: Failed to establish a new connection: [Errno 111] Connection refused'))
[2024-04-24T23:45:03.542+0000] {process_utils.py:190} INFO - 
[2024-04-24T23:45:03.542+0000] {process_utils.py:190} INFO - During handling of the above exception, another exception occurred:
[2024-04-24T23:45:03.542+0000] {process_utils.py:190} INFO - 
[2024-04-24T23:45:03.543+0000] {process_utils.py:190} INFO - Traceback (most recent call last):
[2024-04-24T23:45:03.543+0000] {process_utils.py:190} INFO -   File "/tmp/venv-callwv7drmi_/script.py", line 132, in <module>
[2024-04-24T23:45:03.543+0000] {process_utils.py:190} INFO -     res = train_the_challenger_model(*arg_dict["args"], **arg_dict["kwargs"])
[2024-04-24T23:45:03.543+0000] {process_utils.py:190} INFO -   File "/tmp/venv-callwv7drmi_/script.py", line 110, in train_the_challenger_model
[2024-04-24T23:45:03.544+0000] {process_utils.py:190} INFO -     champion_model = load_the_champion_model()
[2024-04-24T23:45:03.544+0000] {process_utils.py:190} INFO -   File "/tmp/venv-callwv7drmi_/script.py", line 42, in load_the_champion_model
[2024-04-24T23:45:03.544+0000] {process_utils.py:190} INFO -     model_data = client.get_model_version_by_alias(model_name, alias)
[2024-04-24T23:45:03.544+0000] {process_utils.py:190} INFO -   File "/tmp/venv9718v237/lib/python3.8/site-packages/mlflow/tracking/client.py", line 3745, in get_model_version_by_alias
[2024-04-24T23:45:03.545+0000] {process_utils.py:190} INFO -     return self._get_registry_client().get_model_version_by_alias(name, alias)
[2024-04-24T23:45:03.545+0000] {process_utils.py:190} INFO -   File "/tmp/venv9718v237/lib/python3.8/site-packages/mlflow/tracking/_model_registry/client.py", line 366, in get_model_version_by_alias
[2024-04-24T23:45:03.545+0000] {process_utils.py:190} INFO -     return self.store.get_model_version_by_alias(name, alias)
[2024-04-24T23:45:03.545+0000] {process_utils.py:190} INFO -   File "/tmp/venv9718v237/lib/python3.8/site-packages/mlflow/store/model_registry/rest_store.py", line 400, in get_model_version_by_alias
[2024-04-24T23:45:03.546+0000] {process_utils.py:190} INFO -     response_proto = self._call_endpoint(GetModelVersionByAlias, req_body)
[2024-04-24T23:45:03.546+0000] {process_utils.py:190} INFO -   File "/tmp/venv9718v237/lib/python3.8/site-packages/mlflow/store/model_registry/base_rest_store.py", line 44, in _call_endpoint
[2024-04-24T23:45:03.546+0000] {process_utils.py:190} INFO -     return call_endpoint(
[2024-04-24T23:45:03.546+0000] {process_utils.py:190} INFO -   File "/tmp/venv9718v237/lib/python3.8/site-packages/mlflow/utils/rest_utils.py", line 216, in call_endpoint
[2024-04-24T23:45:03.546+0000] {process_utils.py:190} INFO -     response = http_request(**call_kwargs)
[2024-04-24T23:45:03.547+0000] {process_utils.py:190} INFO -   File "/tmp/venv9718v237/lib/python3.8/site-packages/mlflow/utils/rest_utils.py", line 130, in http_request
[2024-04-24T23:45:03.547+0000] {process_utils.py:190} INFO -     raise MlflowException(f"API request to {url} failed with exception {e}")
[2024-04-24T23:45:03.547+0000] {process_utils.py:190} INFO - mlflow.exceptions.MlflowException: API request to http://mlflow:5000/api/2.0/mlflow/registered-models/alias failed with exception HTTPConnectionPool(host='mlflow', port=5000): Max retries exceeded with url: /api/2.0/mlflow/registered-models/alias?name=mnist_784&alias=champion (Caused by NewConnectionError('<urllib3.connection.HTTPConnection object at 0x7f523e60fca0>: Failed to establish a new connection: [Errno 111] Connection refused'))
[2024-04-24T23:45:03.850+0000] {taskinstance.py:2698} ERROR - Task failed with exception
Traceback (most recent call last):
  File "/home/airflow/.local/lib/python3.8/site-packages/airflow/models/taskinstance.py", line 433, in _execute_task
    result = execute_callable(context=context, **execute_callable_kwargs)
  File "/home/airflow/.local/lib/python3.8/site-packages/airflow/decorators/base.py", line 241, in execute
    return_value = super().execute(context)
  File "/home/airflow/.local/lib/python3.8/site-packages/airflow/operators/python.py", line 400, in execute
    return super().execute(context=serializable_context)
  File "/home/airflow/.local/lib/python3.8/site-packages/airflow/operators/python.py", line 199, in execute
    return_value = self.execute_callable()
  File "/home/airflow/.local/lib/python3.8/site-packages/airflow/operators/python.py", line 716, in execute_callable
    result = self._execute_python_callable_in_subprocess(python_path)
  File "/home/airflow/.local/lib/python3.8/site-packages/airflow/operators/python.py", line 471, in _execute_python_callable_in_subprocess
    raise AirflowException(error_msg) from None
airflow.exceptions.AirflowException: Process returned non-zero exit status 1.
API request to http://mlflow:5000/api/2.0/mlflow/registered-models/alias failed with exception HTTPConnectionPool(host='mlflow', port=5000): Max retries exceeded with url: /api/2.0/mlflow/registered-models/alias?name=mnist_784&alias=champion (Caused by NewConnectionError('<urllib3.connection.HTTPConnection object at 0x7f523e60fca0>: Failed to establish a new connection: [Errno 111] Connection refused'))
[2024-04-24T23:45:03.853+0000] {taskinstance.py:1138} INFO - Marking task as UP_FOR_RETRY. dag_id=retrain_the_model_mnist_784, task_id=train_the_challenger_model, execution_date=20240423T000000, start_date=20240424T234346, end_date=20240424T234503
[2024-04-24T23:45:03.862+0000] {standard_task_runner.py:107} ERROR - Failed to execute job 37 for task train_the_challenger_model (Process returned non-zero exit status 1.
API request to http://mlflow:5000/api/2.0/mlflow/registered-models/alias failed with exception HTTPConnectionPool(host='mlflow', port=5000): Max retries exceeded with url: /api/2.0/mlflow/registered-models/alias?name=mnist_784&alias=champion (Caused by NewConnectionError('<urllib3.connection.HTTPConnection object at 0x7f523e60fca0>: Failed to establish a new connection: [Errno 111] Connection refused')); 13410)
[2024-04-24T23:45:03.869+0000] {local_task_job_runner.py:234} INFO - Task exited with return code 1
[2024-04-24T23:45:03.884+0000] {taskinstance.py:3280} INFO - 0 downstream tasks scheduled from follow-on schedule check
