[2024-04-21T22:57:30.118+0000] {taskinstance.py:1956} INFO - Dependencies all met for dep_context=non-requeueable deps ti=<TaskInstance: process_etl_heart_data.normalize_numerical_features scheduled__2024-04-20T00:00:00+00:00 [queued]>
[2024-04-21T22:57:30.123+0000] {taskinstance.py:1956} INFO - Dependencies all met for dep_context=requeueable deps ti=<TaskInstance: process_etl_heart_data.normalize_numerical_features scheduled__2024-04-20T00:00:00+00:00 [queued]>
[2024-04-21T22:57:30.124+0000] {taskinstance.py:2170} INFO - Starting attempt 1 of 2
[2024-04-21T22:57:30.132+0000] {taskinstance.py:2191} INFO - Executing <Task(_PythonVirtualenvDecoratedOperator): normalize_numerical_features> on 2024-04-20 00:00:00+00:00
[2024-04-21T22:57:30.136+0000] {standard_task_runner.py:60} INFO - Started process 17539 to run task
[2024-04-21T22:57:30.139+0000] {standard_task_runner.py:87} INFO - Running: ['***', 'tasks', 'run', 'process_etl_heart_data', 'normalize_numerical_features', 'scheduled__2024-04-20T00:00:00+00:00', '--job-id', '9', '--raw', '--subdir', 'DAGS_FOLDER/etl_process.py', '--cfg-path', '/tmp/tmp2m2inlej']
[2024-04-21T22:57:30.140+0000] {standard_task_runner.py:88} INFO - Job 9: Subtask normalize_numerical_features
[2024-04-21T22:57:30.169+0000] {task_command.py:423} INFO - Running <TaskInstance: process_etl_heart_data.normalize_numerical_features scheduled__2024-04-20T00:00:00+00:00 [running]> on host 2e52d55d127b
[2024-04-21T22:57:30.214+0000] {taskinstance.py:2480} INFO - Exporting env vars: AIRFLOW_CTX_DAG_OWNER='Facundo Adrian Lucianna' AIRFLOW_CTX_DAG_ID='process_etl_heart_data' AIRFLOW_CTX_TASK_ID='normalize_numerical_features' AIRFLOW_CTX_EXECUTION_DATE='2024-04-20T00:00:00+00:00' AIRFLOW_CTX_TRY_NUMBER='1' AIRFLOW_CTX_DAG_RUN_ID='scheduled__2024-04-20T00:00:00+00:00'
[2024-04-21T22:57:30.215+0000] {process_utils.py:182} INFO - Executing cmd: /usr/local/bin/python -m virtualenv /tmp/venvky9ptz1y --system-site-packages --python=python
[2024-04-21T22:57:30.221+0000] {process_utils.py:186} INFO - Output:
[2024-04-21T22:57:30.680+0000] {process_utils.py:190} INFO - created virtual environment CPython3.8.18.final.0-64 in 167ms
[2024-04-21T22:57:30.680+0000] {process_utils.py:190} INFO -   creator CPython3Posix(dest=/tmp/venvky9ptz1y, clear=False, no_vcs_ignore=False, global=True)
[2024-04-21T22:57:30.681+0000] {process_utils.py:190} INFO -   seeder FromAppData(download=False, pip=bundle, setuptools=bundle, wheel=bundle, via=copy, app_data_dir=/home/***/.local/share/virtualenv)
[2024-04-21T22:57:30.681+0000] {process_utils.py:190} INFO -     added seed packages: pip==23.3.1, setuptools==69.0.2, wheel==0.42.0
[2024-04-21T22:57:30.681+0000] {process_utils.py:190} INFO -   activators BashActivator,CShellActivator,FishActivator,NushellActivator,PowerShellActivator,PythonActivator
[2024-04-21T22:57:30.710+0000] {process_utils.py:182} INFO - Executing cmd: /tmp/venvky9ptz1y/bin/pip install -r /tmp/venvky9ptz1y/requirements.txt
[2024-04-21T22:57:30.715+0000] {process_utils.py:186} INFO - Output:
[2024-04-21T22:57:31.528+0000] {process_utils.py:190} INFO - Collecting awswrangler==3.6.0 (from -r /tmp/venvky9ptz1y/requirements.txt (line 1))
[2024-04-21T22:57:31.529+0000] {process_utils.py:190} INFO -   Using cached awswrangler-3.6.0-py3-none-any.whl.metadata (23 kB)
[2024-04-21T22:57:31.733+0000] {process_utils.py:190} INFO - Collecting mlflow==2.10.2 (from -r /tmp/venvky9ptz1y/requirements.txt (line 2))
[2024-04-21T22:57:31.842+0000] {process_utils.py:190} INFO -   Downloading mlflow-2.10.2-py3-none-any.whl.metadata (13 kB)
[2024-04-21T22:57:31.850+0000] {process_utils.py:190} INFO - Requirement already satisfied: scikit-learn==1.3.2 in /home/***/.local/lib/python3.8/site-packages (from -r /tmp/venvky9ptz1y/requirements.txt (line 3)) (1.3.2)
[2024-04-21T22:57:31.881+0000] {process_utils.py:190} INFO - Requirement already satisfied: boto3<2.0.0,>=1.20.32 in /home/***/.local/lib/python3.8/site-packages (from awswrangler==3.6.0->-r /tmp/venvky9ptz1y/requirements.txt (line 1)) (1.34.88)
[2024-04-21T22:57:31.881+0000] {process_utils.py:190} INFO - Requirement already satisfied: botocore<2.0.0,>=1.23.32 in /home/***/.local/lib/python3.8/site-packages (from awswrangler==3.6.0->-r /tmp/venvky9ptz1y/requirements.txt (line 1)) (1.34.88)
[2024-04-21T22:57:31.882+0000] {process_utils.py:190} INFO - Requirement already satisfied: numpy<2.0,>=1.18 in /home/***/.local/lib/python3.8/site-packages (from awswrangler==3.6.0->-r /tmp/venvky9ptz1y/requirements.txt (line 1)) (1.24.4)
[2024-04-21T22:57:31.883+0000] {process_utils.py:190} INFO - Requirement already satisfied: packaging<24.0,>=21.1 in /home/***/.local/lib/python3.8/site-packages (from awswrangler==3.6.0->-r /tmp/venvky9ptz1y/requirements.txt (line 1)) (23.2)
[2024-04-21T22:57:31.883+0000] {process_utils.py:190} INFO - Requirement already satisfied: pandas<2.1.0,>=1.2.0 in /home/***/.local/lib/python3.8/site-packages (from awswrangler==3.6.0->-r /tmp/venvky9ptz1y/requirements.txt (line 1)) (2.0.3)
[2024-04-21T22:57:31.884+0000] {process_utils.py:190} INFO - Requirement already satisfied: pyarrow>=7.0.0 in /home/***/.local/lib/python3.8/site-packages (from awswrangler==3.6.0->-r /tmp/venvky9ptz1y/requirements.txt (line 1)) (14.0.2)
[2024-04-21T22:57:31.885+0000] {process_utils.py:190} INFO - Requirement already satisfied: typing-extensions<5.0.0,>=4.4.0 in /home/***/.local/lib/python3.8/site-packages (from awswrangler==3.6.0->-r /tmp/venvky9ptz1y/requirements.txt (line 1)) (4.9.0)
[2024-04-21T22:57:31.936+0000] {process_utils.py:190} INFO - Requirement already satisfied: click<9,>=7.0 in /home/***/.local/lib/python3.8/site-packages (from mlflow==2.10.2->-r /tmp/venvky9ptz1y/requirements.txt (line 2)) (8.1.7)
[2024-04-21T22:57:31.936+0000] {process_utils.py:190} INFO - Requirement already satisfied: cloudpickle<4 in /home/***/.local/lib/python3.8/site-packages (from mlflow==2.10.2->-r /tmp/venvky9ptz1y/requirements.txt (line 2)) (3.0.0)
[2024-04-21T22:57:31.937+0000] {process_utils.py:190} INFO - Requirement already satisfied: entrypoints<1 in /home/***/.local/lib/python3.8/site-packages (from mlflow==2.10.2->-r /tmp/venvky9ptz1y/requirements.txt (line 2)) (0.4)
[2024-04-21T22:57:31.937+0000] {process_utils.py:190} INFO - Requirement already satisfied: gitpython<4,>=2.1.0 in /home/***/.local/lib/python3.8/site-packages (from mlflow==2.10.2->-r /tmp/venvky9ptz1y/requirements.txt (line 2)) (3.1.43)
[2024-04-21T22:57:31.938+0000] {process_utils.py:190} INFO - Requirement already satisfied: pyyaml<7,>=5.1 in /home/***/.local/lib/python3.8/site-packages (from mlflow==2.10.2->-r /tmp/venvky9ptz1y/requirements.txt (line 2)) (6.0.1)
[2024-04-21T22:57:31.938+0000] {process_utils.py:190} INFO - Requirement already satisfied: protobuf<5,>=3.12.0 in /home/***/.local/lib/python3.8/site-packages (from mlflow==2.10.2->-r /tmp/venvky9ptz1y/requirements.txt (line 2)) (4.25.2)
[2024-04-21T22:57:31.939+0000] {process_utils.py:190} INFO - Requirement already satisfied: pytz<2024 in /home/***/.local/lib/python3.8/site-packages (from mlflow==2.10.2->-r /tmp/venvky9ptz1y/requirements.txt (line 2)) (2023.3.post1)
[2024-04-21T22:57:31.939+0000] {process_utils.py:190} INFO - Requirement already satisfied: requests<3,>=2.17.3 in /home/***/.local/lib/python3.8/site-packages (from mlflow==2.10.2->-r /tmp/venvky9ptz1y/requirements.txt (line 2)) (2.31.0)
[2024-04-21T22:57:31.940+0000] {process_utils.py:190} INFO - Requirement already satisfied: importlib-metadata!=4.7.0,<8,>=3.7.0 in /home/***/.local/lib/python3.8/site-packages (from mlflow==2.10.2->-r /tmp/venvky9ptz1y/requirements.txt (line 2)) (6.11.0)
[2024-04-21T22:57:31.940+0000] {process_utils.py:190} INFO - Requirement already satisfied: sqlparse<1,>=0.4.0 in /home/***/.local/lib/python3.8/site-packages (from mlflow==2.10.2->-r /tmp/venvky9ptz1y/requirements.txt (line 2)) (0.4.4)
[2024-04-21T22:57:31.941+0000] {process_utils.py:190} INFO - Requirement already satisfied: alembic!=1.10.0,<2 in /home/***/.local/lib/python3.8/site-packages (from mlflow==2.10.2->-r /tmp/venvky9ptz1y/requirements.txt (line 2)) (1.13.1)
[2024-04-21T22:57:31.941+0000] {process_utils.py:190} INFO - Requirement already satisfied: docker<8,>=4.0.0 in /home/***/.local/lib/python3.8/site-packages (from mlflow==2.10.2->-r /tmp/venvky9ptz1y/requirements.txt (line 2)) (7.0.0)
[2024-04-21T22:57:31.942+0000] {process_utils.py:190} INFO - Requirement already satisfied: Flask<4 in /home/***/.local/lib/python3.8/site-packages (from mlflow==2.10.2->-r /tmp/venvky9ptz1y/requirements.txt (line 2)) (2.2.5)
[2024-04-21T22:57:31.942+0000] {process_utils.py:190} INFO - Requirement already satisfied: scipy<2 in /home/***/.local/lib/python3.8/site-packages (from mlflow==2.10.2->-r /tmp/venvky9ptz1y/requirements.txt (line 2)) (1.10.1)
[2024-04-21T22:57:31.943+0000] {process_utils.py:190} INFO - Requirement already satisfied: querystring-parser<2 in /home/***/.local/lib/python3.8/site-packages (from mlflow==2.10.2->-r /tmp/venvky9ptz1y/requirements.txt (line 2)) (1.2.4)
[2024-04-21T22:57:31.943+0000] {process_utils.py:190} INFO - Requirement already satisfied: sqlalchemy<3,>=1.4.0 in /home/***/.local/lib/python3.8/site-packages (from mlflow==2.10.2->-r /tmp/venvky9ptz1y/requirements.txt (line 2)) (1.4.51)
[2024-04-21T22:57:31.944+0000] {process_utils.py:190} INFO - Requirement already satisfied: markdown<4,>=3.3 in /home/***/.local/lib/python3.8/site-packages (from mlflow==2.10.2->-r /tmp/venvky9ptz1y/requirements.txt (line 2)) (3.5.2)
[2024-04-21T22:57:31.944+0000] {process_utils.py:190} INFO - Requirement already satisfied: matplotlib<4 in /home/***/.local/lib/python3.8/site-packages (from mlflow==2.10.2->-r /tmp/venvky9ptz1y/requirements.txt (line 2)) (3.7.5)
[2024-04-21T22:57:31.945+0000] {process_utils.py:190} INFO - Requirement already satisfied: gunicorn<22 in /home/***/.local/lib/python3.8/site-packages (from mlflow==2.10.2->-r /tmp/venvky9ptz1y/requirements.txt (line 2)) (21.2.0)
[2024-04-21T22:57:31.946+0000] {process_utils.py:190} INFO - Requirement already satisfied: Jinja2<4,>=2.11 in /home/***/.local/lib/python3.8/site-packages (from mlflow==2.10.2->-r /tmp/venvky9ptz1y/requirements.txt (line 2)) (3.1.3)
[2024-04-21T22:57:31.975+0000] {process_utils.py:190} INFO - Requirement already satisfied: joblib>=1.1.1 in /home/***/.local/lib/python3.8/site-packages (from scikit-learn==1.3.2->-r /tmp/venvky9ptz1y/requirements.txt (line 3)) (1.4.0)
[2024-04-21T22:57:31.975+0000] {process_utils.py:190} INFO - Requirement already satisfied: threadpoolctl>=2.0.0 in /home/***/.local/lib/python3.8/site-packages (from scikit-learn==1.3.2->-r /tmp/venvky9ptz1y/requirements.txt (line 3)) (3.4.0)
[2024-04-21T22:57:31.981+0000] {process_utils.py:190} INFO - Requirement already satisfied: Mako in /home/***/.local/lib/python3.8/site-packages (from alembic!=1.10.0,<2->mlflow==2.10.2->-r /tmp/venvky9ptz1y/requirements.txt (line 2)) (1.3.0)
[2024-04-21T22:57:31.982+0000] {process_utils.py:190} INFO - Requirement already satisfied: importlib-resources in /home/***/.local/lib/python3.8/site-packages (from alembic!=1.10.0,<2->mlflow==2.10.2->-r /tmp/venvky9ptz1y/requirements.txt (line 2)) (5.13.0)
[2024-04-21T22:57:31.986+0000] {process_utils.py:190} INFO - Requirement already satisfied: jmespath<2.0.0,>=0.7.1 in /home/***/.local/lib/python3.8/site-packages (from boto3<2.0.0,>=1.20.32->awswrangler==3.6.0->-r /tmp/venvky9ptz1y/requirements.txt (line 1)) (0.10.0)
[2024-04-21T22:57:31.987+0000] {process_utils.py:190} INFO - Requirement already satisfied: s3transfer<0.11.0,>=0.10.0 in /home/***/.local/lib/python3.8/site-packages (from boto3<2.0.0,>=1.20.32->awswrangler==3.6.0->-r /tmp/venvky9ptz1y/requirements.txt (line 1)) (0.10.1)
[2024-04-21T22:57:31.992+0000] {process_utils.py:190} INFO - Requirement already satisfied: python-dateutil<3.0.0,>=2.1 in /home/***/.local/lib/python3.8/site-packages (from botocore<2.0.0,>=1.23.32->awswrangler==3.6.0->-r /tmp/venvky9ptz1y/requirements.txt (line 1)) (2.8.2)
[2024-04-21T22:57:31.993+0000] {process_utils.py:190} INFO - Requirement already satisfied: urllib3<1.27,>=1.25.4 in /home/***/.local/lib/python3.8/site-packages (from botocore<2.0.0,>=1.23.32->awswrangler==3.6.0->-r /tmp/venvky9ptz1y/requirements.txt (line 1)) (1.26.18)
[2024-04-21T22:57:32.007+0000] {process_utils.py:190} INFO - Requirement already satisfied: Werkzeug>=2.2.2 in /home/***/.local/lib/python3.8/site-packages (from Flask<4->mlflow==2.10.2->-r /tmp/venvky9ptz1y/requirements.txt (line 2)) (2.2.3)
[2024-04-21T22:57:32.007+0000] {process_utils.py:190} INFO - Requirement already satisfied: itsdangerous>=2.0 in /home/***/.local/lib/python3.8/site-packages (from Flask<4->mlflow==2.10.2->-r /tmp/venvky9ptz1y/requirements.txt (line 2)) (2.1.2)
[2024-04-21T22:57:32.021+0000] {process_utils.py:190} INFO - Requirement already satisfied: gitdb<5,>=4.0.1 in /home/***/.local/lib/python3.8/site-packages (from gitpython<4,>=2.1.0->mlflow==2.10.2->-r /tmp/venvky9ptz1y/requirements.txt (line 2)) (4.0.11)
[2024-04-21T22:57:32.054+0000] {process_utils.py:190} INFO - Requirement already satisfied: zipp>=0.5 in /home/***/.local/lib/python3.8/site-packages (from importlib-metadata!=4.7.0,<8,>=3.7.0->mlflow==2.10.2->-r /tmp/venvky9ptz1y/requirements.txt (line 2)) (3.17.0)
[2024-04-21T22:57:32.057+0000] {process_utils.py:190} INFO - Requirement already satisfied: MarkupSafe>=2.0 in /home/***/.local/lib/python3.8/site-packages (from Jinja2<4,>=2.11->mlflow==2.10.2->-r /tmp/venvky9ptz1y/requirements.txt (line 2)) (2.1.3)
[2024-04-21T22:57:32.073+0000] {process_utils.py:190} INFO - Requirement already satisfied: contourpy>=1.0.1 in /home/***/.local/lib/python3.8/site-packages (from matplotlib<4->mlflow==2.10.2->-r /tmp/venvky9ptz1y/requirements.txt (line 2)) (1.1.1)
[2024-04-21T22:57:32.074+0000] {process_utils.py:190} INFO - Requirement already satisfied: cycler>=0.10 in /home/***/.local/lib/python3.8/site-packages (from matplotlib<4->mlflow==2.10.2->-r /tmp/venvky9ptz1y/requirements.txt (line 2)) (0.12.1)
[2024-04-21T22:57:32.074+0000] {process_utils.py:190} INFO - Requirement already satisfied: fonttools>=4.22.0 in /home/***/.local/lib/python3.8/site-packages (from matplotlib<4->mlflow==2.10.2->-r /tmp/venvky9ptz1y/requirements.txt (line 2)) (4.51.0)
[2024-04-21T22:57:32.075+0000] {process_utils.py:190} INFO - Requirement already satisfied: kiwisolver>=1.0.1 in /home/***/.local/lib/python3.8/site-packages (from matplotlib<4->mlflow==2.10.2->-r /tmp/venvky9ptz1y/requirements.txt (line 2)) (1.4.5)
[2024-04-21T22:57:32.076+0000] {process_utils.py:190} INFO - Requirement already satisfied: pillow>=6.2.0 in /home/***/.local/lib/python3.8/site-packages (from matplotlib<4->mlflow==2.10.2->-r /tmp/venvky9ptz1y/requirements.txt (line 2)) (10.3.0)
[2024-04-21T22:57:32.076+0000] {process_utils.py:190} INFO - Requirement already satisfied: pyparsing>=2.3.1 in /home/***/.local/lib/python3.8/site-packages (from matplotlib<4->mlflow==2.10.2->-r /tmp/venvky9ptz1y/requirements.txt (line 2)) (3.1.1)
[2024-04-21T22:57:32.136+0000] {process_utils.py:190} INFO - Requirement already satisfied: tzdata>=2022.1 in /home/***/.local/lib/python3.8/site-packages (from pandas<2.1.0,>=1.2.0->awswrangler==3.6.0->-r /tmp/venvky9ptz1y/requirements.txt (line 1)) (2023.4)
[2024-04-21T22:57:32.148+0000] {process_utils.py:190} INFO - Requirement already satisfied: six in /home/***/.local/lib/python3.8/site-packages (from querystring-parser<2->mlflow==2.10.2->-r /tmp/venvky9ptz1y/requirements.txt (line 2)) (1.16.0)
[2024-04-21T22:57:32.154+0000] {process_utils.py:190} INFO - Requirement already satisfied: charset-normalizer<4,>=2 in /home/***/.local/lib/python3.8/site-packages (from requests<3,>=2.17.3->mlflow==2.10.2->-r /tmp/venvky9ptz1y/requirements.txt (line 2)) (3.3.2)
[2024-04-21T22:57:32.155+0000] {process_utils.py:190} INFO - Requirement already satisfied: idna<4,>=2.5 in /home/***/.local/lib/python3.8/site-packages (from requests<3,>=2.17.3->mlflow==2.10.2->-r /tmp/venvky9ptz1y/requirements.txt (line 2)) (3.6)
[2024-04-21T22:57:32.155+0000] {process_utils.py:190} INFO - Requirement already satisfied: certifi>=2017.4.17 in /home/***/.local/lib/python3.8/site-packages (from requests<3,>=2.17.3->mlflow==2.10.2->-r /tmp/venvky9ptz1y/requirements.txt (line 2)) (2023.11.17)
[2024-04-21T22:57:32.217+0000] {process_utils.py:190} INFO - Requirement already satisfied: greenlet!=0.4.17 in /home/***/.local/lib/python3.8/site-packages (from sqlalchemy<3,>=1.4.0->mlflow==2.10.2->-r /tmp/venvky9ptz1y/requirements.txt (line 2)) (3.0.3)
[2024-04-21T22:57:32.299+0000] {process_utils.py:190} INFO - Requirement already satisfied: smmap<6,>=3.0.1 in /home/***/.local/lib/python3.8/site-packages (from gitdb<5,>=4.0.1->gitpython<4,>=2.1.0->mlflow==2.10.2->-r /tmp/venvky9ptz1y/requirements.txt (line 2)) (5.0.1)
[2024-04-21T22:57:32.413+0000] {process_utils.py:190} INFO - Using cached awswrangler-3.6.0-py3-none-any.whl (403 kB)
[2024-04-21T22:57:32.434+0000] {process_utils.py:190} INFO - Downloading mlflow-2.10.2-py3-none-any.whl (19.5 MB)
[2024-04-21T22:57:38.927+0000] {process_utils.py:190} INFO -    ━━━━━━━━━━━━━━━━━━━━━━━━━━━━━━━━━━━━━━━━ 19.5/19.5 MB 3.2 MB/s eta 0:00:00
[2024-04-21T22:57:40.826+0000] {process_utils.py:190} INFO - Installing collected packages: mlflow, awswrangler
[2024-04-21T22:57:40.826+0000] {process_utils.py:190} INFO -   Attempting uninstall: mlflow
[2024-04-21T22:57:40.828+0000] {process_utils.py:190} INFO -     Found existing installation: mlflow 2.12.1
[2024-04-21T22:57:40.828+0000] {process_utils.py:190} INFO -     Not uninstalling mlflow at /home/***/.local/lib/python3.8/site-packages, outside environment /tmp/venvky9ptz1y
[2024-04-21T22:57:40.828+0000] {process_utils.py:190} INFO -     Can't uninstall 'mlflow'. No files were found to uninstall.
[2024-04-21T22:57:41.811+0000] {process_utils.py:190} INFO - Successfully installed awswrangler-3.6.0 mlflow-2.10.2
[2024-04-21T22:57:41.938+0000] {process_utils.py:190} INFO - 
[2024-04-21T22:57:41.939+0000] {process_utils.py:190} INFO - [notice] A new release of pip is available: 23.3.1 -> 24.0
[2024-04-21T22:57:41.939+0000] {process_utils.py:190} INFO - [notice] To update, run: python -m pip install --upgrade pip
[2024-04-21T22:57:42.070+0000] {process_utils.py:182} INFO - Executing cmd: /tmp/venvky9ptz1y/bin/python /tmp/venv-callh4tnmevp/script.py /tmp/venv-callh4tnmevp/script.in /tmp/venv-callh4tnmevp/script.out /tmp/venv-callh4tnmevp/string_args.txt /tmp/venv-callh4tnmevp/termination.log
[2024-04-21T22:57:42.077+0000] {process_utils.py:186} INFO - Output:
[2024-04-21T22:57:43.909+0000] {process_utils.py:190} INFO - [[34m2024-04-21T22:57:43.908+0000[0m] {[34mcredentials.py:[0m1147} INFO[0m - Found credentials in environment variables.[0m
[2024-04-21T22:57:43.946+0000] {process_utils.py:190} INFO - [[34m2024-04-21T22:57:43.945+0000[0m] {[34mconfigprovider.py:[0m957} INFO[0m - Found endpoint for s3 via: environment_service.[0m
[2024-04-21T22:57:44.203+0000] {process_utils.py:190} INFO - [[34m2024-04-21T22:57:44.203+0000[0m] {[34mcredentials.py:[0m1147} INFO[0m - Found credentials in environment variables.[0m
[2024-04-21T22:57:44.329+0000] {process_utils.py:190} INFO - [[34m2024-04-21T22:57:44.329+0000[0m] {[34mconfigprovider.py:[0m957} INFO[0m - Found endpoint for s3 via: environment_service.[0m
[2024-04-21T22:57:44.508+0000] {process_utils.py:190} INFO - [[34m2024-04-21T22:57:44.508+0000[0m] {[34mcredentials.py:[0m1147} INFO[0m - Found credentials in environment variables.[0m
[2024-04-21T22:57:44.542+0000] {process_utils.py:190} INFO - [[34m2024-04-21T22:57:44.541+0000[0m] {[34mconfigprovider.py:[0m957} INFO[0m - Found endpoint for s3 via: environment_service.[0m
[2024-04-21T22:57:45.184+0000] {process_utils.py:190} INFO - [[34m2024-04-21T22:57:45.184+0000[0m] {[34mcredentials.py:[0m1147} INFO[0m - Found credentials in environment variables.[0m
[2024-04-21T22:57:45.220+0000] {process_utils.py:190} INFO - [[34m2024-04-21T22:57:45.219+0000[0m] {[34mconfigprovider.py:[0m957} INFO[0m - Found endpoint for s3 via: environment_service.[0m
[2024-04-21T22:57:45.399+0000] {process_utils.py:190} INFO - [[34m2024-04-21T22:57:45.398+0000[0m] {[34mcredentials.py:[0m1147} INFO[0m - Found credentials in environment variables.[0m
[2024-04-21T22:57:45.445+0000] {process_utils.py:190} INFO - [[34m2024-04-21T22:57:45.445+0000[0m] {[34mconfigprovider.py:[0m957} INFO[0m - Found endpoint for s3 via: environment_service.[0m
[2024-04-21T22:57:45.662+0000] {process_utils.py:190} INFO - Traceback (most recent call last):
[2024-04-21T22:57:45.663+0000] {process_utils.py:190} INFO -   File "/tmp/venvky9ptz1y/lib/python3.8/site-packages/mlflow/tracking/_tracking_service/client.py", line 321, in log_param
[2024-04-21T22:57:45.663+0000] {process_utils.py:190} INFO -     self.store.log_param(run_id, param)
[2024-04-21T22:57:45.664+0000] {process_utils.py:190} INFO -   File "/tmp/venvky9ptz1y/lib/python3.8/site-packages/mlflow/store/tracking/rest_store.py", line 210, in log_param
[2024-04-21T22:57:45.664+0000] {process_utils.py:190} INFO -     self._call_endpoint(LogParam, req_body)
[2024-04-21T22:57:45.664+0000] {process_utils.py:190} INFO -   File "/tmp/venvky9ptz1y/lib/python3.8/site-packages/mlflow/store/tracking/rest_store.py", line 59, in _call_endpoint
[2024-04-21T22:57:45.664+0000] {process_utils.py:190} INFO -     return call_endpoint(self.get_host_creds(), endpoint, method, json_body, response_proto)
[2024-04-21T22:57:45.665+0000] {process_utils.py:190} INFO -   File "/tmp/venvky9ptz1y/lib/python3.8/site-packages/mlflow/utils/rest_utils.py", line 220, in call_endpoint
[2024-04-21T22:57:45.665+0000] {process_utils.py:190} INFO -     response = verify_rest_response(response, endpoint)
[2024-04-21T22:57:45.665+0000] {process_utils.py:190} INFO -   File "/tmp/venvky9ptz1y/lib/python3.8/site-packages/mlflow/utils/rest_utils.py", line 152, in verify_rest_response
[2024-04-21T22:57:45.665+0000] {process_utils.py:190} INFO -     raise RestException(json.loads(response.text))
[2024-04-21T22:57:45.666+0000] {process_utils.py:190} INFO - mlflow.exceptions.RestException: INVALID_PARAMETER_VALUE: Changing param values is not allowed. Param with key='Standard Scaler mean values' was already logged with value='[5.48743961e+01 6.42512077e-01 1.31555556e+02 2.48251208e+02
[2024-04-21T22:57:45.666+0000] {process_utils.py:190} INFO -  1.59420290e-01 1.48565217e+02 3.09178744e-01 1.05942029e+00
[2024-04-21T22:57:45.666+0000] {process_utils.py:190} INFO -  1.44927536e-01 2.99516908e-01 4.73429952e-01 1.93236715e-02
[2024-04-21T22:57:45.666+0000] {process_utils.py:190} INFO -  5.12077295e-01 4.73429952e-01 6.28019324e-02 2.07729469e-01
[2024-04-21T22:57:45.667+0000] {process_utils.py:190} INFO -  1.44927536e-01 7.72946860e-02 5.31400966e-02 3.81642512e-01]' for run ID='1948954b0d0e47d29091104fd3187536'. Attempted logging new value '[ 2.40280152e-16  3.00350190e-17  7.17622419e-16 -9.22504156e-17
[2024-04-21T22:57:45.667+0000] {process_utils.py:190} INFO -   1.24430793e-16  1.63047246e-16  1.34084906e-17  3.64710945e-17
[2024-04-21T22:57:45.667+0000] {process_utils.py:190} INFO -   9.86864911e-17 -2.35989435e-17  6.43607551e-17  8.58143401e-18
[2024-04-21T22:57:45.667+0000] {process_utils.py:190} INFO -  -1.63047246e-16  7.07968306e-17 -1.71628680e-17 -1.28721510e-17
[2024-04-21T22:57:45.668+0000] {process_utils.py:190} INFO -   2.57443020e-17  1.71628680e-17  5.57793210e-17  1.15849359e-16]'.
[2024-04-21T22:57:45.668+0000] {process_utils.py:190} INFO - 
[2024-04-21T22:57:45.668+0000] {process_utils.py:190} INFO - During handling of the above exception, another exception occurred:
[2024-04-21T22:57:45.668+0000] {process_utils.py:190} INFO - 
[2024-04-21T22:57:45.668+0000] {process_utils.py:190} INFO - Traceback (most recent call last):
[2024-04-21T22:57:45.668+0000] {process_utils.py:190} INFO -   File "/tmp/venv-callh4tnmevp/script.py", line 95, in <module>
[2024-04-21T22:57:45.669+0000] {process_utils.py:190} INFO -     res = normalize_data(*arg_dict["args"], **arg_dict["kwargs"])
[2024-04-21T22:57:45.669+0000] {process_utils.py:190} INFO -   File "/tmp/venv-callh4tnmevp/script.py", line 91, in normalize_data
[2024-04-21T22:57:45.669+0000] {process_utils.py:190} INFO -     mlflow.log_param("Standard Scaler mean values", sc_X.mean_)
[2024-04-21T22:57:45.669+0000] {process_utils.py:190} INFO -   File "/tmp/venvky9ptz1y/lib/python3.8/site-packages/mlflow/tracking/fluent.py", line 647, in log_param
[2024-04-21T22:57:45.670+0000] {process_utils.py:190} INFO -     return MlflowClient().log_param(run_id, key, value, synchronous=synchronous)
[2024-04-21T22:57:45.670+0000] {process_utils.py:190} INFO -   File "/tmp/venvky9ptz1y/lib/python3.8/site-packages/mlflow/tracking/client.py", line 841, in log_param
[2024-04-21T22:57:45.670+0000] {process_utils.py:190} INFO -     self._tracking_client.log_param(run_id, key, value, synchronous=True)
[2024-04-21T22:57:45.670+0000] {process_utils.py:190} INFO -   File "/tmp/venvky9ptz1y/lib/python3.8/site-packages/mlflow/tracking/_tracking_service/client.py", line 328, in log_param
[2024-04-21T22:57:45.670+0000] {process_utils.py:190} INFO -     raise MlflowException(msg, INVALID_PARAMETER_VALUE)
[2024-04-21T22:57:45.671+0000] {process_utils.py:190} INFO - mlflow.exceptions.MlflowException: INVALID_PARAMETER_VALUE: Changing param values is not allowed. Param with key='Standard Scaler mean values' was already logged with value='[5.48743961e+01 6.42512077e-01 1.31555556e+02 2.48251208e+02
[2024-04-21T22:57:45.671+0000] {process_utils.py:190} INFO -  1.59420290e-01 1.48565217e+02 3.09178744e-01 1.05942029e+00
[2024-04-21T22:57:45.671+0000] {process_utils.py:190} INFO -  1.44927536e-01 2.99516908e-01 4.73429952e-01 1.93236715e-02
[2024-04-21T22:57:45.671+0000] {process_utils.py:190} INFO -  5.12077295e-01 4.73429952e-01 6.28019324e-02 2.07729469e-01
[2024-04-21T22:57:45.672+0000] {process_utils.py:190} INFO -  1.44927536e-01 7.72946860e-02 5.31400966e-02 3.81642512e-01]' for run ID='1948954b0d0e47d29091104fd3187536'. Attempted logging new value '[ 2.40280152e-16  3.00350190e-17  7.17622419e-16 -9.22504156e-17
[2024-04-21T22:57:45.672+0000] {process_utils.py:190} INFO -   1.24430793e-16  1.63047246e-16  1.34084906e-17  3.64710945e-17
[2024-04-21T22:57:45.672+0000] {process_utils.py:190} INFO -   9.86864911e-17 -2.35989435e-17  6.43607551e-17  8.58143401e-18
[2024-04-21T22:57:45.672+0000] {process_utils.py:190} INFO -  -1.63047246e-16  7.07968306e-17 -1.71628680e-17 -1.28721510e-17
[2024-04-21T22:57:45.673+0000] {process_utils.py:190} INFO -   2.57443020e-17  1.71628680e-17  5.57793210e-17  1.15849359e-16]'.
[2024-04-21T22:57:45.673+0000] {process_utils.py:190} INFO - 
[2024-04-21T22:57:45.673+0000] {process_utils.py:190} INFO - The cause of this error is typically due to repeated calls
[2024-04-21T22:57:45.673+0000] {process_utils.py:190} INFO - to an individual run_id event logging.
[2024-04-21T22:57:45.674+0000] {process_utils.py:190} INFO - 
[2024-04-21T22:57:45.674+0000] {process_utils.py:190} INFO - Incorrect Example:
[2024-04-21T22:57:45.674+0000] {process_utils.py:190} INFO - ---------------------------------------
[2024-04-21T22:57:45.674+0000] {process_utils.py:190} INFO - with mlflow.start_run():
[2024-04-21T22:57:45.674+0000] {process_utils.py:190} INFO -     mlflow.log_param("depth", 3)
[2024-04-21T22:57:45.675+0000] {process_utils.py:190} INFO -     mlflow.log_param("depth", 5)
[2024-04-21T22:57:45.675+0000] {process_utils.py:190} INFO - ---------------------------------------
[2024-04-21T22:57:45.675+0000] {process_utils.py:190} INFO - 
[2024-04-21T22:57:45.675+0000] {process_utils.py:190} INFO - Which will throw an MlflowException for overwriting a
[2024-04-21T22:57:45.675+0000] {process_utils.py:190} INFO - logged parameter.
[2024-04-21T22:57:45.675+0000] {process_utils.py:190} INFO - 
[2024-04-21T22:57:45.676+0000] {process_utils.py:190} INFO - Correct Example:
[2024-04-21T22:57:45.676+0000] {process_utils.py:190} INFO - ---------------------------------------
[2024-04-21T22:57:45.676+0000] {process_utils.py:190} INFO - with mlflow.start_run():
[2024-04-21T22:57:45.676+0000] {process_utils.py:190} INFO -     with mlflow.start_run(nested=True):
[2024-04-21T22:57:45.677+0000] {process_utils.py:190} INFO -         mlflow.log_param("depth", 3)
[2024-04-21T22:57:45.677+0000] {process_utils.py:190} INFO -     with mlflow.start_run(nested=True):
[2024-04-21T22:57:45.677+0000] {process_utils.py:190} INFO -         mlflow.log_param("depth", 5)
[2024-04-21T22:57:45.677+0000] {process_utils.py:190} INFO - ---------------------------------------
[2024-04-21T22:57:45.677+0000] {process_utils.py:190} INFO - 
[2024-04-21T22:57:45.678+0000] {process_utils.py:190} INFO - Which will create a new nested run for each individual
[2024-04-21T22:57:45.678+0000] {process_utils.py:190} INFO - model and prevent parameter key collisions within the
[2024-04-21T22:57:45.678+0000] {process_utils.py:190} INFO - tracking store.
[2024-04-21T22:57:46.117+0000] {taskinstance.py:2698} ERROR - Task failed with exception
Traceback (most recent call last):
  File "/home/airflow/.local/lib/python3.8/site-packages/airflow/models/taskinstance.py", line 433, in _execute_task
    result = execute_callable(context=context, **execute_callable_kwargs)
  File "/home/airflow/.local/lib/python3.8/site-packages/airflow/decorators/base.py", line 241, in execute
    return_value = super().execute(context)
  File "/home/airflow/.local/lib/python3.8/site-packages/airflow/operators/python.py", line 400, in execute
    return super().execute(context=serializable_context)
  File "/home/airflow/.local/lib/python3.8/site-packages/airflow/operators/python.py", line 199, in execute
    return_value = self.execute_callable()
  File "/home/airflow/.local/lib/python3.8/site-packages/airflow/operators/python.py", line 716, in execute_callable
    result = self._execute_python_callable_in_subprocess(python_path)
  File "/home/airflow/.local/lib/python3.8/site-packages/airflow/operators/python.py", line 471, in _execute_python_callable_in_subprocess
    raise AirflowException(error_msg) from None
airflow.exceptions.AirflowException: Process returned non-zero exit status 1.
INVALID_PARAMETER_VALUE: Changing param values is not allowed. Param with key='Standard Scaler mean values' was already logged with value='[5.48743961e+01 6.42512077e-01 1.31555556e+02 2.48251208e+02
 1.59420290e-01 1.48565217e+02 3.09178744e-01 1.05942029e+00
 1.44927536e-01 2.99516908e-01 4.73429952e-01 1.93236715e-02
 5.12077295e-01 4.73429952e-01 6.28019324e-02 2.07729469e-01
 1.44927536e-01 7.72946860e-02 5.31400966e-02 3.81642512e-01]' for run ID='1948954b0d0e47d29091104fd3187536'. Attempted logging new value '[ 2.40280152e-16  3.00350190e-17  7.17622419e-16 -9.22504156e-17
  1.24430793e-16  1.63047246e-16  1.34084906e-17  3.64710945e-17
  9.86864911e-17 -2.35989435e-17  6.43607551e-17  8.58143401e-18
 -1.63047246e-16  7.07968306e-17 -1.71628680e-17 -1.28721510e-17
  2.57443020e-17  1.71628680e-17  5.57793210e-17  1.15849359e-16]'.

The cause of this error is typically due to repeated calls
to an individual run_id event logging.

Incorrect Example:
---------------------------------------
with mlflow.start_run():
    mlflow.log_param("depth", 3)
    mlflow.log_param("depth", 5)
---------------------------------------

Which will throw an MlflowException for overwriting a
logged parameter.

Correct Example:
---------------------------------------
with mlflow.start_run():
    with mlflow.start_run(nested=True):
        mlflow.log_param("depth", 3)
    with mlflow.start_run(nested=True):
        mlflow.log_param("depth", 5)
---------------------------------------

Which will create a new nested run for each individual
model and prevent parameter key collisions within the
tracking store.
[2024-04-21T22:57:46.119+0000] {taskinstance.py:1138} INFO - Marking task as UP_FOR_RETRY. dag_id=process_etl_heart_data, task_id=normalize_numerical_features, execution_date=20240420T000000, start_date=20240421T225730, end_date=20240421T225746
[2024-04-21T22:57:49.626+0000] {standard_task_runner.py:107} ERROR - Failed to execute job 9 for task normalize_numerical_features (Process returned non-zero exit status 1.
INVALID_PARAMETER_VALUE: Changing param values is not allowed. Param with key='Standard Scaler mean values' was already logged with value='[5.48743961e+01 6.42512077e-01 1.31555556e+02 2.48251208e+02
 1.59420290e-01 1.48565217e+02 3.09178744e-01 1.05942029e+00
 1.44927536e-01 2.99516908e-01 4.73429952e-01 1.93236715e-02
 5.12077295e-01 4.73429952e-01 6.28019324e-02 2.07729469e-01
 1.44927536e-01 7.72946860e-02 5.31400966e-02 3.81642512e-01]' for run ID='1948954b0d0e47d29091104fd3187536'. Attempted logging new value '[ 2.40280152e-16  3.00350190e-17  7.17622419e-16 -9.22504156e-17
  1.24430793e-16  1.63047246e-16  1.34084906e-17  3.64710945e-17
  9.86864911e-17 -2.35989435e-17  6.43607551e-17  8.58143401e-18
 -1.63047246e-16  7.07968306e-17 -1.71628680e-17 -1.28721510e-17
  2.57443020e-17  1.71628680e-17  5.57793210e-17  1.15849359e-16]'.

The cause of this error is typically due to repeated calls
to an individual run_id event logging.

Incorrect Example:
---------------------------------------
with mlflow.start_run():
    mlflow.log_param("depth", 3)
    mlflow.log_param("depth", 5)
---------------------------------------

Which will throw an MlflowException for overwriting a
logged parameter.

Correct Example:
---------------------------------------
with mlflow.start_run():
    with mlflow.start_run(nested=True):
        mlflow.log_param("depth", 3)
    with mlflow.start_run(nested=True):
        mlflow.log_param("depth", 5)
---------------------------------------

Which will create a new nested run for each individual
model and prevent parameter key collisions within the
tracking store.; 17539)
[2024-04-21T22:57:49.648+0000] {local_task_job_runner.py:234} INFO - Task exited with return code 1
[2024-04-21T22:57:49.658+0000] {taskinstance.py:3280} INFO - 0 downstream tasks scheduled from follow-on schedule check
