[2024-04-21T23:02:46.857+0000] {taskinstance.py:1956} INFO - Dependencies all met for dep_context=non-requeueable deps ti=<TaskInstance: process_etl_heart_data.normalize_numerical_features scheduled__2024-04-20T00:00:00+00:00 [queued]>
[2024-04-21T23:02:46.861+0000] {taskinstance.py:1956} INFO - Dependencies all met for dep_context=requeueable deps ti=<TaskInstance: process_etl_heart_data.normalize_numerical_features scheduled__2024-04-20T00:00:00+00:00 [queued]>
[2024-04-21T23:02:46.862+0000] {taskinstance.py:2170} INFO - Starting attempt 2 of 2
[2024-04-21T23:02:46.871+0000] {taskinstance.py:2191} INFO - Executing <Task(_PythonVirtualenvDecoratedOperator): normalize_numerical_features> on 2024-04-20 00:00:00+00:00
[2024-04-21T23:02:46.874+0000] {standard_task_runner.py:60} INFO - Started process 20354 to run task
[2024-04-21T23:02:46.876+0000] {standard_task_runner.py:87} INFO - Running: ['***', 'tasks', 'run', 'process_etl_heart_data', 'normalize_numerical_features', 'scheduled__2024-04-20T00:00:00+00:00', '--job-id', '12', '--raw', '--subdir', 'DAGS_FOLDER/etl_process.py', '--cfg-path', '/tmp/tmp0cslb108']
[2024-04-21T23:02:46.877+0000] {standard_task_runner.py:88} INFO - Job 12: Subtask normalize_numerical_features
[2024-04-21T23:02:46.906+0000] {task_command.py:423} INFO - Running <TaskInstance: process_etl_heart_data.normalize_numerical_features scheduled__2024-04-20T00:00:00+00:00 [running]> on host 2e52d55d127b
[2024-04-21T23:02:46.950+0000] {taskinstance.py:2480} INFO - Exporting env vars: AIRFLOW_CTX_DAG_OWNER='Facundo Adrian Lucianna' AIRFLOW_CTX_DAG_ID='process_etl_heart_data' AIRFLOW_CTX_TASK_ID='normalize_numerical_features' AIRFLOW_CTX_EXECUTION_DATE='2024-04-20T00:00:00+00:00' AIRFLOW_CTX_TRY_NUMBER='2' AIRFLOW_CTX_DAG_RUN_ID='scheduled__2024-04-20T00:00:00+00:00'
[2024-04-21T23:02:46.952+0000] {process_utils.py:182} INFO - Executing cmd: /usr/local/bin/python -m virtualenv /tmp/venvx6yx46_j --system-site-packages --python=python
[2024-04-21T23:02:46.957+0000] {process_utils.py:186} INFO - Output:
[2024-04-21T23:02:47.372+0000] {process_utils.py:190} INFO - created virtual environment CPython3.8.18.final.0-64 in 150ms
[2024-04-21T23:02:47.372+0000] {process_utils.py:190} INFO -   creator CPython3Posix(dest=/tmp/venvx6yx46_j, clear=False, no_vcs_ignore=False, global=True)
[2024-04-21T23:02:47.373+0000] {process_utils.py:190} INFO -   seeder FromAppData(download=False, pip=bundle, setuptools=bundle, wheel=bundle, via=copy, app_data_dir=/home/***/.local/share/virtualenv)
[2024-04-21T23:02:47.373+0000] {process_utils.py:190} INFO -     added seed packages: pip==23.3.1, setuptools==69.0.2, wheel==0.42.0
[2024-04-21T23:02:47.374+0000] {process_utils.py:190} INFO -   activators BashActivator,CShellActivator,FishActivator,NushellActivator,PowerShellActivator,PythonActivator
[2024-04-21T23:02:47.392+0000] {process_utils.py:182} INFO - Executing cmd: /tmp/venvx6yx46_j/bin/pip install -r /tmp/venvx6yx46_j/requirements.txt
[2024-04-21T23:02:47.397+0000] {process_utils.py:186} INFO - Output:
[2024-04-21T23:02:48.265+0000] {process_utils.py:190} INFO - Collecting awswrangler==3.6.0 (from -r /tmp/venvx6yx46_j/requirements.txt (line 1))
[2024-04-21T23:02:48.267+0000] {process_utils.py:190} INFO -   Using cached awswrangler-3.6.0-py3-none-any.whl.metadata (23 kB)
[2024-04-21T23:02:48.324+0000] {process_utils.py:190} INFO - Collecting mlflow==2.10.2 (from -r /tmp/venvx6yx46_j/requirements.txt (line 2))
[2024-04-21T23:02:48.325+0000] {process_utils.py:190} INFO -   Using cached mlflow-2.10.2-py3-none-any.whl.metadata (13 kB)
[2024-04-21T23:02:48.326+0000] {process_utils.py:190} INFO - Requirement already satisfied: scikit-learn==1.3.2 in /home/***/.local/lib/python3.8/site-packages (from -r /tmp/venvx6yx46_j/requirements.txt (line 3)) (1.3.2)
[2024-04-21T23:02:48.357+0000] {process_utils.py:190} INFO - Requirement already satisfied: boto3<2.0.0,>=1.20.32 in /home/***/.local/lib/python3.8/site-packages (from awswrangler==3.6.0->-r /tmp/venvx6yx46_j/requirements.txt (line 1)) (1.34.88)
[2024-04-21T23:02:48.357+0000] {process_utils.py:190} INFO - Requirement already satisfied: botocore<2.0.0,>=1.23.32 in /home/***/.local/lib/python3.8/site-packages (from awswrangler==3.6.0->-r /tmp/venvx6yx46_j/requirements.txt (line 1)) (1.34.88)
[2024-04-21T23:02:48.358+0000] {process_utils.py:190} INFO - Requirement already satisfied: numpy<2.0,>=1.18 in /home/***/.local/lib/python3.8/site-packages (from awswrangler==3.6.0->-r /tmp/venvx6yx46_j/requirements.txt (line 1)) (1.24.4)
[2024-04-21T23:02:48.359+0000] {process_utils.py:190} INFO - Requirement already satisfied: packaging<24.0,>=21.1 in /home/***/.local/lib/python3.8/site-packages (from awswrangler==3.6.0->-r /tmp/venvx6yx46_j/requirements.txt (line 1)) (23.2)
[2024-04-21T23:02:48.359+0000] {process_utils.py:190} INFO - Requirement already satisfied: pandas<2.1.0,>=1.2.0 in /home/***/.local/lib/python3.8/site-packages (from awswrangler==3.6.0->-r /tmp/venvx6yx46_j/requirements.txt (line 1)) (2.0.3)
[2024-04-21T23:02:48.360+0000] {process_utils.py:190} INFO - Requirement already satisfied: pyarrow>=7.0.0 in /home/***/.local/lib/python3.8/site-packages (from awswrangler==3.6.0->-r /tmp/venvx6yx46_j/requirements.txt (line 1)) (14.0.2)
[2024-04-21T23:02:48.360+0000] {process_utils.py:190} INFO - Requirement already satisfied: typing-extensions<5.0.0,>=4.4.0 in /home/***/.local/lib/python3.8/site-packages (from awswrangler==3.6.0->-r /tmp/venvx6yx46_j/requirements.txt (line 1)) (4.9.0)
[2024-04-21T23:02:48.396+0000] {process_utils.py:190} INFO - Requirement already satisfied: click<9,>=7.0 in /home/***/.local/lib/python3.8/site-packages (from mlflow==2.10.2->-r /tmp/venvx6yx46_j/requirements.txt (line 2)) (8.1.7)
[2024-04-21T23:02:48.397+0000] {process_utils.py:190} INFO - Requirement already satisfied: cloudpickle<4 in /home/***/.local/lib/python3.8/site-packages (from mlflow==2.10.2->-r /tmp/venvx6yx46_j/requirements.txt (line 2)) (3.0.0)
[2024-04-21T23:02:48.397+0000] {process_utils.py:190} INFO - Requirement already satisfied: entrypoints<1 in /home/***/.local/lib/python3.8/site-packages (from mlflow==2.10.2->-r /tmp/venvx6yx46_j/requirements.txt (line 2)) (0.4)
[2024-04-21T23:02:48.398+0000] {process_utils.py:190} INFO - Requirement already satisfied: gitpython<4,>=2.1.0 in /home/***/.local/lib/python3.8/site-packages (from mlflow==2.10.2->-r /tmp/venvx6yx46_j/requirements.txt (line 2)) (3.1.43)
[2024-04-21T23:02:48.398+0000] {process_utils.py:190} INFO - Requirement already satisfied: pyyaml<7,>=5.1 in /home/***/.local/lib/python3.8/site-packages (from mlflow==2.10.2->-r /tmp/venvx6yx46_j/requirements.txt (line 2)) (6.0.1)
[2024-04-21T23:02:48.399+0000] {process_utils.py:190} INFO - Requirement already satisfied: protobuf<5,>=3.12.0 in /home/***/.local/lib/python3.8/site-packages (from mlflow==2.10.2->-r /tmp/venvx6yx46_j/requirements.txt (line 2)) (4.25.2)
[2024-04-21T23:02:48.400+0000] {process_utils.py:190} INFO - Requirement already satisfied: pytz<2024 in /home/***/.local/lib/python3.8/site-packages (from mlflow==2.10.2->-r /tmp/venvx6yx46_j/requirements.txt (line 2)) (2023.3.post1)
[2024-04-21T23:02:48.400+0000] {process_utils.py:190} INFO - Requirement already satisfied: requests<3,>=2.17.3 in /home/***/.local/lib/python3.8/site-packages (from mlflow==2.10.2->-r /tmp/venvx6yx46_j/requirements.txt (line 2)) (2.31.0)
[2024-04-21T23:02:48.401+0000] {process_utils.py:190} INFO - Requirement already satisfied: importlib-metadata!=4.7.0,<8,>=3.7.0 in /home/***/.local/lib/python3.8/site-packages (from mlflow==2.10.2->-r /tmp/venvx6yx46_j/requirements.txt (line 2)) (6.11.0)
[2024-04-21T23:02:48.401+0000] {process_utils.py:190} INFO - Requirement already satisfied: sqlparse<1,>=0.4.0 in /home/***/.local/lib/python3.8/site-packages (from mlflow==2.10.2->-r /tmp/venvx6yx46_j/requirements.txt (line 2)) (0.4.4)
[2024-04-21T23:02:48.402+0000] {process_utils.py:190} INFO - Requirement already satisfied: alembic!=1.10.0,<2 in /home/***/.local/lib/python3.8/site-packages (from mlflow==2.10.2->-r /tmp/venvx6yx46_j/requirements.txt (line 2)) (1.13.1)
[2024-04-21T23:02:48.402+0000] {process_utils.py:190} INFO - Requirement already satisfied: docker<8,>=4.0.0 in /home/***/.local/lib/python3.8/site-packages (from mlflow==2.10.2->-r /tmp/venvx6yx46_j/requirements.txt (line 2)) (7.0.0)
[2024-04-21T23:02:48.403+0000] {process_utils.py:190} INFO - Requirement already satisfied: Flask<4 in /home/***/.local/lib/python3.8/site-packages (from mlflow==2.10.2->-r /tmp/venvx6yx46_j/requirements.txt (line 2)) (2.2.5)
[2024-04-21T23:02:48.403+0000] {process_utils.py:190} INFO - Requirement already satisfied: scipy<2 in /home/***/.local/lib/python3.8/site-packages (from mlflow==2.10.2->-r /tmp/venvx6yx46_j/requirements.txt (line 2)) (1.10.1)
[2024-04-21T23:02:48.404+0000] {process_utils.py:190} INFO - Requirement already satisfied: querystring-parser<2 in /home/***/.local/lib/python3.8/site-packages (from mlflow==2.10.2->-r /tmp/venvx6yx46_j/requirements.txt (line 2)) (1.2.4)
[2024-04-21T23:02:48.404+0000] {process_utils.py:190} INFO - Requirement already satisfied: sqlalchemy<3,>=1.4.0 in /home/***/.local/lib/python3.8/site-packages (from mlflow==2.10.2->-r /tmp/venvx6yx46_j/requirements.txt (line 2)) (1.4.51)
[2024-04-21T23:02:48.405+0000] {process_utils.py:190} INFO - Requirement already satisfied: markdown<4,>=3.3 in /home/***/.local/lib/python3.8/site-packages (from mlflow==2.10.2->-r /tmp/venvx6yx46_j/requirements.txt (line 2)) (3.5.2)
[2024-04-21T23:02:48.405+0000] {process_utils.py:190} INFO - Requirement already satisfied: matplotlib<4 in /home/***/.local/lib/python3.8/site-packages (from mlflow==2.10.2->-r /tmp/venvx6yx46_j/requirements.txt (line 2)) (3.7.5)
[2024-04-21T23:02:48.406+0000] {process_utils.py:190} INFO - Requirement already satisfied: gunicorn<22 in /home/***/.local/lib/python3.8/site-packages (from mlflow==2.10.2->-r /tmp/venvx6yx46_j/requirements.txt (line 2)) (21.2.0)
[2024-04-21T23:02:48.407+0000] {process_utils.py:190} INFO - Requirement already satisfied: Jinja2<4,>=2.11 in /home/***/.local/lib/python3.8/site-packages (from mlflow==2.10.2->-r /tmp/venvx6yx46_j/requirements.txt (line 2)) (3.1.3)
[2024-04-21T23:02:48.429+0000] {process_utils.py:190} INFO - Requirement already satisfied: joblib>=1.1.1 in /home/***/.local/lib/python3.8/site-packages (from scikit-learn==1.3.2->-r /tmp/venvx6yx46_j/requirements.txt (line 3)) (1.4.0)
[2024-04-21T23:02:48.429+0000] {process_utils.py:190} INFO - Requirement already satisfied: threadpoolctl>=2.0.0 in /home/***/.local/lib/python3.8/site-packages (from scikit-learn==1.3.2->-r /tmp/venvx6yx46_j/requirements.txt (line 3)) (3.4.0)
[2024-04-21T23:02:48.434+0000] {process_utils.py:190} INFO - Requirement already satisfied: Mako in /home/***/.local/lib/python3.8/site-packages (from alembic!=1.10.0,<2->mlflow==2.10.2->-r /tmp/venvx6yx46_j/requirements.txt (line 2)) (1.3.0)
[2024-04-21T23:02:48.435+0000] {process_utils.py:190} INFO - Requirement already satisfied: importlib-resources in /home/***/.local/lib/python3.8/site-packages (from alembic!=1.10.0,<2->mlflow==2.10.2->-r /tmp/venvx6yx46_j/requirements.txt (line 2)) (5.13.0)
[2024-04-21T23:02:48.439+0000] {process_utils.py:190} INFO - Requirement already satisfied: jmespath<2.0.0,>=0.7.1 in /home/***/.local/lib/python3.8/site-packages (from boto3<2.0.0,>=1.20.32->awswrangler==3.6.0->-r /tmp/venvx6yx46_j/requirements.txt (line 1)) (0.10.0)
[2024-04-21T23:02:48.440+0000] {process_utils.py:190} INFO - Requirement already satisfied: s3transfer<0.11.0,>=0.10.0 in /home/***/.local/lib/python3.8/site-packages (from boto3<2.0.0,>=1.20.32->awswrangler==3.6.0->-r /tmp/venvx6yx46_j/requirements.txt (line 1)) (0.10.1)
[2024-04-21T23:02:48.444+0000] {process_utils.py:190} INFO - Requirement already satisfied: python-dateutil<3.0.0,>=2.1 in /home/***/.local/lib/python3.8/site-packages (from botocore<2.0.0,>=1.23.32->awswrangler==3.6.0->-r /tmp/venvx6yx46_j/requirements.txt (line 1)) (2.8.2)
[2024-04-21T23:02:48.445+0000] {process_utils.py:190} INFO - Requirement already satisfied: urllib3<1.27,>=1.25.4 in /home/***/.local/lib/python3.8/site-packages (from botocore<2.0.0,>=1.23.32->awswrangler==3.6.0->-r /tmp/venvx6yx46_j/requirements.txt (line 1)) (1.26.18)
[2024-04-21T23:02:48.459+0000] {process_utils.py:190} INFO - Requirement already satisfied: Werkzeug>=2.2.2 in /home/***/.local/lib/python3.8/site-packages (from Flask<4->mlflow==2.10.2->-r /tmp/venvx6yx46_j/requirements.txt (line 2)) (2.2.3)
[2024-04-21T23:02:48.460+0000] {process_utils.py:190} INFO - Requirement already satisfied: itsdangerous>=2.0 in /home/***/.local/lib/python3.8/site-packages (from Flask<4->mlflow==2.10.2->-r /tmp/venvx6yx46_j/requirements.txt (line 2)) (2.1.2)
[2024-04-21T23:02:48.474+0000] {process_utils.py:190} INFO - Requirement already satisfied: gitdb<5,>=4.0.1 in /home/***/.local/lib/python3.8/site-packages (from gitpython<4,>=2.1.0->mlflow==2.10.2->-r /tmp/venvx6yx46_j/requirements.txt (line 2)) (4.0.11)
[2024-04-21T23:02:48.505+0000] {process_utils.py:190} INFO - Requirement already satisfied: zipp>=0.5 in /home/***/.local/lib/python3.8/site-packages (from importlib-metadata!=4.7.0,<8,>=3.7.0->mlflow==2.10.2->-r /tmp/venvx6yx46_j/requirements.txt (line 2)) (3.17.0)
[2024-04-21T23:02:48.508+0000] {process_utils.py:190} INFO - Requirement already satisfied: MarkupSafe>=2.0 in /home/***/.local/lib/python3.8/site-packages (from Jinja2<4,>=2.11->mlflow==2.10.2->-r /tmp/venvx6yx46_j/requirements.txt (line 2)) (2.1.3)
[2024-04-21T23:02:48.525+0000] {process_utils.py:190} INFO - Requirement already satisfied: contourpy>=1.0.1 in /home/***/.local/lib/python3.8/site-packages (from matplotlib<4->mlflow==2.10.2->-r /tmp/venvx6yx46_j/requirements.txt (line 2)) (1.1.1)
[2024-04-21T23:02:48.525+0000] {process_utils.py:190} INFO - Requirement already satisfied: cycler>=0.10 in /home/***/.local/lib/python3.8/site-packages (from matplotlib<4->mlflow==2.10.2->-r /tmp/venvx6yx46_j/requirements.txt (line 2)) (0.12.1)
[2024-04-21T23:02:48.526+0000] {process_utils.py:190} INFO - Requirement already satisfied: fonttools>=4.22.0 in /home/***/.local/lib/python3.8/site-packages (from matplotlib<4->mlflow==2.10.2->-r /tmp/venvx6yx46_j/requirements.txt (line 2)) (4.51.0)
[2024-04-21T23:02:48.526+0000] {process_utils.py:190} INFO - Requirement already satisfied: kiwisolver>=1.0.1 in /home/***/.local/lib/python3.8/site-packages (from matplotlib<4->mlflow==2.10.2->-r /tmp/venvx6yx46_j/requirements.txt (line 2)) (1.4.5)
[2024-04-21T23:02:48.527+0000] {process_utils.py:190} INFO - Requirement already satisfied: pillow>=6.2.0 in /home/***/.local/lib/python3.8/site-packages (from matplotlib<4->mlflow==2.10.2->-r /tmp/venvx6yx46_j/requirements.txt (line 2)) (10.3.0)
[2024-04-21T23:02:48.528+0000] {process_utils.py:190} INFO - Requirement already satisfied: pyparsing>=2.3.1 in /home/***/.local/lib/python3.8/site-packages (from matplotlib<4->mlflow==2.10.2->-r /tmp/venvx6yx46_j/requirements.txt (line 2)) (3.1.1)
[2024-04-21T23:02:48.588+0000] {process_utils.py:190} INFO - Requirement already satisfied: tzdata>=2022.1 in /home/***/.local/lib/python3.8/site-packages (from pandas<2.1.0,>=1.2.0->awswrangler==3.6.0->-r /tmp/venvx6yx46_j/requirements.txt (line 1)) (2023.4)
[2024-04-21T23:02:48.601+0000] {process_utils.py:190} INFO - Requirement already satisfied: six in /home/***/.local/lib/python3.8/site-packages (from querystring-parser<2->mlflow==2.10.2->-r /tmp/venvx6yx46_j/requirements.txt (line 2)) (1.16.0)
[2024-04-21T23:02:48.607+0000] {process_utils.py:190} INFO - Requirement already satisfied: charset-normalizer<4,>=2 in /home/***/.local/lib/python3.8/site-packages (from requests<3,>=2.17.3->mlflow==2.10.2->-r /tmp/venvx6yx46_j/requirements.txt (line 2)) (3.3.2)
[2024-04-21T23:02:48.607+0000] {process_utils.py:190} INFO - Requirement already satisfied: idna<4,>=2.5 in /home/***/.local/lib/python3.8/site-packages (from requests<3,>=2.17.3->mlflow==2.10.2->-r /tmp/venvx6yx46_j/requirements.txt (line 2)) (3.6)
[2024-04-21T23:02:48.608+0000] {process_utils.py:190} INFO - Requirement already satisfied: certifi>=2017.4.17 in /home/***/.local/lib/python3.8/site-packages (from requests<3,>=2.17.3->mlflow==2.10.2->-r /tmp/venvx6yx46_j/requirements.txt (line 2)) (2023.11.17)
[2024-04-21T23:02:48.672+0000] {process_utils.py:190} INFO - Requirement already satisfied: greenlet!=0.4.17 in /home/***/.local/lib/python3.8/site-packages (from sqlalchemy<3,>=1.4.0->mlflow==2.10.2->-r /tmp/venvx6yx46_j/requirements.txt (line 2)) (3.0.3)
[2024-04-21T23:02:48.740+0000] {process_utils.py:190} INFO - Requirement already satisfied: smmap<6,>=3.0.1 in /home/***/.local/lib/python3.8/site-packages (from gitdb<5,>=4.0.1->gitpython<4,>=2.1.0->mlflow==2.10.2->-r /tmp/venvx6yx46_j/requirements.txt (line 2)) (5.0.1)
[2024-04-21T23:02:48.853+0000] {process_utils.py:190} INFO - Using cached awswrangler-3.6.0-py3-none-any.whl (403 kB)
[2024-04-21T23:02:48.855+0000] {process_utils.py:190} INFO - Using cached mlflow-2.10.2-py3-none-any.whl (19.5 MB)
[2024-04-21T23:02:50.656+0000] {process_utils.py:190} INFO - Installing collected packages: mlflow, awswrangler
[2024-04-21T23:02:50.656+0000] {process_utils.py:190} INFO -   Attempting uninstall: mlflow
[2024-04-21T23:02:50.657+0000] {process_utils.py:190} INFO -     Found existing installation: mlflow 2.12.1
[2024-04-21T23:02:50.658+0000] {process_utils.py:190} INFO -     Not uninstalling mlflow at /home/***/.local/lib/python3.8/site-packages, outside environment /tmp/venvx6yx46_j
[2024-04-21T23:02:50.658+0000] {process_utils.py:190} INFO -     Can't uninstall 'mlflow'. No files were found to uninstall.
[2024-04-21T23:02:51.528+0000] {process_utils.py:190} INFO - Successfully installed awswrangler-3.6.0 mlflow-2.10.2
[2024-04-21T23:02:51.781+0000] {process_utils.py:190} INFO - 
[2024-04-21T23:02:51.781+0000] {process_utils.py:190} INFO - [notice] A new release of pip is available: 23.3.1 -> 24.0
[2024-04-21T23:02:51.782+0000] {process_utils.py:190} INFO - [notice] To update, run: python -m pip install --upgrade pip
[2024-04-21T23:02:51.879+0000] {process_utils.py:182} INFO - Executing cmd: /tmp/venvx6yx46_j/bin/python /tmp/venv-callosezp8ou/script.py /tmp/venv-callosezp8ou/script.in /tmp/venv-callosezp8ou/script.out /tmp/venv-callosezp8ou/string_args.txt /tmp/venv-callosezp8ou/termination.log
[2024-04-21T23:02:51.886+0000] {process_utils.py:186} INFO - Output:
[2024-04-21T23:02:53.575+0000] {process_utils.py:190} INFO - [[34m2024-04-21T23:02:53.575+0000[0m] {[34mcredentials.py:[0m1147} INFO[0m - Found credentials in environment variables.[0m
[2024-04-21T23:02:53.613+0000] {process_utils.py:190} INFO - [[34m2024-04-21T23:02:53.612+0000[0m] {[34mconfigprovider.py:[0m957} INFO[0m - Found endpoint for s3 via: environment_service.[0m
[2024-04-21T23:02:53.642+0000] {process_utils.py:190} INFO - [[34m2024-04-21T23:02:53.641+0000[0m] {[34mcredentials.py:[0m1147} INFO[0m - Found credentials in environment variables.[0m
[2024-04-21T23:02:53.781+0000] {process_utils.py:190} INFO - [[34m2024-04-21T23:02:53.781+0000[0m] {[34mconfigprovider.py:[0m957} INFO[0m - Found endpoint for s3 via: environment_service.[0m
[2024-04-21T23:02:53.812+0000] {process_utils.py:190} INFO - [[34m2024-04-21T23:02:53.812+0000[0m] {[34mcredentials.py:[0m1147} INFO[0m - Found credentials in environment variables.[0m
[2024-04-21T23:02:53.848+0000] {process_utils.py:190} INFO - [[34m2024-04-21T23:02:53.847+0000[0m] {[34mconfigprovider.py:[0m957} INFO[0m - Found endpoint for s3 via: environment_service.[0m
[2024-04-21T23:02:53.994+0000] {process_utils.py:190} INFO - [[34m2024-04-21T23:02:53.994+0000[0m] {[34mcredentials.py:[0m1147} INFO[0m - Found credentials in environment variables.[0m
[2024-04-21T23:02:54.031+0000] {process_utils.py:190} INFO - [[34m2024-04-21T23:02:54.031+0000[0m] {[34mconfigprovider.py:[0m957} INFO[0m - Found endpoint for s3 via: environment_service.[0m
[2024-04-21T23:02:54.048+0000] {process_utils.py:190} INFO - [[34m2024-04-21T23:02:54.048+0000[0m] {[34mcredentials.py:[0m1147} INFO[0m - Found credentials in environment variables.[0m
[2024-04-21T23:02:54.081+0000] {process_utils.py:190} INFO - [[34m2024-04-21T23:02:54.081+0000[0m] {[34mconfigprovider.py:[0m957} INFO[0m - Found endpoint for s3 via: environment_service.[0m
[2024-04-21T23:02:54.215+0000] {process_utils.py:190} INFO - Traceback (most recent call last):
[2024-04-21T23:02:54.216+0000] {process_utils.py:190} INFO -   File "/tmp/venvx6yx46_j/lib/python3.8/site-packages/mlflow/tracking/_tracking_service/client.py", line 321, in log_param
[2024-04-21T23:02:54.216+0000] {process_utils.py:190} INFO -     self.store.log_param(run_id, param)
[2024-04-21T23:02:54.216+0000] {process_utils.py:190} INFO -   File "/tmp/venvx6yx46_j/lib/python3.8/site-packages/mlflow/store/tracking/rest_store.py", line 210, in log_param
[2024-04-21T23:02:54.216+0000] {process_utils.py:190} INFO -     self._call_endpoint(LogParam, req_body)
[2024-04-21T23:02:54.217+0000] {process_utils.py:190} INFO -   File "/tmp/venvx6yx46_j/lib/python3.8/site-packages/mlflow/store/tracking/rest_store.py", line 59, in _call_endpoint
[2024-04-21T23:02:54.217+0000] {process_utils.py:190} INFO -     return call_endpoint(self.get_host_creds(), endpoint, method, json_body, response_proto)
[2024-04-21T23:02:54.217+0000] {process_utils.py:190} INFO -   File "/tmp/venvx6yx46_j/lib/python3.8/site-packages/mlflow/utils/rest_utils.py", line 220, in call_endpoint
[2024-04-21T23:02:54.218+0000] {process_utils.py:190} INFO -     response = verify_rest_response(response, endpoint)
[2024-04-21T23:02:54.218+0000] {process_utils.py:190} INFO -   File "/tmp/venvx6yx46_j/lib/python3.8/site-packages/mlflow/utils/rest_utils.py", line 152, in verify_rest_response
[2024-04-21T23:02:54.218+0000] {process_utils.py:190} INFO -     raise RestException(json.loads(response.text))
[2024-04-21T23:02:54.218+0000] {process_utils.py:190} INFO - mlflow.exceptions.RestException: INVALID_PARAMETER_VALUE: Changing param values is not allowed. Param with key='Standard Scaler mean values' was already logged with value='[5.48743961e+01 6.42512077e-01 1.31555556e+02 2.48251208e+02
[2024-04-21T23:02:54.219+0000] {process_utils.py:190} INFO -  1.59420290e-01 1.48565217e+02 3.09178744e-01 1.05942029e+00
[2024-04-21T23:02:54.219+0000] {process_utils.py:190} INFO -  1.44927536e-01 2.99516908e-01 4.73429952e-01 1.93236715e-02
[2024-04-21T23:02:54.219+0000] {process_utils.py:190} INFO -  5.12077295e-01 4.73429952e-01 6.28019324e-02 2.07729469e-01
[2024-04-21T23:02:54.219+0000] {process_utils.py:190} INFO -  1.44927536e-01 7.72946860e-02 5.31400966e-02 3.81642512e-01]' for run ID='1948954b0d0e47d29091104fd3187536'. Attempted logging new value '[ 8.58143401e-18 -4.29071700e-18  6.43607551e-17 -1.71628680e-17
[2024-04-21T23:02:54.220+0000] {process_utils.py:190} INFO -   7.72329061e-17  8.58143401e-18 -6.65061136e-17  2.14535850e-18
[2024-04-21T23:02:54.220+0000] {process_utils.py:190} INFO -  -7.29421891e-17 -2.35989435e-17  6.43607551e-17  5.14886040e-17
[2024-04-21T23:02:54.220+0000] {process_utils.py:190} INFO -   1.33012227e-16  7.07968306e-17 -1.71628680e-17 -1.93082265e-17
[2024-04-21T23:02:54.221+0000] {process_utils.py:190} INFO -   1.63047246e-16  8.58143401e-17  5.57793210e-17 -6.86514721e-17]'.
[2024-04-21T23:02:54.221+0000] {process_utils.py:190} INFO - 
[2024-04-21T23:02:54.221+0000] {process_utils.py:190} INFO - During handling of the above exception, another exception occurred:
[2024-04-21T23:02:54.221+0000] {process_utils.py:190} INFO - 
[2024-04-21T23:02:54.222+0000] {process_utils.py:190} INFO - Traceback (most recent call last):
[2024-04-21T23:02:54.222+0000] {process_utils.py:190} INFO -   File "/tmp/venv-callosezp8ou/script.py", line 95, in <module>
[2024-04-21T23:02:54.222+0000] {process_utils.py:190} INFO -     res = normalize_data(*arg_dict["args"], **arg_dict["kwargs"])
[2024-04-21T23:02:54.222+0000] {process_utils.py:190} INFO -   File "/tmp/venv-callosezp8ou/script.py", line 91, in normalize_data
[2024-04-21T23:02:54.222+0000] {process_utils.py:190} INFO -     mlflow.log_param("Standard Scaler mean values", sc_X.mean_)
[2024-04-21T23:02:54.223+0000] {process_utils.py:190} INFO -   File "/tmp/venvx6yx46_j/lib/python3.8/site-packages/mlflow/tracking/fluent.py", line 647, in log_param
[2024-04-21T23:02:54.223+0000] {process_utils.py:190} INFO -     return MlflowClient().log_param(run_id, key, value, synchronous=synchronous)
[2024-04-21T23:02:54.223+0000] {process_utils.py:190} INFO -   File "/tmp/venvx6yx46_j/lib/python3.8/site-packages/mlflow/tracking/client.py", line 841, in log_param
[2024-04-21T23:02:54.223+0000] {process_utils.py:190} INFO -     self._tracking_client.log_param(run_id, key, value, synchronous=True)
[2024-04-21T23:02:54.223+0000] {process_utils.py:190} INFO -   File "/tmp/venvx6yx46_j/lib/python3.8/site-packages/mlflow/tracking/_tracking_service/client.py", line 328, in log_param
[2024-04-21T23:02:54.224+0000] {process_utils.py:190} INFO -     raise MlflowException(msg, INVALID_PARAMETER_VALUE)
[2024-04-21T23:02:54.224+0000] {process_utils.py:190} INFO - mlflow.exceptions.MlflowException: INVALID_PARAMETER_VALUE: Changing param values is not allowed. Param with key='Standard Scaler mean values' was already logged with value='[5.48743961e+01 6.42512077e-01 1.31555556e+02 2.48251208e+02
[2024-04-21T23:02:54.224+0000] {process_utils.py:190} INFO -  1.59420290e-01 1.48565217e+02 3.09178744e-01 1.05942029e+00
[2024-04-21T23:02:54.224+0000] {process_utils.py:190} INFO -  1.44927536e-01 2.99516908e-01 4.73429952e-01 1.93236715e-02
[2024-04-21T23:02:54.224+0000] {process_utils.py:190} INFO -  5.12077295e-01 4.73429952e-01 6.28019324e-02 2.07729469e-01
[2024-04-21T23:02:54.225+0000] {process_utils.py:190} INFO -  1.44927536e-01 7.72946860e-02 5.31400966e-02 3.81642512e-01]' for run ID='1948954b0d0e47d29091104fd3187536'. Attempted logging new value '[ 8.58143401e-18 -4.29071700e-18  6.43607551e-17 -1.71628680e-17
[2024-04-21T23:02:54.225+0000] {process_utils.py:190} INFO -   7.72329061e-17  8.58143401e-18 -6.65061136e-17  2.14535850e-18
[2024-04-21T23:02:54.225+0000] {process_utils.py:190} INFO -  -7.29421891e-17 -2.35989435e-17  6.43607551e-17  5.14886040e-17
[2024-04-21T23:02:54.225+0000] {process_utils.py:190} INFO -   1.33012227e-16  7.07968306e-17 -1.71628680e-17 -1.93082265e-17
[2024-04-21T23:02:54.225+0000] {process_utils.py:190} INFO -   1.63047246e-16  8.58143401e-17  5.57793210e-17 -6.86514721e-17]'.
[2024-04-21T23:02:54.226+0000] {process_utils.py:190} INFO - 
[2024-04-21T23:02:54.226+0000] {process_utils.py:190} INFO - The cause of this error is typically due to repeated calls
[2024-04-21T23:02:54.226+0000] {process_utils.py:190} INFO - to an individual run_id event logging.
[2024-04-21T23:02:54.226+0000] {process_utils.py:190} INFO - 
[2024-04-21T23:02:54.226+0000] {process_utils.py:190} INFO - Incorrect Example:
[2024-04-21T23:02:54.227+0000] {process_utils.py:190} INFO - ---------------------------------------
[2024-04-21T23:02:54.227+0000] {process_utils.py:190} INFO - with mlflow.start_run():
[2024-04-21T23:02:54.227+0000] {process_utils.py:190} INFO -     mlflow.log_param("depth", 3)
[2024-04-21T23:02:54.227+0000] {process_utils.py:190} INFO -     mlflow.log_param("depth", 5)
[2024-04-21T23:02:54.228+0000] {process_utils.py:190} INFO - ---------------------------------------
[2024-04-21T23:02:54.228+0000] {process_utils.py:190} INFO - 
[2024-04-21T23:02:54.228+0000] {process_utils.py:190} INFO - Which will throw an MlflowException for overwriting a
[2024-04-21T23:02:54.228+0000] {process_utils.py:190} INFO - logged parameter.
[2024-04-21T23:02:54.228+0000] {process_utils.py:190} INFO - 
[2024-04-21T23:02:54.229+0000] {process_utils.py:190} INFO - Correct Example:
[2024-04-21T23:02:54.229+0000] {process_utils.py:190} INFO - ---------------------------------------
[2024-04-21T23:02:54.229+0000] {process_utils.py:190} INFO - with mlflow.start_run():
[2024-04-21T23:02:54.229+0000] {process_utils.py:190} INFO -     with mlflow.start_run(nested=True):
[2024-04-21T23:02:54.229+0000] {process_utils.py:190} INFO -         mlflow.log_param("depth", 3)
[2024-04-21T23:02:54.230+0000] {process_utils.py:190} INFO -     with mlflow.start_run(nested=True):
[2024-04-21T23:02:54.230+0000] {process_utils.py:190} INFO -         mlflow.log_param("depth", 5)
[2024-04-21T23:02:54.230+0000] {process_utils.py:190} INFO - ---------------------------------------
[2024-04-21T23:02:54.230+0000] {process_utils.py:190} INFO - 
[2024-04-21T23:02:54.230+0000] {process_utils.py:190} INFO - Which will create a new nested run for each individual
[2024-04-21T23:02:54.231+0000] {process_utils.py:190} INFO - model and prevent parameter key collisions within the
[2024-04-21T23:02:54.231+0000] {process_utils.py:190} INFO - tracking store.
[2024-04-21T23:03:06.987+0000] {taskinstance.py:2698} ERROR - Task failed with exception
Traceback (most recent call last):
  File "/home/airflow/.local/lib/python3.8/site-packages/airflow/models/taskinstance.py", line 433, in _execute_task
    result = execute_callable(context=context, **execute_callable_kwargs)
  File "/home/airflow/.local/lib/python3.8/site-packages/airflow/decorators/base.py", line 241, in execute
    return_value = super().execute(context)
  File "/home/airflow/.local/lib/python3.8/site-packages/airflow/operators/python.py", line 400, in execute
    return super().execute(context=serializable_context)
  File "/home/airflow/.local/lib/python3.8/site-packages/airflow/operators/python.py", line 199, in execute
    return_value = self.execute_callable()
  File "/home/airflow/.local/lib/python3.8/site-packages/airflow/operators/python.py", line 716, in execute_callable
    result = self._execute_python_callable_in_subprocess(python_path)
  File "/home/airflow/.local/lib/python3.8/site-packages/airflow/operators/python.py", line 471, in _execute_python_callable_in_subprocess
    raise AirflowException(error_msg) from None
airflow.exceptions.AirflowException: Process returned non-zero exit status 1.
INVALID_PARAMETER_VALUE: Changing param values is not allowed. Param with key='Standard Scaler mean values' was already logged with value='[5.48743961e+01 6.42512077e-01 1.31555556e+02 2.48251208e+02
 1.59420290e-01 1.48565217e+02 3.09178744e-01 1.05942029e+00
 1.44927536e-01 2.99516908e-01 4.73429952e-01 1.93236715e-02
 5.12077295e-01 4.73429952e-01 6.28019324e-02 2.07729469e-01
 1.44927536e-01 7.72946860e-02 5.31400966e-02 3.81642512e-01]' for run ID='1948954b0d0e47d29091104fd3187536'. Attempted logging new value '[ 8.58143401e-18 -4.29071700e-18  6.43607551e-17 -1.71628680e-17
  7.72329061e-17  8.58143401e-18 -6.65061136e-17  2.14535850e-18
 -7.29421891e-17 -2.35989435e-17  6.43607551e-17  5.14886040e-17
  1.33012227e-16  7.07968306e-17 -1.71628680e-17 -1.93082265e-17
  1.63047246e-16  8.58143401e-17  5.57793210e-17 -6.86514721e-17]'.

The cause of this error is typically due to repeated calls
to an individual run_id event logging.

Incorrect Example:
---------------------------------------
with mlflow.start_run():
    mlflow.log_param("depth", 3)
    mlflow.log_param("depth", 5)
---------------------------------------

Which will throw an MlflowException for overwriting a
logged parameter.

Correct Example:
---------------------------------------
with mlflow.start_run():
    with mlflow.start_run(nested=True):
        mlflow.log_param("depth", 3)
    with mlflow.start_run(nested=True):
        mlflow.log_param("depth", 5)
---------------------------------------

Which will create a new nested run for each individual
model and prevent parameter key collisions within the
tracking store.
[2024-04-21T23:03:06.989+0000] {taskinstance.py:1138} INFO - Marking task as FAILED. dag_id=process_etl_heart_data, task_id=normalize_numerical_features, execution_date=20240420T000000, start_date=20240421T230246, end_date=20240421T230306
[2024-04-21T23:03:07.000+0000] {standard_task_runner.py:107} ERROR - Failed to execute job 12 for task normalize_numerical_features (Process returned non-zero exit status 1.
INVALID_PARAMETER_VALUE: Changing param values is not allowed. Param with key='Standard Scaler mean values' was already logged with value='[5.48743961e+01 6.42512077e-01 1.31555556e+02 2.48251208e+02
 1.59420290e-01 1.48565217e+02 3.09178744e-01 1.05942029e+00
 1.44927536e-01 2.99516908e-01 4.73429952e-01 1.93236715e-02
 5.12077295e-01 4.73429952e-01 6.28019324e-02 2.07729469e-01
 1.44927536e-01 7.72946860e-02 5.31400966e-02 3.81642512e-01]' for run ID='1948954b0d0e47d29091104fd3187536'. Attempted logging new value '[ 8.58143401e-18 -4.29071700e-18  6.43607551e-17 -1.71628680e-17
  7.72329061e-17  8.58143401e-18 -6.65061136e-17  2.14535850e-18
 -7.29421891e-17 -2.35989435e-17  6.43607551e-17  5.14886040e-17
  1.33012227e-16  7.07968306e-17 -1.71628680e-17 -1.93082265e-17
  1.63047246e-16  8.58143401e-17  5.57793210e-17 -6.86514721e-17]'.

The cause of this error is typically due to repeated calls
to an individual run_id event logging.

Incorrect Example:
---------------------------------------
with mlflow.start_run():
    mlflow.log_param("depth", 3)
    mlflow.log_param("depth", 5)
---------------------------------------

Which will throw an MlflowException for overwriting a
logged parameter.

Correct Example:
---------------------------------------
with mlflow.start_run():
    with mlflow.start_run(nested=True):
        mlflow.log_param("depth", 3)
    with mlflow.start_run(nested=True):
        mlflow.log_param("depth", 5)
---------------------------------------

Which will create a new nested run for each individual
model and prevent parameter key collisions within the
tracking store.; 20354)
[2024-04-21T23:03:07.044+0000] {local_task_job_runner.py:234} INFO - Task exited with return code 1
[2024-04-21T23:03:07.055+0000] {taskinstance.py:3280} INFO - 0 downstream tasks scheduled from follow-on schedule check
